 2018-09-11 23:28:15,965 [P1916/D3/T1] INFO  Umbraco.Core.CoreBootManager - Umbraco 7.11.1 application starting on SEMEREMEHAR57F0
 2018-09-11 23:28:16,041 [P1916/D3/T1] INFO  Umbraco.Core.PluginManager - Determining hash of code files on disk
 2018-09-11 23:28:17,497 [P1916/D3/T1] INFO  Umbraco.Core.PluginManager - Hash determined (took 1456ms)
 2018-09-11 23:28:17,599 [P1916/D3/T1] INFO  Umbraco.Core.MainDom - Acquiring MainDom...
 2018-09-11 23:28:17,611 [P1916/D3/T1] INFO  Umbraco.Core.MainDom - Acquired MainDom.
 2018-09-11 23:28:17,614 [P1916/D3/T1] INFO  Umbraco.Core.PluginManager - Resolving umbraco.interfaces.IDiscoverable
 2018-09-11 23:28:18,136 [P1916/D3/T1] INFO  Umbraco.Core.PluginManager - Resolved umbraco.interfaces.IDiscoverable (took 522ms)
 2018-09-11 23:28:18,136 [P1916/D3/T1] INFO  Umbraco.Core.PluginManager - Resolving umbraco.interfaces.IApplicationStartupHandler
 2018-09-11 23:28:18,148 [P1916/D3/T1] INFO  Umbraco.Core.PluginManager - Resolved umbraco.interfaces.IApplicationStartupHandler (took 11ms)
 2018-09-11 23:28:18,167 [P1916/D3/T1] INFO  Umbraco.Core.PluginManager - Resolving umbraco.interfaces.IDiscoverable
 2018-09-11 23:28:18,170 [P1916/D3/T1] INFO  Umbraco.Core.PluginManager - Resolved umbraco.interfaces.IDiscoverable (took 2ms)
 2018-09-11 23:28:18,171 [P1916/D3/T1] INFO  Umbraco.Core.PluginManager - Resolving Umbraco.Core.PropertyEditors.IPropertyEditorValueConverter
 2018-09-11 23:28:18,193 [P1916/D3/T1] INFO  Umbraco.Core.PluginManager - Resolved Umbraco.Core.PropertyEditors.IPropertyEditorValueConverter (took 21ms)
 2018-09-11 23:28:18,193 [P1916/D3/T1] INFO  Umbraco.Core.PluginManager - Resolving umbraco.interfaces.IDiscoverable
 2018-09-11 23:28:18,194 [P1916/D3/T1] INFO  Umbraco.Core.PluginManager - Resolved umbraco.interfaces.IDiscoverable (took 0ms)
 2018-09-11 23:28:18,194 [P1916/D3/T1] INFO  Umbraco.Core.PluginManager - Resolving Umbraco.Core.PropertyEditors.IPropertyValueConverter
 2018-09-11 23:28:18,213 [P1916/D3/T1] INFO  Umbraco.Core.PluginManager - Resolved Umbraco.Core.PropertyEditors.IPropertyValueConverter (took 19ms)
 2018-09-11 23:28:18,227 [P1916/D3/T1] INFO  Umbraco.Core.PluginManager - Resolving umbraco.interfaces.IDiscoverable
 2018-09-11 23:28:18,228 [P1916/D3/T1] INFO  Umbraco.Core.PluginManager - Resolved umbraco.interfaces.IDiscoverable (took 0ms)
 2018-09-11 23:28:18,228 [P1916/D3/T1] INFO  Umbraco.Core.PluginManager - Resolving Umbraco.Web.Mvc.SurfaceController
 2018-09-11 23:28:18,248 [P1916/D3/T1] INFO  Umbraco.Core.PluginManager - Resolved Umbraco.Web.Mvc.SurfaceController (took 19ms)
 2018-09-11 23:28:18,249 [P1916/D3/T1] INFO  Umbraco.Core.PluginManager - Resolving umbraco.interfaces.IDiscoverable
 2018-09-11 23:28:18,249 [P1916/D3/T1] INFO  Umbraco.Core.PluginManager - Resolved umbraco.interfaces.IDiscoverable (took 0ms)
 2018-09-11 23:28:18,250 [P1916/D3/T1] INFO  Umbraco.Core.PluginManager - Resolving Umbraco.Web.WebApi.UmbracoApiController
 2018-09-11 23:28:18,268 [P1916/D3/T1] INFO  Umbraco.Core.PluginManager - Resolved Umbraco.Web.WebApi.UmbracoApiController (took 17ms)
 2018-09-11 23:28:20,681 [P1916/D3/T1] WARN  Umbraco.Core.Persistence.DbConnectionExtensions - Configured database is reporting as not being available! DataSource: SEMEREMEHAR57F0\ADULIS, InitialCatalog: umbraco. Exception: System.Data.SqlClient.SqlException (0x80131904): Login failed for user 'umbraco_db_user'.
   at System.Data.SqlClient.SqlInternalConnectionTds..ctor(DbConnectionPoolIdentity identity, SqlConnectionString connectionOptions, SqlCredential credential, Object providerInfo, String newPassword, SecureString newSecurePassword, Boolean redirectedUserInstance, SqlConnectionString userConnectionOptions, SessionData reconnectSessionData, DbConnectionPool pool, String accessToken, Boolean applyTransientFaultHandling, SqlAuthenticationProviderManager sqlAuthProviderManager)
   at System.Data.SqlClient.SqlConnectionFactory.CreateConnection(DbConnectionOptions options, DbConnectionPoolKey poolKey, Object poolGroupProviderInfo, DbConnectionPool pool, DbConnection owningConnection, DbConnectionOptions userOptions)
   at System.Data.ProviderBase.DbConnectionFactory.CreatePooledConnection(DbConnectionPool pool, DbConnection owningObject, DbConnectionOptions options, DbConnectionPoolKey poolKey, DbConnectionOptions userOptions)
   at System.Data.ProviderBase.DbConnectionPool.CreateObject(DbConnection owningObject, DbConnectionOptions userOptions, DbConnectionInternal oldConnection)
   at System.Data.ProviderBase.DbConnectionPool.UserCreateRequest(DbConnection owningObject, DbConnectionOptions userOptions, DbConnectionInternal oldConnection)
   at System.Data.ProviderBase.DbConnectionPool.TryGetConnection(DbConnection owningObject, UInt32 waitForMultipleObjectsTimeout, Boolean allowCreate, Boolean onlyOneCheckConnection, DbConnectionOptions userOptions, DbConnectionInternal& connection)
   at System.Data.ProviderBase.DbConnectionPool.TryGetConnection(DbConnection owningObject, TaskCompletionSource`1 retry, DbConnectionOptions userOptions, DbConnectionInternal& connection)
   at System.Data.ProviderBase.DbConnectionFactory.TryGetConnection(DbConnection owningConnection, TaskCompletionSource`1 retry, DbConnectionOptions userOptions, DbConnectionInternal oldConnection, DbConnectionInternal& connection)
   at System.Data.ProviderBase.DbConnectionInternal.TryOpenConnectionInternal(DbConnection outerConnection, DbConnectionFactory connectionFactory, TaskCompletionSource`1 retry, DbConnectionOptions userOptions)
   at System.Data.ProviderBase.DbConnectionClosed.TryOpenConnection(DbConnection outerConnection, DbConnectionFactory connectionFactory, TaskCompletionSource`1 retry, DbConnectionOptions userOptions)
   at System.Data.SqlClient.SqlConnection.TryOpenInner(TaskCompletionSource`1 retry)
   at System.Data.SqlClient.SqlConnection.TryOpen(TaskCompletionSource`1 retry)
   at System.Data.SqlClient.SqlConnection.Open()
   at Umbraco.Core.Persistence.DbConnectionExtensions.IsAvailable(IDbConnection connection)
ClientConnectionId:9cb75db8-ba35-402d-b3bd-eb5c03ee33ec
Error Number:18456,State:1,Class:14
 2018-09-11 23:28:20,682 [P1916/D3/T1] INFO  Umbraco.Core.DatabaseContext - CanConnect = False
 2018-09-11 23:28:20,977 [P1916/D3/T1] WARN  Umbraco.Core.Persistence.DbConnectionExtensions - Configured database is reporting as not being available! DataSource: SEMEREMEHAR57F0\ADULIS, InitialCatalog: umbraco. Exception: System.Data.SqlClient.SqlException (0x80131904): Login failed for user 'umbraco_db_user'.
   at System.Data.ProviderBase.DbConnectionPool.TryGetConnection(DbConnection owningObject, UInt32 waitForMultipleObjectsTimeout, Boolean allowCreate, Boolean onlyOneCheckConnection, DbConnectionOptions userOptions, DbConnectionInternal& connection)
   at System.Data.ProviderBase.DbConnectionPool.TryGetConnection(DbConnection owningObject, TaskCompletionSource`1 retry, DbConnectionOptions userOptions, DbConnectionInternal& connection)
   at System.Data.ProviderBase.DbConnectionFactory.TryGetConnection(DbConnection owningConnection, TaskCompletionSource`1 retry, DbConnectionOptions userOptions, DbConnectionInternal oldConnection, DbConnectionInternal& connection)
   at System.Data.ProviderBase.DbConnectionInternal.TryOpenConnectionInternal(DbConnection outerConnection, DbConnectionFactory connectionFactory, TaskCompletionSource`1 retry, DbConnectionOptions userOptions)
   at System.Data.ProviderBase.DbConnectionClosed.TryOpenConnection(DbConnection outerConnection, DbConnectionFactory connectionFactory, TaskCompletionSource`1 retry, DbConnectionOptions userOptions)
   at System.Data.SqlClient.SqlConnection.TryOpenInner(TaskCompletionSource`1 retry)
   at System.Data.SqlClient.SqlConnection.TryOpen(TaskCompletionSource`1 retry)
   at System.Data.SqlClient.SqlConnection.Open()
   at Umbraco.Core.Persistence.DbConnectionExtensions.IsAvailable(IDbConnection connection)
ClientConnectionId:9cb75db8-ba35-402d-b3bd-eb5c03ee33ec
Error Number:18456,State:1,Class:14
 2018-09-11 23:28:20,978 [P1916/D3/T1] INFO  Umbraco.Core.DatabaseContext - CanConnect = False
 2018-09-11 23:28:21,979 [P1916/D3/T1] WARN  Umbraco.Core.Persistence.DbConnectionExtensions - Configured database is reporting as not being available! DataSource: SEMEREMEHAR57F0\ADULIS, InitialCatalog: umbraco. Exception: System.Data.SqlClient.SqlException (0x80131904): Login failed for user 'umbraco_db_user'.
   at System.Data.ProviderBase.DbConnectionPool.TryGetConnection(DbConnection owningObject, UInt32 waitForMultipleObjectsTimeout, Boolean allowCreate, Boolean onlyOneCheckConnection, DbConnectionOptions userOptions, DbConnectionInternal& connection)
   at System.Data.ProviderBase.DbConnectionPool.TryGetConnection(DbConnection owningObject, TaskCompletionSource`1 retry, DbConnectionOptions userOptions, DbConnectionInternal& connection)
   at System.Data.ProviderBase.DbConnectionFactory.TryGetConnection(DbConnection owningConnection, TaskCompletionSource`1 retry, DbConnectionOptions userOptions, DbConnectionInternal oldConnection, DbConnectionInternal& connection)
   at System.Data.ProviderBase.DbConnectionInternal.TryOpenConnectionInternal(DbConnection outerConnection, DbConnectionFactory connectionFactory, TaskCompletionSource`1 retry, DbConnectionOptions userOptions)
   at System.Data.ProviderBase.DbConnectionClosed.TryOpenConnection(DbConnection outerConnection, DbConnectionFactory connectionFactory, TaskCompletionSource`1 retry, DbConnectionOptions userOptions)
   at System.Data.SqlClient.SqlConnection.TryOpenInner(TaskCompletionSource`1 retry)
   at System.Data.SqlClient.SqlConnection.TryOpen(TaskCompletionSource`1 retry)
   at System.Data.SqlClient.SqlConnection.Open()
   at Umbraco.Core.Persistence.DbConnectionExtensions.IsAvailable(IDbConnection connection)
ClientConnectionId:9cb75db8-ba35-402d-b3bd-eb5c03ee33ec
Error Number:18456,State:1,Class:14
 2018-09-11 23:28:21,980 [P1916/D3/T1] INFO  Umbraco.Core.DatabaseContext - CanConnect = False
 2018-09-11 23:28:22,981 [P1916/D3/T1] WARN  Umbraco.Core.Persistence.DbConnectionExtensions - Configured database is reporting as not being available! DataSource: SEMEREMEHAR57F0\ADULIS, InitialCatalog: umbraco. Exception: System.Data.SqlClient.SqlException (0x80131904): Login failed for user 'umbraco_db_user'.
   at System.Data.ProviderBase.DbConnectionPool.TryGetConnection(DbConnection owningObject, UInt32 waitForMultipleObjectsTimeout, Boolean allowCreate, Boolean onlyOneCheckConnection, DbConnectionOptions userOptions, DbConnectionInternal& connection)
   at System.Data.ProviderBase.DbConnectionPool.TryGetConnection(DbConnection owningObject, TaskCompletionSource`1 retry, DbConnectionOptions userOptions, DbConnectionInternal& connection)
   at System.Data.ProviderBase.DbConnectionFactory.TryGetConnection(DbConnection owningConnection, TaskCompletionSource`1 retry, DbConnectionOptions userOptions, DbConnectionInternal oldConnection, DbConnectionInternal& connection)
   at System.Data.ProviderBase.DbConnectionInternal.TryOpenConnectionInternal(DbConnection outerConnection, DbConnectionFactory connectionFactory, TaskCompletionSource`1 retry, DbConnectionOptions userOptions)
   at System.Data.ProviderBase.DbConnectionClosed.TryOpenConnection(DbConnection outerConnection, DbConnectionFactory connectionFactory, TaskCompletionSource`1 retry, DbConnectionOptions userOptions)
   at System.Data.SqlClient.SqlConnection.TryOpenInner(TaskCompletionSource`1 retry)
   at System.Data.SqlClient.SqlConnection.TryOpen(TaskCompletionSource`1 retry)
   at System.Data.SqlClient.SqlConnection.Open()
   at Umbraco.Core.Persistence.DbConnectionExtensions.IsAvailable(IDbConnection connection)
ClientConnectionId:9cb75db8-ba35-402d-b3bd-eb5c03ee33ec
Error Number:18456,State:1,Class:14
 2018-09-11 23:28:22,981 [P1916/D3/T1] INFO  Umbraco.Core.DatabaseContext - CanConnect = False
 2018-09-11 23:28:23,983 [P1916/D3/T1] WARN  Umbraco.Core.Persistence.DbConnectionExtensions - Configured database is reporting as not being available! DataSource: SEMEREMEHAR57F0\ADULIS, InitialCatalog: umbraco. Exception: System.Data.SqlClient.SqlException (0x80131904): Login failed for user 'umbraco_db_user'.
   at System.Data.ProviderBase.DbConnectionPool.TryGetConnection(DbConnection owningObject, UInt32 waitForMultipleObjectsTimeout, Boolean allowCreate, Boolean onlyOneCheckConnection, DbConnectionOptions userOptions, DbConnectionInternal& connection)
   at System.Data.ProviderBase.DbConnectionPool.TryGetConnection(DbConnection owningObject, TaskCompletionSource`1 retry, DbConnectionOptions userOptions, DbConnectionInternal& connection)
   at System.Data.ProviderBase.DbConnectionFactory.TryGetConnection(DbConnection owningConnection, TaskCompletionSource`1 retry, DbConnectionOptions userOptions, DbConnectionInternal oldConnection, DbConnectionInternal& connection)
   at System.Data.ProviderBase.DbConnectionInternal.TryOpenConnectionInternal(DbConnection outerConnection, DbConnectionFactory connectionFactory, TaskCompletionSource`1 retry, DbConnectionOptions userOptions)
   at System.Data.ProviderBase.DbConnectionClosed.TryOpenConnection(DbConnection outerConnection, DbConnectionFactory connectionFactory, TaskCompletionSource`1 retry, DbConnectionOptions userOptions)
   at System.Data.SqlClient.SqlConnection.TryOpenInner(TaskCompletionSource`1 retry)
   at System.Data.SqlClient.SqlConnection.TryOpen(TaskCompletionSource`1 retry)
   at System.Data.SqlClient.SqlConnection.Open()
   at Umbraco.Core.Persistence.DbConnectionExtensions.IsAvailable(IDbConnection connection)
ClientConnectionId:9cb75db8-ba35-402d-b3bd-eb5c03ee33ec
Error Number:18456,State:1,Class:14
 2018-09-11 23:28:23,983 [P1916/D3/T1] INFO  Umbraco.Core.DatabaseContext - CanConnect = False
 2018-09-11 23:28:24,989 [P1916/D3/T1] WARN  Umbraco.Core.Persistence.DbConnectionExtensions - Configured database is reporting as not being available! DataSource: SEMEREMEHAR57F0\ADULIS, InitialCatalog: umbraco. Exception: System.Data.SqlClient.SqlException (0x80131904): Login failed for user 'umbraco_db_user'.
   at System.Data.ProviderBase.DbConnectionPool.TryGetConnection(DbConnection owningObject, UInt32 waitForMultipleObjectsTimeout, Boolean allowCreate, Boolean onlyOneCheckConnection, DbConnectionOptions userOptions, DbConnectionInternal& connection)
   at System.Data.ProviderBase.DbConnectionPool.TryGetConnection(DbConnection owningObject, TaskCompletionSource`1 retry, DbConnectionOptions userOptions, DbConnectionInternal& connection)
   at System.Data.ProviderBase.DbConnectionFactory.TryGetConnection(DbConnection owningConnection, TaskCompletionSource`1 retry, DbConnectionOptions userOptions, DbConnectionInternal oldConnection, DbConnectionInternal& connection)
   at System.Data.ProviderBase.DbConnectionInternal.TryOpenConnectionInternal(DbConnection outerConnection, DbConnectionFactory connectionFactory, TaskCompletionSource`1 retry, DbConnectionOptions userOptions)
   at System.Data.ProviderBase.DbConnectionClosed.TryOpenConnection(DbConnection outerConnection, DbConnectionFactory connectionFactory, TaskCompletionSource`1 retry, DbConnectionOptions userOptions)
   at System.Data.SqlClient.SqlConnection.TryOpenInner(TaskCompletionSource`1 retry)
   at System.Data.SqlClient.SqlConnection.TryOpen(TaskCompletionSource`1 retry)
   at System.Data.SqlClient.SqlConnection.Open()
   at Umbraco.Core.Persistence.DbConnectionExtensions.IsAvailable(IDbConnection connection)
ClientConnectionId:9cb75db8-ba35-402d-b3bd-eb5c03ee33ec
Error Number:18456,State:1,Class:14
 2018-09-11 23:28:24,989 [P1916/D3/T1] INFO  Umbraco.Core.DatabaseContext - CanConnect = False
 2018-09-11 23:28:25,999 [P1916/D3/T1] WARN  Umbraco.Core.Persistence.DbConnectionExtensions - Configured database is reporting as not being available! DataSource: SEMEREMEHAR57F0\ADULIS, InitialCatalog: umbraco. Exception: System.Data.SqlClient.SqlException (0x80131904): Login failed for user 'umbraco_db_user'.
   at System.Data.SqlClient.SqlInternalConnectionTds..ctor(DbConnectionPoolIdentity identity, SqlConnectionString connectionOptions, SqlCredential credential, Object providerInfo, String newPassword, SecureString newSecurePassword, Boolean redirectedUserInstance, SqlConnectionString userConnectionOptions, SessionData reconnectSessionData, DbConnectionPool pool, String accessToken, Boolean applyTransientFaultHandling, SqlAuthenticationProviderManager sqlAuthProviderManager)
   at System.Data.SqlClient.SqlConnectionFactory.CreateConnection(DbConnectionOptions options, DbConnectionPoolKey poolKey, Object poolGroupProviderInfo, DbConnectionPool pool, DbConnection owningConnection, DbConnectionOptions userOptions)
   at System.Data.ProviderBase.DbConnectionFactory.CreatePooledConnection(DbConnectionPool pool, DbConnection owningObject, DbConnectionOptions options, DbConnectionPoolKey poolKey, DbConnectionOptions userOptions)
   at System.Data.ProviderBase.DbConnectionPool.CreateObject(DbConnection owningObject, DbConnectionOptions userOptions, DbConnectionInternal oldConnection)
   at System.Data.ProviderBase.DbConnectionPool.UserCreateRequest(DbConnection owningObject, DbConnectionOptions userOptions, DbConnectionInternal oldConnection)
   at System.Data.ProviderBase.DbConnectionPool.TryGetConnection(DbConnection owningObject, UInt32 waitForMultipleObjectsTimeout, Boolean allowCreate, Boolean onlyOneCheckConnection, DbConnectionOptions userOptions, DbConnectionInternal& connection)
   at System.Data.ProviderBase.DbConnectionPool.TryGetConnection(DbConnection owningObject, TaskCompletionSource`1 retry, DbConnectionOptions userOptions, DbConnectionInternal& connection)
   at System.Data.ProviderBase.DbConnectionFactory.TryGetConnection(DbConnection owningConnection, TaskCompletionSource`1 retry, DbConnectionOptions userOptions, DbConnectionInternal oldConnection, DbConnectionInternal& connection)
   at System.Data.ProviderBase.DbConnectionInternal.TryOpenConnectionInternal(DbConnection outerConnection, DbConnectionFactory connectionFactory, TaskCompletionSource`1 retry, DbConnectionOptions userOptions)
   at System.Data.ProviderBase.DbConnectionClosed.TryOpenConnection(DbConnection outerConnection, DbConnectionFactory connectionFactory, TaskCompletionSource`1 retry, DbConnectionOptions userOptions)
   at System.Data.SqlClient.SqlConnection.TryOpenInner(TaskCompletionSource`1 retry)
   at System.Data.SqlClient.SqlConnection.TryOpen(TaskCompletionSource`1 retry)
   at System.Data.SqlClient.SqlConnection.Open()
   at Umbraco.Core.Persistence.DbConnectionExtensions.IsAvailable(IDbConnection connection)
ClientConnectionId:330cb5a8-c77d-40ca-85ca-3e385845ea48
Error Number:18456,State:1,Class:14
 2018-09-11 23:28:26,000 [P1916/D3/T1] INFO  Umbraco.Core.DatabaseContext - CanConnect = False
 2018-09-11 23:28:26,008 [P1916/D3/T1] ERROR Umbraco.Core.UmbracoApplicationBase - An unhandled exception occurred
Umbraco.Core.Exceptions.UmbracoStartupFailedException: Umbraco cannot start. A connection string is configured but Umbraco cannot connect to the database.
   at Umbraco.Core.CoreBootManager.EnsureDatabaseConnection()
   at Umbraco.Core.CoreBootManager.Complete(Action`1 afterComplete)
   at Umbraco.Web.WebBootManager.Complete(Action`1 afterComplete)
   at Umbraco.Core.UmbracoApplicationBase.StartApplication(Object sender, EventArgs e)
   at Umbraco.Core.UmbracoApplicationBase.Application_Start(Object sender, EventArgs e)
 2018-09-11 23:28:36,244 [P1916/D3/T8] INFO  Umbraco.Core.MainDom - Stopping...
 2018-09-11 23:28:36,246 [P1916/D3/T8] INFO  Umbraco.Web.ExamineStartup - Examine shutting down
 2018-09-11 23:28:36,248 [P1916/D3/T8] INFO  Umbraco.Web.ExamineStartup - Complete (took 1ms)
 2018-09-11 23:28:36,248 [P1916/D3/T8] INFO  Umbraco.Core.MainDom - Released MainDom.
 2018-09-11 23:29:06,395 [P1916/D3/T8] INFO  Umbraco.Core.UmbracoApplicationBase - Application shutdown. Details: InitializationError

_shutDownMessage=Initialization Error
HostingEnvironment initiated shutdown
HostingEnvironment caused shutdown

_shutDownStack=   at System.Environment.GetStackTrace(Exception e, Boolean needFileInfo)
   at System.Environment.get_StackTrace()
   at System.Web.Hosting.HostingEnvironment.InitiateShutdownInternal()
   at System.Web.Hosting.HostingEnvironment.InitiateShutdownWithoutDemand()
   at System.Web.HttpRuntime.ShutdownAppDomain(String stackTrace)
   at System.Web.HttpRuntime.AppDomainShutdownTimerCallback(Object state)
   at System.Threading.TimerQueueTimer.CallCallbackInContext(Object state)
   at System.Threading.ExecutionContext.RunInternal(ExecutionContext executionContext, ContextCallback callback, Object state, Boolean preserveSyncCtx)
   at System.Threading.ExecutionContext.Run(ExecutionContext executionContext, ContextCallback callback, Object state, Boolean preserveSyncCtx)
   at System.Threading.TimerQueueTimer.CallCallback()
   at System.Threading.TimerQueueTimer.Fire()
   at System.Threading.TimerQueue.FireNextTimers()
   at System.Threading.TimerQueue.AppDomainTimerCallback()
 2018-09-12 17:57:28,086 [P1916/D4/T1] INFO  Umbraco.Core.CoreBootManager - Umbraco 7.11.1 application starting on SEMEREMEHAR57F0
 2018-09-12 17:57:28,128 [P1916/D4/T1] INFO  Umbraco.Core.PluginManager - Determining hash of code files on disk
 2018-09-12 17:57:29,316 [P1916/D4/T1] INFO  Umbraco.Core.PluginManager - Hash determined (took 1188ms)
 2018-09-12 17:57:29,410 [P1916/D4/T1] INFO  Umbraco.Core.MainDom - Acquiring MainDom...
 2018-09-12 17:57:29,415 [P1916/D4/T1] INFO  Umbraco.Core.MainDom - Acquired MainDom.
 2018-09-12 17:57:29,416 [P1916/D4/T1] INFO  Umbraco.Core.PluginManager - Resolving umbraco.interfaces.IDiscoverable
 2018-09-12 17:57:29,857 [P1916/D4/T1] INFO  Umbraco.Core.PluginManager - Resolved umbraco.interfaces.IDiscoverable (took 440ms)
 2018-09-12 17:57:29,857 [P1916/D4/T1] INFO  Umbraco.Core.PluginManager - Resolving umbraco.interfaces.IApplicationStartupHandler
 2018-09-12 17:57:29,872 [P1916/D4/T1] INFO  Umbraco.Core.PluginManager - Resolved umbraco.interfaces.IApplicationStartupHandler (took 14ms)
 2018-09-12 17:57:29,891 [P1916/D4/T1] INFO  Umbraco.Core.PluginManager - Resolving umbraco.interfaces.IDiscoverable
 2018-09-12 17:57:29,892 [P1916/D4/T1] INFO  Umbraco.Core.PluginManager - Resolved umbraco.interfaces.IDiscoverable (took 1ms)
 2018-09-12 17:57:29,893 [P1916/D4/T1] INFO  Umbraco.Core.PluginManager - Resolving Umbraco.Core.PropertyEditors.IPropertyEditorValueConverter
 2018-09-12 17:57:29,910 [P1916/D4/T1] INFO  Umbraco.Core.PluginManager - Resolved Umbraco.Core.PropertyEditors.IPropertyEditorValueConverter (took 17ms)
 2018-09-12 17:57:29,911 [P1916/D4/T1] INFO  Umbraco.Core.PluginManager - Resolving umbraco.interfaces.IDiscoverable
 2018-09-12 17:57:29,911 [P1916/D4/T1] INFO  Umbraco.Core.PluginManager - Resolved umbraco.interfaces.IDiscoverable (took 0ms)
 2018-09-12 17:57:29,912 [P1916/D4/T1] INFO  Umbraco.Core.PluginManager - Resolving Umbraco.Core.PropertyEditors.IPropertyValueConverter
 2018-09-12 17:57:29,931 [P1916/D4/T1] INFO  Umbraco.Core.PluginManager - Resolved Umbraco.Core.PropertyEditors.IPropertyValueConverter (took 19ms)
 2018-09-12 17:57:29,949 [P1916/D4/T1] INFO  Umbraco.Core.PluginManager - Resolving umbraco.interfaces.IDiscoverable
 2018-09-12 17:57:29,949 [P1916/D4/T1] INFO  Umbraco.Core.PluginManager - Resolved umbraco.interfaces.IDiscoverable (took 0ms)
 2018-09-12 17:57:29,949 [P1916/D4/T1] INFO  Umbraco.Core.PluginManager - Resolving Umbraco.Web.Mvc.SurfaceController
 2018-09-12 17:57:29,970 [P1916/D4/T1] INFO  Umbraco.Core.PluginManager - Resolved Umbraco.Web.Mvc.SurfaceController (took 21ms)
 2018-09-12 17:57:29,971 [P1916/D4/T1] INFO  Umbraco.Core.PluginManager - Resolving umbraco.interfaces.IDiscoverable
 2018-09-12 17:57:29,971 [P1916/D4/T1] INFO  Umbraco.Core.PluginManager - Resolved umbraco.interfaces.IDiscoverable (took 0ms)
 2018-09-12 17:57:29,972 [P1916/D4/T1] INFO  Umbraco.Core.PluginManager - Resolving Umbraco.Web.WebApi.UmbracoApiController
 2018-09-12 17:57:29,994 [P1916/D4/T1] INFO  Umbraco.Core.PluginManager - Resolved Umbraco.Web.WebApi.UmbracoApiController (took 22ms)
 2018-09-12 17:57:46,563 [P1916/D4/T1] WARN  Umbraco.Core.Persistence.DbConnectionExtensions - Configured database is reporting as not being available! DataSource: .\ADULIS, InitialCatalog: umbraco. Exception: System.Data.SqlClient.SqlException (0x80131904): A network-related or instance-specific error occurred while establishing a connection to SQL Server. The server was not found or was not accessible. Verify that the instance name is correct and that SQL Server is configured to allow remote connections. (provider: Shared Memory Provider, error: 40 - Could not open a connection to SQL Server) ---> System.ComponentModel.Win32Exception (0x80004005): The system cannot find the file specified
   at System.Data.SqlClient.SqlInternalConnectionTds..ctor(DbConnectionPoolIdentity identity, SqlConnectionString connectionOptions, SqlCredential credential, Object providerInfo, String newPassword, SecureString newSecurePassword, Boolean redirectedUserInstance, SqlConnectionString userConnectionOptions, SessionData reconnectSessionData, DbConnectionPool pool, String accessToken, Boolean applyTransientFaultHandling, SqlAuthenticationProviderManager sqlAuthProviderManager)
   at System.Data.SqlClient.SqlConnectionFactory.CreateConnection(DbConnectionOptions options, DbConnectionPoolKey poolKey, Object poolGroupProviderInfo, DbConnectionPool pool, DbConnection owningConnection, DbConnectionOptions userOptions)
   at System.Data.ProviderBase.DbConnectionFactory.CreatePooledConnection(DbConnectionPool pool, DbConnection owningObject, DbConnectionOptions options, DbConnectionPoolKey poolKey, DbConnectionOptions userOptions)
   at System.Data.ProviderBase.DbConnectionPool.CreateObject(DbConnection owningObject, DbConnectionOptions userOptions, DbConnectionInternal oldConnection)
   at System.Data.ProviderBase.DbConnectionPool.UserCreateRequest(DbConnection owningObject, DbConnectionOptions userOptions, DbConnectionInternal oldConnection)
   at System.Data.ProviderBase.DbConnectionPool.TryGetConnection(DbConnection owningObject, UInt32 waitForMultipleObjectsTimeout, Boolean allowCreate, Boolean onlyOneCheckConnection, DbConnectionOptions userOptions, DbConnectionInternal& connection)
   at System.Data.ProviderBase.DbConnectionPool.TryGetConnection(DbConnection owningObject, TaskCompletionSource`1 retry, DbConnectionOptions userOptions, DbConnectionInternal& connection)
   at System.Data.ProviderBase.DbConnectionFactory.TryGetConnection(DbConnection owningConnection, TaskCompletionSource`1 retry, DbConnectionOptions userOptions, DbConnectionInternal oldConnection, DbConnectionInternal& connection)
   at System.Data.ProviderBase.DbConnectionInternal.TryOpenConnectionInternal(DbConnection outerConnection, DbConnectionFactory connectionFactory, TaskCompletionSource`1 retry, DbConnectionOptions userOptions)
   at System.Data.ProviderBase.DbConnectionClosed.TryOpenConnection(DbConnection outerConnection, DbConnectionFactory connectionFactory, TaskCompletionSource`1 retry, DbConnectionOptions userOptions)
   at System.Data.SqlClient.SqlConnection.TryOpenInner(TaskCompletionSource`1 retry)
   at System.Data.SqlClient.SqlConnection.TryOpen(TaskCompletionSource`1 retry)
   at System.Data.SqlClient.SqlConnection.Open()
   at Umbraco.Core.Persistence.DbConnectionExtensions.IsAvailable(IDbConnection connection)
ClientConnectionId:00000000-0000-0000-0000-000000000000
Error Number:2,State:0,Class:20
 2018-09-12 17:57:46,564 [P1916/D4/T1] INFO  Umbraco.Core.DatabaseContext - CanConnect = False
 2018-09-12 17:57:46,692 [P1916/D4/T1] WARN  Umbraco.Core.Persistence.DbConnectionExtensions - Configured database is reporting as not being available! DataSource: .\ADULIS, InitialCatalog: umbraco. Exception: System.Data.SqlClient.SqlException (0x80131904): A network-related or instance-specific error occurred while establishing a connection to SQL Server. The server was not found or was not accessible. Verify that the instance name is correct and that SQL Server is configured to allow remote connections. (provider: Shared Memory Provider, error: 40 - Could not open a connection to SQL Server) ---> System.ComponentModel.Win32Exception (0x80004005): The system cannot find the file specified
   at System.Data.ProviderBase.DbConnectionPool.TryGetConnection(DbConnection owningObject, UInt32 waitForMultipleObjectsTimeout, Boolean allowCreate, Boolean onlyOneCheckConnection, DbConnectionOptions userOptions, DbConnectionInternal& connection)
   at System.Data.ProviderBase.DbConnectionPool.TryGetConnection(DbConnection owningObject, TaskCompletionSource`1 retry, DbConnectionOptions userOptions, DbConnectionInternal& connection)
   at System.Data.ProviderBase.DbConnectionFactory.TryGetConnection(DbConnection owningConnection, TaskCompletionSource`1 retry, DbConnectionOptions userOptions, DbConnectionInternal oldConnection, DbConnectionInternal& connection)
   at System.Data.ProviderBase.DbConnectionInternal.TryOpenConnectionInternal(DbConnection outerConnection, DbConnectionFactory connectionFactory, TaskCompletionSource`1 retry, DbConnectionOptions userOptions)
   at System.Data.ProviderBase.DbConnectionClosed.TryOpenConnection(DbConnection outerConnection, DbConnectionFactory connectionFactory, TaskCompletionSource`1 retry, DbConnectionOptions userOptions)
   at System.Data.SqlClient.SqlConnection.TryOpenInner(TaskCompletionSource`1 retry)
   at System.Data.SqlClient.SqlConnection.TryOpen(TaskCompletionSource`1 retry)
   at System.Data.SqlClient.SqlConnection.Open()
   at Umbraco.Core.Persistence.DbConnectionExtensions.IsAvailable(IDbConnection connection)
ClientConnectionId:00000000-0000-0000-0000-000000000000
Error Number:2,State:0,Class:20
 2018-09-12 17:57:46,693 [P1916/D4/T1] INFO  Umbraco.Core.DatabaseContext - CanConnect = False
 2018-09-12 17:57:47,694 [P1916/D4/T1] WARN  Umbraco.Core.Persistence.DbConnectionExtensions - Configured database is reporting as not being available! DataSource: .\ADULIS, InitialCatalog: umbraco. Exception: System.Data.SqlClient.SqlException (0x80131904): A network-related or instance-specific error occurred while establishing a connection to SQL Server. The server was not found or was not accessible. Verify that the instance name is correct and that SQL Server is configured to allow remote connections. (provider: Shared Memory Provider, error: 40 - Could not open a connection to SQL Server) ---> System.ComponentModel.Win32Exception (0x80004005): The system cannot find the file specified
   at System.Data.ProviderBase.DbConnectionPool.TryGetConnection(DbConnection owningObject, UInt32 waitForMultipleObjectsTimeout, Boolean allowCreate, Boolean onlyOneCheckConnection, DbConnectionOptions userOptions, DbConnectionInternal& connection)
   at System.Data.ProviderBase.DbConnectionPool.TryGetConnection(DbConnection owningObject, TaskCompletionSource`1 retry, DbConnectionOptions userOptions, DbConnectionInternal& connection)
   at System.Data.ProviderBase.DbConnectionFactory.TryGetConnection(DbConnection owningConnection, TaskCompletionSource`1 retry, DbConnectionOptions userOptions, DbConnectionInternal oldConnection, DbConnectionInternal& connection)
   at System.Data.ProviderBase.DbConnectionInternal.TryOpenConnectionInternal(DbConnection outerConnection, DbConnectionFactory connectionFactory, TaskCompletionSource`1 retry, DbConnectionOptions userOptions)
   at System.Data.ProviderBase.DbConnectionClosed.TryOpenConnection(DbConnection outerConnection, DbConnectionFactory connectionFactory, TaskCompletionSource`1 retry, DbConnectionOptions userOptions)
   at System.Data.SqlClient.SqlConnection.TryOpenInner(TaskCompletionSource`1 retry)
   at System.Data.SqlClient.SqlConnection.TryOpen(TaskCompletionSource`1 retry)
   at System.Data.SqlClient.SqlConnection.Open()
   at Umbraco.Core.Persistence.DbConnectionExtensions.IsAvailable(IDbConnection connection)
ClientConnectionId:00000000-0000-0000-0000-000000000000
Error Number:2,State:0,Class:20
 2018-09-12 17:57:47,696 [P1916/D4/T1] INFO  Umbraco.Core.DatabaseContext - CanConnect = False
 2018-09-12 17:57:48,699 [P1916/D4/T1] WARN  Umbraco.Core.Persistence.DbConnectionExtensions - Configured database is reporting as not being available! DataSource: .\ADULIS, InitialCatalog: umbraco. Exception: System.Data.SqlClient.SqlException (0x80131904): A network-related or instance-specific error occurred while establishing a connection to SQL Server. The server was not found or was not accessible. Verify that the instance name is correct and that SQL Server is configured to allow remote connections. (provider: Shared Memory Provider, error: 40 - Could not open a connection to SQL Server) ---> System.ComponentModel.Win32Exception (0x80004005): The system cannot find the file specified
   at System.Data.ProviderBase.DbConnectionPool.TryGetConnection(DbConnection owningObject, UInt32 waitForMultipleObjectsTimeout, Boolean allowCreate, Boolean onlyOneCheckConnection, DbConnectionOptions userOptions, DbConnectionInternal& connection)
   at System.Data.ProviderBase.DbConnectionPool.TryGetConnection(DbConnection owningObject, TaskCompletionSource`1 retry, DbConnectionOptions userOptions, DbConnectionInternal& connection)
   at System.Data.ProviderBase.DbConnectionFactory.TryGetConnection(DbConnection owningConnection, TaskCompletionSource`1 retry, DbConnectionOptions userOptions, DbConnectionInternal oldConnection, DbConnectionInternal& connection)
   at System.Data.ProviderBase.DbConnectionInternal.TryOpenConnectionInternal(DbConnection outerConnection, DbConnectionFactory connectionFactory, TaskCompletionSource`1 retry, DbConnectionOptions userOptions)
   at System.Data.ProviderBase.DbConnectionClosed.TryOpenConnection(DbConnection outerConnection, DbConnectionFactory connectionFactory, TaskCompletionSource`1 retry, DbConnectionOptions userOptions)
   at System.Data.SqlClient.SqlConnection.TryOpenInner(TaskCompletionSource`1 retry)
   at System.Data.SqlClient.SqlConnection.TryOpen(TaskCompletionSource`1 retry)
   at System.Data.SqlClient.SqlConnection.Open()
   at Umbraco.Core.Persistence.DbConnectionExtensions.IsAvailable(IDbConnection connection)
ClientConnectionId:00000000-0000-0000-0000-000000000000
Error Number:2,State:0,Class:20
 2018-09-12 17:57:48,699 [P1916/D4/T1] INFO  Umbraco.Core.DatabaseContext - CanConnect = False
 2018-09-12 17:57:49,701 [P1916/D4/T1] WARN  Umbraco.Core.Persistence.DbConnectionExtensions - Configured database is reporting as not being available! DataSource: .\ADULIS, InitialCatalog: umbraco. Exception: System.Data.SqlClient.SqlException (0x80131904): A network-related or instance-specific error occurred while establishing a connection to SQL Server. The server was not found or was not accessible. Verify that the instance name is correct and that SQL Server is configured to allow remote connections. (provider: Shared Memory Provider, error: 40 - Could not open a connection to SQL Server) ---> System.ComponentModel.Win32Exception (0x80004005): The system cannot find the file specified
   at System.Data.ProviderBase.DbConnectionPool.TryGetConnection(DbConnection owningObject, UInt32 waitForMultipleObjectsTimeout, Boolean allowCreate, Boolean onlyOneCheckConnection, DbConnectionOptions userOptions, DbConnectionInternal& connection)
   at System.Data.ProviderBase.DbConnectionPool.TryGetConnection(DbConnection owningObject, TaskCompletionSource`1 retry, DbConnectionOptions userOptions, DbConnectionInternal& connection)
   at System.Data.ProviderBase.DbConnectionFactory.TryGetConnection(DbConnection owningConnection, TaskCompletionSource`1 retry, DbConnectionOptions userOptions, DbConnectionInternal oldConnection, DbConnectionInternal& connection)
   at System.Data.ProviderBase.DbConnectionInternal.TryOpenConnectionInternal(DbConnection outerConnection, DbConnectionFactory connectionFactory, TaskCompletionSource`1 retry, DbConnectionOptions userOptions)
   at System.Data.ProviderBase.DbConnectionClosed.TryOpenConnection(DbConnection outerConnection, DbConnectionFactory connectionFactory, TaskCompletionSource`1 retry, DbConnectionOptions userOptions)
   at System.Data.SqlClient.SqlConnection.TryOpenInner(TaskCompletionSource`1 retry)
   at System.Data.SqlClient.SqlConnection.TryOpen(TaskCompletionSource`1 retry)
   at System.Data.SqlClient.SqlConnection.Open()
   at Umbraco.Core.Persistence.DbConnectionExtensions.IsAvailable(IDbConnection connection)
ClientConnectionId:00000000-0000-0000-0000-000000000000
Error Number:2,State:0,Class:20
 2018-09-12 17:57:49,702 [P1916/D4/T1] INFO  Umbraco.Core.DatabaseContext - CanConnect = False
 2018-09-12 17:57:50,703 [P1916/D4/T1] WARN  Umbraco.Core.Persistence.DbConnectionExtensions - Configured database is reporting as not being available! DataSource: .\ADULIS, InitialCatalog: umbraco. Exception: System.Data.SqlClient.SqlException (0x80131904): A network-related or instance-specific error occurred while establishing a connection to SQL Server. The server was not found or was not accessible. Verify that the instance name is correct and that SQL Server is configured to allow remote connections. (provider: Shared Memory Provider, error: 40 - Could not open a connection to SQL Server) ---> System.ComponentModel.Win32Exception (0x80004005): The system cannot find the file specified
   at System.Data.ProviderBase.DbConnectionPool.TryGetConnection(DbConnection owningObject, UInt32 waitForMultipleObjectsTimeout, Boolean allowCreate, Boolean onlyOneCheckConnection, DbConnectionOptions userOptions, DbConnectionInternal& connection)
   at System.Data.ProviderBase.DbConnectionPool.TryGetConnection(DbConnection owningObject, TaskCompletionSource`1 retry, DbConnectionOptions userOptions, DbConnectionInternal& connection)
   at System.Data.ProviderBase.DbConnectionFactory.TryGetConnection(DbConnection owningConnection, TaskCompletionSource`1 retry, DbConnectionOptions userOptions, DbConnectionInternal oldConnection, DbConnectionInternal& connection)
   at System.Data.ProviderBase.DbConnectionInternal.TryOpenConnectionInternal(DbConnection outerConnection, DbConnectionFactory connectionFactory, TaskCompletionSource`1 retry, DbConnectionOptions userOptions)
   at System.Data.ProviderBase.DbConnectionClosed.TryOpenConnection(DbConnection outerConnection, DbConnectionFactory connectionFactory, TaskCompletionSource`1 retry, DbConnectionOptions userOptions)
   at System.Data.SqlClient.SqlConnection.TryOpenInner(TaskCompletionSource`1 retry)
   at System.Data.SqlClient.SqlConnection.TryOpen(TaskCompletionSource`1 retry)
   at System.Data.SqlClient.SqlConnection.Open()
   at Umbraco.Core.Persistence.DbConnectionExtensions.IsAvailable(IDbConnection connection)
ClientConnectionId:00000000-0000-0000-0000-000000000000
Error Number:2,State:0,Class:20
 2018-09-12 17:57:50,704 [P1916/D4/T1] INFO  Umbraco.Core.DatabaseContext - CanConnect = False
 2018-09-12 17:58:06,283 [P1916/D4/T1] WARN  Umbraco.Core.Persistence.DbConnectionExtensions - Configured database is reporting as not being available! DataSource: .\ADULIS, InitialCatalog: umbraco. Exception: System.Data.SqlClient.SqlException (0x80131904): A network-related or instance-specific error occurred while establishing a connection to SQL Server. The server was not found or was not accessible. Verify that the instance name is correct and that SQL Server is configured to allow remote connections. (provider: Shared Memory Provider, error: 40 - Could not open a connection to SQL Server) ---> System.ComponentModel.Win32Exception (0x80004005): The system cannot find the file specified
   at System.Data.SqlClient.SqlInternalConnectionTds..ctor(DbConnectionPoolIdentity identity, SqlConnectionString connectionOptions, SqlCredential credential, Object providerInfo, String newPassword, SecureString newSecurePassword, Boolean redirectedUserInstance, SqlConnectionString userConnectionOptions, SessionData reconnectSessionData, DbConnectionPool pool, String accessToken, Boolean applyTransientFaultHandling, SqlAuthenticationProviderManager sqlAuthProviderManager)
   at System.Data.SqlClient.SqlConnectionFactory.CreateConnection(DbConnectionOptions options, DbConnectionPoolKey poolKey, Object poolGroupProviderInfo, DbConnectionPool pool, DbConnection owningConnection, DbConnectionOptions userOptions)
   at System.Data.ProviderBase.DbConnectionFactory.CreatePooledConnection(DbConnectionPool pool, DbConnection owningObject, DbConnectionOptions options, DbConnectionPoolKey poolKey, DbConnectionOptions userOptions)
   at System.Data.ProviderBase.DbConnectionPool.CreateObject(DbConnection owningObject, DbConnectionOptions userOptions, DbConnectionInternal oldConnection)
   at System.Data.ProviderBase.DbConnectionPool.UserCreateRequest(DbConnection owningObject, DbConnectionOptions userOptions, DbConnectionInternal oldConnection)
   at System.Data.ProviderBase.DbConnectionPool.TryGetConnection(DbConnection owningObject, UInt32 waitForMultipleObjectsTimeout, Boolean allowCreate, Boolean onlyOneCheckConnection, DbConnectionOptions userOptions, DbConnectionInternal& connection)
   at System.Data.ProviderBase.DbConnectionPool.TryGetConnection(DbConnection owningObject, TaskCompletionSource`1 retry, DbConnectionOptions userOptions, DbConnectionInternal& connection)
   at System.Data.ProviderBase.DbConnectionFactory.TryGetConnection(DbConnection owningConnection, TaskCompletionSource`1 retry, DbConnectionOptions userOptions, DbConnectionInternal oldConnection, DbConnectionInternal& connection)
   at System.Data.ProviderBase.DbConnectionInternal.TryOpenConnectionInternal(DbConnection outerConnection, DbConnectionFactory connectionFactory, TaskCompletionSource`1 retry, DbConnectionOptions userOptions)
   at System.Data.ProviderBase.DbConnectionClosed.TryOpenConnection(DbConnection outerConnection, DbConnectionFactory connectionFactory, TaskCompletionSource`1 retry, DbConnectionOptions userOptions)
   at System.Data.SqlClient.SqlConnection.TryOpenInner(TaskCompletionSource`1 retry)
   at System.Data.SqlClient.SqlConnection.TryOpen(TaskCompletionSource`1 retry)
   at System.Data.SqlClient.SqlConnection.Open()
   at Umbraco.Core.Persistence.DbConnectionExtensions.IsAvailable(IDbConnection connection)
ClientConnectionId:00000000-0000-0000-0000-000000000000
Error Number:2,State:0,Class:20
 2018-09-12 17:58:06,284 [P1916/D4/T1] INFO  Umbraco.Core.DatabaseContext - CanConnect = False
 2018-09-12 17:58:06,294 [P1916/D4/T1] ERROR Umbraco.Core.UmbracoApplicationBase - An unhandled exception occurred
Umbraco.Core.Exceptions.UmbracoStartupFailedException: Umbraco cannot start. A connection string is configured but Umbraco cannot connect to the database.
   at Umbraco.Core.CoreBootManager.EnsureDatabaseConnection()
   at Umbraco.Core.CoreBootManager.Complete(Action`1 afterComplete)
   at Umbraco.Web.WebBootManager.Complete(Action`1 afterComplete)
   at Umbraco.Core.UmbracoApplicationBase.StartApplication(Object sender, EventArgs e)
   at Umbraco.Core.UmbracoApplicationBase.Application_Start(Object sender, EventArgs e)
 2018-09-12 17:58:16,524 [P1916/D4/T50] INFO  Umbraco.Core.MainDom - Stopping...
 2018-09-12 17:58:16,526 [P1916/D4/T50] INFO  Umbraco.Web.ExamineStartup - Examine shutting down
 2018-09-12 17:58:16,528 [P1916/D4/T50] INFO  Umbraco.Web.ExamineStartup - Complete (took 1ms)
 2018-09-12 17:58:16,529 [P1916/D4/T50] INFO  Umbraco.Core.MainDom - Released MainDom.
 2018-09-12 17:58:46,643 [P1916/D4/T50] INFO  Umbraco.Core.UmbracoApplicationBase - Application shutdown. Details: InitializationError

_shutDownMessage=Initialization Error
HostingEnvironment initiated shutdown
HostingEnvironment caused shutdown

_shutDownStack=   at System.Environment.GetStackTrace(Exception e, Boolean needFileInfo)
   at System.Environment.get_StackTrace()
   at System.Web.Hosting.HostingEnvironment.InitiateShutdownInternal()
   at System.Web.Hosting.HostingEnvironment.InitiateShutdownWithoutDemand()
   at System.Web.HttpRuntime.ShutdownAppDomain(String stackTrace)
   at System.Web.HttpRuntime.AppDomainShutdownTimerCallback(Object state)
   at System.Threading.TimerQueueTimer.CallCallbackInContext(Object state)
   at System.Threading.ExecutionContext.RunInternal(ExecutionContext executionContext, ContextCallback callback, Object state, Boolean preserveSyncCtx)
   at System.Threading.ExecutionContext.Run(ExecutionContext executionContext, ContextCallback callback, Object state, Boolean preserveSyncCtx)
   at System.Threading.TimerQueueTimer.CallCallback()
   at System.Threading.TimerQueueTimer.Fire()
   at System.Threading.TimerQueue.FireNextTimers()
   at System.Threading.TimerQueue.AppDomainTimerCallback()
