 2018-09-20 21:30:17,221 [P2168/D2/T1] INFO  Umbraco.Core.CoreBootManager - Umbraco 7.11.1 application starting on SEMEREMEHAR57F0
 2018-09-20 21:30:17,248 [P2168/D2/T1] INFO  Umbraco.Core.PluginManager - Determining hash of code files on disk
 2018-09-20 21:30:18,273 [P2168/D2/T1] INFO  Umbraco.Core.PluginManager - Hash determined (took 1025ms)
 2018-09-20 21:30:18,362 [P2168/D2/T1] INFO  Umbraco.Core.MainDom - Acquiring MainDom...
 2018-09-20 21:30:18,363 [P2168/D2/T1] INFO  Umbraco.Core.MainDom - Acquired MainDom.
 2018-09-20 21:30:18,365 [P2168/D2/T1] INFO  Umbraco.Core.PluginManager - Resolving umbraco.interfaces.IDiscoverable
 2018-09-20 21:30:18,699 [P2168/D2/T1] INFO  Umbraco.Core.PluginManager - Resolved umbraco.interfaces.IDiscoverable (took 333ms)
 2018-09-20 21:30:18,699 [P2168/D2/T1] INFO  Umbraco.Core.PluginManager - Resolving umbraco.interfaces.IApplicationStartupHandler
 2018-09-20 21:30:18,713 [P2168/D2/T1] INFO  Umbraco.Core.PluginManager - Resolved umbraco.interfaces.IApplicationStartupHandler (took 13ms)
 2018-09-20 21:30:18,727 [P2168/D2/T1] INFO  Umbraco.Core.PluginManager - Resolving umbraco.interfaces.IDiscoverable
 2018-09-20 21:30:18,728 [P2168/D2/T1] INFO  Umbraco.Core.PluginManager - Resolved umbraco.interfaces.IDiscoverable (took 0ms)
 2018-09-20 21:30:18,728 [P2168/D2/T1] INFO  Umbraco.Core.PluginManager - Resolving Umbraco.Core.PropertyEditors.IPropertyEditorValueConverter
 2018-09-20 21:30:18,746 [P2168/D2/T1] INFO  Umbraco.Core.PluginManager - Resolved Umbraco.Core.PropertyEditors.IPropertyEditorValueConverter (took 18ms)
 2018-09-20 21:30:18,747 [P2168/D2/T1] INFO  Umbraco.Core.PluginManager - Resolving umbraco.interfaces.IDiscoverable
 2018-09-20 21:30:18,747 [P2168/D2/T1] INFO  Umbraco.Core.PluginManager - Resolved umbraco.interfaces.IDiscoverable (took 0ms)
 2018-09-20 21:30:18,748 [P2168/D2/T1] INFO  Umbraco.Core.PluginManager - Resolving Umbraco.Core.PropertyEditors.IPropertyValueConverter
 2018-09-20 21:30:18,761 [P2168/D2/T1] INFO  Umbraco.Core.PluginManager - Resolved Umbraco.Core.PropertyEditors.IPropertyValueConverter (took 13ms)
 2018-09-20 21:30:18,773 [P2168/D2/T1] INFO  Umbraco.Core.PluginManager - Resolving umbraco.interfaces.IDiscoverable
 2018-09-20 21:30:18,773 [P2168/D2/T1] INFO  Umbraco.Core.PluginManager - Resolved umbraco.interfaces.IDiscoverable (took 0ms)
 2018-09-20 21:30:18,774 [P2168/D2/T1] INFO  Umbraco.Core.PluginManager - Resolving Umbraco.Web.Mvc.SurfaceController
 2018-09-20 21:30:18,791 [P2168/D2/T1] INFO  Umbraco.Core.PluginManager - Resolved Umbraco.Web.Mvc.SurfaceController (took 17ms)
 2018-09-20 21:30:18,792 [P2168/D2/T1] INFO  Umbraco.Core.PluginManager - Resolving umbraco.interfaces.IDiscoverable
 2018-09-20 21:30:18,793 [P2168/D2/T1] INFO  Umbraco.Core.PluginManager - Resolved umbraco.interfaces.IDiscoverable (took 0ms)
 2018-09-20 21:30:18,794 [P2168/D2/T1] INFO  Umbraco.Core.PluginManager - Resolving Umbraco.Web.WebApi.UmbracoApiController
 2018-09-20 21:30:18,806 [P2168/D2/T1] INFO  Umbraco.Core.PluginManager - Resolved Umbraco.Web.WebApi.UmbracoApiController (took 12ms)
 2018-09-20 21:30:20,199 [P2168/D2/T1] WARN  Umbraco.Core.Persistence.DbConnectionExtensions - Configured database is reporting as not being available! DataSource: ., InitialCatalog: umbraco. Exception: System.Data.SqlClient.SqlException (0x80131904): Login failed for user 'umbraco_db_user'.
   at System.Data.SqlClient.SqlInternalConnectionTds..ctor(DbConnectionPoolIdentity identity, SqlConnectionString connectionOptions, SqlCredential credential, Object providerInfo, String newPassword, SecureString newSecurePassword, Boolean redirectedUserInstance, SqlConnectionString userConnectionOptions, SessionData reconnectSessionData, DbConnectionPool pool, String accessToken, Boolean applyTransientFaultHandling, SqlAuthenticationProviderManager sqlAuthProviderManager)
   at System.Data.SqlClient.SqlConnectionFactory.CreateConnection(DbConnectionOptions options, DbConnectionPoolKey poolKey, Object poolGroupProviderInfo, DbConnectionPool pool, DbConnection owningConnection, DbConnectionOptions userOptions)
   at System.Data.ProviderBase.DbConnectionFactory.CreatePooledConnection(DbConnectionPool pool, DbConnection owningObject, DbConnectionOptions options, DbConnectionPoolKey poolKey, DbConnectionOptions userOptions)
   at System.Data.ProviderBase.DbConnectionPool.CreateObject(DbConnection owningObject, DbConnectionOptions userOptions, DbConnectionInternal oldConnection)
   at System.Data.ProviderBase.DbConnectionPool.UserCreateRequest(DbConnection owningObject, DbConnectionOptions userOptions, DbConnectionInternal oldConnection)
   at System.Data.ProviderBase.DbConnectionPool.TryGetConnection(DbConnection owningObject, UInt32 waitForMultipleObjectsTimeout, Boolean allowCreate, Boolean onlyOneCheckConnection, DbConnectionOptions userOptions, DbConnectionInternal& connection)
   at System.Data.ProviderBase.DbConnectionPool.TryGetConnection(DbConnection owningObject, TaskCompletionSource`1 retry, DbConnectionOptions userOptions, DbConnectionInternal& connection)
   at System.Data.ProviderBase.DbConnectionFactory.TryGetConnection(DbConnection owningConnection, TaskCompletionSource`1 retry, DbConnectionOptions userOptions, DbConnectionInternal oldConnection, DbConnectionInternal& connection)
   at System.Data.ProviderBase.DbConnectionInternal.TryOpenConnectionInternal(DbConnection outerConnection, DbConnectionFactory connectionFactory, TaskCompletionSource`1 retry, DbConnectionOptions userOptions)
   at System.Data.ProviderBase.DbConnectionClosed.TryOpenConnection(DbConnection outerConnection, DbConnectionFactory connectionFactory, TaskCompletionSource`1 retry, DbConnectionOptions userOptions)
   at System.Data.SqlClient.SqlConnection.TryOpenInner(TaskCompletionSource`1 retry)
   at System.Data.SqlClient.SqlConnection.TryOpen(TaskCompletionSource`1 retry)
   at System.Data.SqlClient.SqlConnection.Open()
   at Umbraco.Core.Persistence.DbConnectionExtensions.IsAvailable(IDbConnection connection)
ClientConnectionId:b0d697c5-2c63-40d3-946b-b5cce905ffd0
Error Number:18456,State:1,Class:14
 2018-09-20 21:30:20,200 [P2168/D2/T1] INFO  Umbraco.Core.DatabaseContext - CanConnect = False
 2018-09-20 21:30:20,312 [P2168/D2/T1] WARN  Umbraco.Core.Persistence.DbConnectionExtensions - Configured database is reporting as not being available! DataSource: ., InitialCatalog: umbraco. Exception: System.Data.SqlClient.SqlException (0x80131904): Login failed for user 'umbraco_db_user'.
   at System.Data.ProviderBase.DbConnectionPool.TryGetConnection(DbConnection owningObject, UInt32 waitForMultipleObjectsTimeout, Boolean allowCreate, Boolean onlyOneCheckConnection, DbConnectionOptions userOptions, DbConnectionInternal& connection)
   at System.Data.ProviderBase.DbConnectionPool.TryGetConnection(DbConnection owningObject, TaskCompletionSource`1 retry, DbConnectionOptions userOptions, DbConnectionInternal& connection)
   at System.Data.ProviderBase.DbConnectionFactory.TryGetConnection(DbConnection owningConnection, TaskCompletionSource`1 retry, DbConnectionOptions userOptions, DbConnectionInternal oldConnection, DbConnectionInternal& connection)
   at System.Data.ProviderBase.DbConnectionInternal.TryOpenConnectionInternal(DbConnection outerConnection, DbConnectionFactory connectionFactory, TaskCompletionSource`1 retry, DbConnectionOptions userOptions)
   at System.Data.ProviderBase.DbConnectionClosed.TryOpenConnection(DbConnection outerConnection, DbConnectionFactory connectionFactory, TaskCompletionSource`1 retry, DbConnectionOptions userOptions)
   at System.Data.SqlClient.SqlConnection.TryOpenInner(TaskCompletionSource`1 retry)
   at System.Data.SqlClient.SqlConnection.TryOpen(TaskCompletionSource`1 retry)
   at System.Data.SqlClient.SqlConnection.Open()
   at Umbraco.Core.Persistence.DbConnectionExtensions.IsAvailable(IDbConnection connection)
ClientConnectionId:b0d697c5-2c63-40d3-946b-b5cce905ffd0
Error Number:18456,State:1,Class:14
 2018-09-20 21:30:20,313 [P2168/D2/T1] INFO  Umbraco.Core.DatabaseContext - CanConnect = False
 2018-09-20 21:30:21,314 [P2168/D2/T1] WARN  Umbraco.Core.Persistence.DbConnectionExtensions - Configured database is reporting as not being available! DataSource: ., InitialCatalog: umbraco. Exception: System.Data.SqlClient.SqlException (0x80131904): Login failed for user 'umbraco_db_user'.
   at System.Data.ProviderBase.DbConnectionPool.TryGetConnection(DbConnection owningObject, UInt32 waitForMultipleObjectsTimeout, Boolean allowCreate, Boolean onlyOneCheckConnection, DbConnectionOptions userOptions, DbConnectionInternal& connection)
   at System.Data.ProviderBase.DbConnectionPool.TryGetConnection(DbConnection owningObject, TaskCompletionSource`1 retry, DbConnectionOptions userOptions, DbConnectionInternal& connection)
   at System.Data.ProviderBase.DbConnectionFactory.TryGetConnection(DbConnection owningConnection, TaskCompletionSource`1 retry, DbConnectionOptions userOptions, DbConnectionInternal oldConnection, DbConnectionInternal& connection)
   at System.Data.ProviderBase.DbConnectionInternal.TryOpenConnectionInternal(DbConnection outerConnection, DbConnectionFactory connectionFactory, TaskCompletionSource`1 retry, DbConnectionOptions userOptions)
   at System.Data.ProviderBase.DbConnectionClosed.TryOpenConnection(DbConnection outerConnection, DbConnectionFactory connectionFactory, TaskCompletionSource`1 retry, DbConnectionOptions userOptions)
   at System.Data.SqlClient.SqlConnection.TryOpenInner(TaskCompletionSource`1 retry)
   at System.Data.SqlClient.SqlConnection.TryOpen(TaskCompletionSource`1 retry)
   at System.Data.SqlClient.SqlConnection.Open()
   at Umbraco.Core.Persistence.DbConnectionExtensions.IsAvailable(IDbConnection connection)
ClientConnectionId:b0d697c5-2c63-40d3-946b-b5cce905ffd0
Error Number:18456,State:1,Class:14
 2018-09-20 21:30:21,315 [P2168/D2/T1] INFO  Umbraco.Core.DatabaseContext - CanConnect = False
 2018-09-20 21:30:22,316 [P2168/D2/T1] WARN  Umbraco.Core.Persistence.DbConnectionExtensions - Configured database is reporting as not being available! DataSource: ., InitialCatalog: umbraco. Exception: System.Data.SqlClient.SqlException (0x80131904): Login failed for user 'umbraco_db_user'.
   at System.Data.ProviderBase.DbConnectionPool.TryGetConnection(DbConnection owningObject, UInt32 waitForMultipleObjectsTimeout, Boolean allowCreate, Boolean onlyOneCheckConnection, DbConnectionOptions userOptions, DbConnectionInternal& connection)
   at System.Data.ProviderBase.DbConnectionPool.TryGetConnection(DbConnection owningObject, TaskCompletionSource`1 retry, DbConnectionOptions userOptions, DbConnectionInternal& connection)
   at System.Data.ProviderBase.DbConnectionFactory.TryGetConnection(DbConnection owningConnection, TaskCompletionSource`1 retry, DbConnectionOptions userOptions, DbConnectionInternal oldConnection, DbConnectionInternal& connection)
   at System.Data.ProviderBase.DbConnectionInternal.TryOpenConnectionInternal(DbConnection outerConnection, DbConnectionFactory connectionFactory, TaskCompletionSource`1 retry, DbConnectionOptions userOptions)
   at System.Data.ProviderBase.DbConnectionClosed.TryOpenConnection(DbConnection outerConnection, DbConnectionFactory connectionFactory, TaskCompletionSource`1 retry, DbConnectionOptions userOptions)
   at System.Data.SqlClient.SqlConnection.TryOpenInner(TaskCompletionSource`1 retry)
   at System.Data.SqlClient.SqlConnection.TryOpen(TaskCompletionSource`1 retry)
   at System.Data.SqlClient.SqlConnection.Open()
   at Umbraco.Core.Persistence.DbConnectionExtensions.IsAvailable(IDbConnection connection)
ClientConnectionId:b0d697c5-2c63-40d3-946b-b5cce905ffd0
Error Number:18456,State:1,Class:14
 2018-09-20 21:30:22,317 [P2168/D2/T1] INFO  Umbraco.Core.DatabaseContext - CanConnect = False
 2018-09-20 21:30:23,318 [P2168/D2/T1] WARN  Umbraco.Core.Persistence.DbConnectionExtensions - Configured database is reporting as not being available! DataSource: ., InitialCatalog: umbraco. Exception: System.Data.SqlClient.SqlException (0x80131904): Login failed for user 'umbraco_db_user'.
   at System.Data.ProviderBase.DbConnectionPool.TryGetConnection(DbConnection owningObject, UInt32 waitForMultipleObjectsTimeout, Boolean allowCreate, Boolean onlyOneCheckConnection, DbConnectionOptions userOptions, DbConnectionInternal& connection)
   at System.Data.ProviderBase.DbConnectionPool.TryGetConnection(DbConnection owningObject, TaskCompletionSource`1 retry, DbConnectionOptions userOptions, DbConnectionInternal& connection)
   at System.Data.ProviderBase.DbConnectionFactory.TryGetConnection(DbConnection owningConnection, TaskCompletionSource`1 retry, DbConnectionOptions userOptions, DbConnectionInternal oldConnection, DbConnectionInternal& connection)
   at System.Data.ProviderBase.DbConnectionInternal.TryOpenConnectionInternal(DbConnection outerConnection, DbConnectionFactory connectionFactory, TaskCompletionSource`1 retry, DbConnectionOptions userOptions)
   at System.Data.ProviderBase.DbConnectionClosed.TryOpenConnection(DbConnection outerConnection, DbConnectionFactory connectionFactory, TaskCompletionSource`1 retry, DbConnectionOptions userOptions)
   at System.Data.SqlClient.SqlConnection.TryOpenInner(TaskCompletionSource`1 retry)
   at System.Data.SqlClient.SqlConnection.TryOpen(TaskCompletionSource`1 retry)
   at System.Data.SqlClient.SqlConnection.Open()
   at Umbraco.Core.Persistence.DbConnectionExtensions.IsAvailable(IDbConnection connection)
ClientConnectionId:b0d697c5-2c63-40d3-946b-b5cce905ffd0
Error Number:18456,State:1,Class:14
 2018-09-20 21:30:23,319 [P2168/D2/T1] INFO  Umbraco.Core.DatabaseContext - CanConnect = False
 2018-09-20 21:30:24,320 [P2168/D2/T1] WARN  Umbraco.Core.Persistence.DbConnectionExtensions - Configured database is reporting as not being available! DataSource: ., InitialCatalog: umbraco. Exception: System.Data.SqlClient.SqlException (0x80131904): Login failed for user 'umbraco_db_user'.
   at System.Data.ProviderBase.DbConnectionPool.TryGetConnection(DbConnection owningObject, UInt32 waitForMultipleObjectsTimeout, Boolean allowCreate, Boolean onlyOneCheckConnection, DbConnectionOptions userOptions, DbConnectionInternal& connection)
   at System.Data.ProviderBase.DbConnectionPool.TryGetConnection(DbConnection owningObject, TaskCompletionSource`1 retry, DbConnectionOptions userOptions, DbConnectionInternal& connection)
   at System.Data.ProviderBase.DbConnectionFactory.TryGetConnection(DbConnection owningConnection, TaskCompletionSource`1 retry, DbConnectionOptions userOptions, DbConnectionInternal oldConnection, DbConnectionInternal& connection)
   at System.Data.ProviderBase.DbConnectionInternal.TryOpenConnectionInternal(DbConnection outerConnection, DbConnectionFactory connectionFactory, TaskCompletionSource`1 retry, DbConnectionOptions userOptions)
   at System.Data.ProviderBase.DbConnectionClosed.TryOpenConnection(DbConnection outerConnection, DbConnectionFactory connectionFactory, TaskCompletionSource`1 retry, DbConnectionOptions userOptions)
   at System.Data.SqlClient.SqlConnection.TryOpenInner(TaskCompletionSource`1 retry)
   at System.Data.SqlClient.SqlConnection.TryOpen(TaskCompletionSource`1 retry)
   at System.Data.SqlClient.SqlConnection.Open()
   at Umbraco.Core.Persistence.DbConnectionExtensions.IsAvailable(IDbConnection connection)
ClientConnectionId:b0d697c5-2c63-40d3-946b-b5cce905ffd0
Error Number:18456,State:1,Class:14
 2018-09-20 21:30:24,321 [P2168/D2/T1] INFO  Umbraco.Core.DatabaseContext - CanConnect = False
 2018-09-20 21:30:25,327 [P2168/D2/T1] WARN  Umbraco.Core.Persistence.DbConnectionExtensions - Configured database is reporting as not being available! DataSource: ., InitialCatalog: umbraco. Exception: System.Data.SqlClient.SqlException (0x80131904): Login failed for user 'umbraco_db_user'.
   at System.Data.SqlClient.SqlInternalConnectionTds..ctor(DbConnectionPoolIdentity identity, SqlConnectionString connectionOptions, SqlCredential credential, Object providerInfo, String newPassword, SecureString newSecurePassword, Boolean redirectedUserInstance, SqlConnectionString userConnectionOptions, SessionData reconnectSessionData, DbConnectionPool pool, String accessToken, Boolean applyTransientFaultHandling, SqlAuthenticationProviderManager sqlAuthProviderManager)
   at System.Data.SqlClient.SqlConnectionFactory.CreateConnection(DbConnectionOptions options, DbConnectionPoolKey poolKey, Object poolGroupProviderInfo, DbConnectionPool pool, DbConnection owningConnection, DbConnectionOptions userOptions)
   at System.Data.ProviderBase.DbConnectionFactory.CreatePooledConnection(DbConnectionPool pool, DbConnection owningObject, DbConnectionOptions options, DbConnectionPoolKey poolKey, DbConnectionOptions userOptions)
   at System.Data.ProviderBase.DbConnectionPool.CreateObject(DbConnection owningObject, DbConnectionOptions userOptions, DbConnectionInternal oldConnection)
   at System.Data.ProviderBase.DbConnectionPool.UserCreateRequest(DbConnection owningObject, DbConnectionOptions userOptions, DbConnectionInternal oldConnection)
   at System.Data.ProviderBase.DbConnectionPool.TryGetConnection(DbConnection owningObject, UInt32 waitForMultipleObjectsTimeout, Boolean allowCreate, Boolean onlyOneCheckConnection, DbConnectionOptions userOptions, DbConnectionInternal& connection)
   at System.Data.ProviderBase.DbConnectionPool.TryGetConnection(DbConnection owningObject, TaskCompletionSource`1 retry, DbConnectionOptions userOptions, DbConnectionInternal& connection)
   at System.Data.ProviderBase.DbConnectionFactory.TryGetConnection(DbConnection owningConnection, TaskCompletionSource`1 retry, DbConnectionOptions userOptions, DbConnectionInternal oldConnection, DbConnectionInternal& connection)
   at System.Data.ProviderBase.DbConnectionInternal.TryOpenConnectionInternal(DbConnection outerConnection, DbConnectionFactory connectionFactory, TaskCompletionSource`1 retry, DbConnectionOptions userOptions)
   at System.Data.ProviderBase.DbConnectionClosed.TryOpenConnection(DbConnection outerConnection, DbConnectionFactory connectionFactory, TaskCompletionSource`1 retry, DbConnectionOptions userOptions)
   at System.Data.SqlClient.SqlConnection.TryOpenInner(TaskCompletionSource`1 retry)
   at System.Data.SqlClient.SqlConnection.TryOpen(TaskCompletionSource`1 retry)
   at System.Data.SqlClient.SqlConnection.Open()
   at Umbraco.Core.Persistence.DbConnectionExtensions.IsAvailable(IDbConnection connection)
ClientConnectionId:7a8d6046-8973-42cc-92a6-6dbfd8ef1482
Error Number:18456,State:1,Class:14
 2018-09-20 21:30:25,328 [P2168/D2/T1] INFO  Umbraco.Core.DatabaseContext - CanConnect = False
 2018-09-20 21:30:25,334 [P2168/D2/T1] ERROR Umbraco.Core.UmbracoApplicationBase - An unhandled exception occurred
Umbraco.Core.Exceptions.UmbracoStartupFailedException: Umbraco cannot start. A connection string is configured but Umbraco cannot connect to the database.
   at Umbraco.Core.CoreBootManager.EnsureDatabaseConnection()
   at Umbraco.Core.CoreBootManager.Complete(Action`1 afterComplete)
   at Umbraco.Web.WebBootManager.Complete(Action`1 afterComplete)
   at Umbraco.Core.UmbracoApplicationBase.StartApplication(Object sender, EventArgs e)
   at Umbraco.Core.UmbracoApplicationBase.Application_Start(Object sender, EventArgs e)
 2018-09-20 21:30:35,549 [P2168/D2/T7] INFO  Umbraco.Core.MainDom - Stopping...
 2018-09-20 21:30:35,552 [P2168/D2/T7] INFO  Umbraco.Web.ExamineStartup - Examine shutting down
 2018-09-20 21:30:35,555 [P2168/D2/T7] INFO  Umbraco.Web.ExamineStartup - Complete (took 2ms)
 2018-09-20 21:30:35,555 [P2168/D2/T7] INFO  Umbraco.Core.MainDom - Released MainDom.
 2018-09-20 21:31:05,693 [P2168/D2/T8] INFO  Umbraco.Core.UmbracoApplicationBase - Application shutdown. Details: InitializationError

_shutDownMessage=Initialization Error
HostingEnvironment initiated shutdown
HostingEnvironment caused shutdown

_shutDownStack=   at System.Environment.GetStackTrace(Exception e, Boolean needFileInfo)
   at System.Environment.get_StackTrace()
   at System.Web.Hosting.HostingEnvironment.InitiateShutdownInternal()
   at System.Web.Hosting.HostingEnvironment.InitiateShutdownWithoutDemand()
   at System.Web.HttpRuntime.ShutdownAppDomain(String stackTrace)
   at System.Web.HttpRuntime.AppDomainShutdownTimerCallback(Object state)
   at System.Threading.TimerQueueTimer.CallCallbackInContext(Object state)
   at System.Threading.ExecutionContext.RunInternal(ExecutionContext executionContext, ContextCallback callback, Object state, Boolean preserveSyncCtx)
   at System.Threading.ExecutionContext.Run(ExecutionContext executionContext, ContextCallback callback, Object state, Boolean preserveSyncCtx)
   at System.Threading.TimerQueueTimer.CallCallback()
   at System.Threading.TimerQueueTimer.Fire()
   at System.Threading.TimerQueue.FireNextTimers()
   at System.Threading.TimerQueue.AppDomainTimerCallback()
 2018-09-20 21:44:18,605 [P2168/D3/T13] INFO  Umbraco.Core.CoreBootManager - Umbraco 7.11.1 application starting on SEMEREMEHAR57F0
 2018-09-20 21:44:18,650 [P2168/D3/T13] INFO  Umbraco.Core.PluginManager - Determining hash of code files on disk
 2018-09-20 21:44:20,255 [P2168/D3/T13] INFO  Umbraco.Core.PluginManager - Hash determined (took 1607ms)
 2018-09-20 21:44:20,354 [P2168/D3/T13] INFO  Umbraco.Core.MainDom - Acquiring MainDom...
 2018-09-20 21:44:20,357 [P2168/D3/T13] INFO  Umbraco.Core.MainDom - Acquired MainDom.
 2018-09-20 21:44:20,360 [P2168/D3/T13] INFO  Umbraco.Core.PluginManager - Resolving umbraco.interfaces.IDiscoverable
 2018-09-20 21:44:21,346 [P2168/D3/T13] INFO  Umbraco.Core.PluginManager - Resolved umbraco.interfaces.IDiscoverable (took 986ms)
 2018-09-20 21:44:21,346 [P2168/D3/T13] INFO  Umbraco.Core.PluginManager - Resolving umbraco.interfaces.IApplicationStartupHandler
 2018-09-20 21:44:21,350 [P2168/D3/T13] INFO  Umbraco.Core.PluginManager - Resolved umbraco.interfaces.IApplicationStartupHandler (took 3ms)
 2018-09-20 21:44:21,432 [P2168/D3/T13] INFO  Umbraco.Core.PluginManager - Resolving umbraco.interfaces.IDiscoverable
 2018-09-20 21:44:21,433 [P2168/D3/T13] INFO  Umbraco.Core.PluginManager - Resolved umbraco.interfaces.IDiscoverable (took 1ms)
 2018-09-20 21:44:21,434 [P2168/D3/T13] INFO  Umbraco.Core.PluginManager - Resolving Umbraco.Core.PropertyEditors.IPropertyEditorValueConverter
 2018-09-20 21:44:21,435 [P2168/D3/T13] INFO  Umbraco.Core.PluginManager - Resolved Umbraco.Core.PropertyEditors.IPropertyEditorValueConverter (took 0ms)
 2018-09-20 21:44:21,435 [P2168/D3/T13] INFO  Umbraco.Core.PluginManager - Resolving umbraco.interfaces.IDiscoverable
 2018-09-20 21:44:21,437 [P2168/D3/T13] INFO  Umbraco.Core.PluginManager - Resolved umbraco.interfaces.IDiscoverable (took 2ms)
 2018-09-20 21:44:21,438 [P2168/D3/T13] INFO  Umbraco.Core.PluginManager - Resolving Umbraco.Core.PropertyEditors.IPropertyValueConverter
 2018-09-20 21:44:21,440 [P2168/D3/T13] INFO  Umbraco.Core.PluginManager - Resolved Umbraco.Core.PropertyEditors.IPropertyValueConverter (took 2ms)
 2018-09-20 21:44:21,464 [P2168/D3/T13] INFO  Umbraco.Core.PluginManager - Resolving umbraco.interfaces.IDiscoverable
 2018-09-20 21:44:21,465 [P2168/D3/T13] INFO  Umbraco.Core.PluginManager - Resolved umbraco.interfaces.IDiscoverable (took 0ms)
 2018-09-20 21:44:21,465 [P2168/D3/T13] INFO  Umbraco.Core.PluginManager - Resolving Umbraco.Web.Mvc.SurfaceController
 2018-09-20 21:44:21,466 [P2168/D3/T13] INFO  Umbraco.Core.PluginManager - Resolved Umbraco.Web.Mvc.SurfaceController (took 1ms)
 2018-09-20 21:44:21,469 [P2168/D3/T13] INFO  Umbraco.Core.PluginManager - Resolving umbraco.interfaces.IDiscoverable
 2018-09-20 21:44:21,469 [P2168/D3/T13] INFO  Umbraco.Core.PluginManager - Resolved umbraco.interfaces.IDiscoverable (took 0ms)
 2018-09-20 21:44:21,470 [P2168/D3/T13] INFO  Umbraco.Core.PluginManager - Resolving Umbraco.Web.WebApi.UmbracoApiController
 2018-09-20 21:44:21,472 [P2168/D3/T13] INFO  Umbraco.Core.PluginManager - Resolved Umbraco.Web.WebApi.UmbracoApiController (took 2ms)
 2018-09-20 21:44:24,207 [P2168/D3/T13] WARN  Umbraco.Core.Persistence.DbConnectionExtensions - Configured database is reporting as not being available! DataSource: ., InitialCatalog: umbraco. Exception: System.Data.SqlClient.SqlException (0x80131904): Login failed for user 'umbraco_db_user'.
   at System.Data.SqlClient.SqlInternalConnectionTds..ctor(DbConnectionPoolIdentity identity, SqlConnectionString connectionOptions, SqlCredential credential, Object providerInfo, String newPassword, SecureString newSecurePassword, Boolean redirectedUserInstance, SqlConnectionString userConnectionOptions, SessionData reconnectSessionData, DbConnectionPool pool, String accessToken, Boolean applyTransientFaultHandling, SqlAuthenticationProviderManager sqlAuthProviderManager)
   at System.Data.SqlClient.SqlConnectionFactory.CreateConnection(DbConnectionOptions options, DbConnectionPoolKey poolKey, Object poolGroupProviderInfo, DbConnectionPool pool, DbConnection owningConnection, DbConnectionOptions userOptions)
   at System.Data.ProviderBase.DbConnectionFactory.CreatePooledConnection(DbConnectionPool pool, DbConnection owningObject, DbConnectionOptions options, DbConnectionPoolKey poolKey, DbConnectionOptions userOptions)
   at System.Data.ProviderBase.DbConnectionPool.CreateObject(DbConnection owningObject, DbConnectionOptions userOptions, DbConnectionInternal oldConnection)
   at System.Data.ProviderBase.DbConnectionPool.UserCreateRequest(DbConnection owningObject, DbConnectionOptions userOptions, DbConnectionInternal oldConnection)
   at System.Data.ProviderBase.DbConnectionPool.TryGetConnection(DbConnection owningObject, UInt32 waitForMultipleObjectsTimeout, Boolean allowCreate, Boolean onlyOneCheckConnection, DbConnectionOptions userOptions, DbConnectionInternal& connection)
   at System.Data.ProviderBase.DbConnectionPool.TryGetConnection(DbConnection owningObject, TaskCompletionSource`1 retry, DbConnectionOptions userOptions, DbConnectionInternal& connection)
   at System.Data.ProviderBase.DbConnectionFactory.TryGetConnection(DbConnection owningConnection, TaskCompletionSource`1 retry, DbConnectionOptions userOptions, DbConnectionInternal oldConnection, DbConnectionInternal& connection)
   at System.Data.ProviderBase.DbConnectionInternal.TryOpenConnectionInternal(DbConnection outerConnection, DbConnectionFactory connectionFactory, TaskCompletionSource`1 retry, DbConnectionOptions userOptions)
   at System.Data.ProviderBase.DbConnectionClosed.TryOpenConnection(DbConnection outerConnection, DbConnectionFactory connectionFactory, TaskCompletionSource`1 retry, DbConnectionOptions userOptions)
   at System.Data.SqlClient.SqlConnection.TryOpenInner(TaskCompletionSource`1 retry)
   at System.Data.SqlClient.SqlConnection.TryOpen(TaskCompletionSource`1 retry)
   at System.Data.SqlClient.SqlConnection.Open()
   at Umbraco.Core.Persistence.DbConnectionExtensions.IsAvailable(IDbConnection connection)
ClientConnectionId:afd27528-3bdc-49ae-b0fb-9be69dd2bac2
Error Number:18456,State:1,Class:14
 2018-09-20 21:44:24,210 [P2168/D3/T13] INFO  Umbraco.Core.DatabaseContext - CanConnect = False
 2018-09-20 21:44:24,554 [P2168/D3/T13] WARN  Umbraco.Core.Persistence.DbConnectionExtensions - Configured database is reporting as not being available! DataSource: ., InitialCatalog: umbraco. Exception: System.Data.SqlClient.SqlException (0x80131904): Login failed for user 'umbraco_db_user'.
   at System.Data.ProviderBase.DbConnectionPool.TryGetConnection(DbConnection owningObject, UInt32 waitForMultipleObjectsTimeout, Boolean allowCreate, Boolean onlyOneCheckConnection, DbConnectionOptions userOptions, DbConnectionInternal& connection)
   at System.Data.ProviderBase.DbConnectionPool.TryGetConnection(DbConnection owningObject, TaskCompletionSource`1 retry, DbConnectionOptions userOptions, DbConnectionInternal& connection)
   at System.Data.ProviderBase.DbConnectionFactory.TryGetConnection(DbConnection owningConnection, TaskCompletionSource`1 retry, DbConnectionOptions userOptions, DbConnectionInternal oldConnection, DbConnectionInternal& connection)
   at System.Data.ProviderBase.DbConnectionInternal.TryOpenConnectionInternal(DbConnection outerConnection, DbConnectionFactory connectionFactory, TaskCompletionSource`1 retry, DbConnectionOptions userOptions)
   at System.Data.ProviderBase.DbConnectionClosed.TryOpenConnection(DbConnection outerConnection, DbConnectionFactory connectionFactory, TaskCompletionSource`1 retry, DbConnectionOptions userOptions)
   at System.Data.SqlClient.SqlConnection.TryOpenInner(TaskCompletionSource`1 retry)
   at System.Data.SqlClient.SqlConnection.TryOpen(TaskCompletionSource`1 retry)
   at System.Data.SqlClient.SqlConnection.Open()
   at Umbraco.Core.Persistence.DbConnectionExtensions.IsAvailable(IDbConnection connection)
ClientConnectionId:afd27528-3bdc-49ae-b0fb-9be69dd2bac2
Error Number:18456,State:1,Class:14
 2018-09-20 21:44:24,555 [P2168/D3/T13] INFO  Umbraco.Core.DatabaseContext - CanConnect = False
 2018-09-20 21:44:25,557 [P2168/D3/T13] WARN  Umbraco.Core.Persistence.DbConnectionExtensions - Configured database is reporting as not being available! DataSource: ., InitialCatalog: umbraco. Exception: System.Data.SqlClient.SqlException (0x80131904): Login failed for user 'umbraco_db_user'.
   at System.Data.ProviderBase.DbConnectionPool.TryGetConnection(DbConnection owningObject, UInt32 waitForMultipleObjectsTimeout, Boolean allowCreate, Boolean onlyOneCheckConnection, DbConnectionOptions userOptions, DbConnectionInternal& connection)
   at System.Data.ProviderBase.DbConnectionPool.TryGetConnection(DbConnection owningObject, TaskCompletionSource`1 retry, DbConnectionOptions userOptions, DbConnectionInternal& connection)
   at System.Data.ProviderBase.DbConnectionFactory.TryGetConnection(DbConnection owningConnection, TaskCompletionSource`1 retry, DbConnectionOptions userOptions, DbConnectionInternal oldConnection, DbConnectionInternal& connection)
   at System.Data.ProviderBase.DbConnectionInternal.TryOpenConnectionInternal(DbConnection outerConnection, DbConnectionFactory connectionFactory, TaskCompletionSource`1 retry, DbConnectionOptions userOptions)
   at System.Data.ProviderBase.DbConnectionClosed.TryOpenConnection(DbConnection outerConnection, DbConnectionFactory connectionFactory, TaskCompletionSource`1 retry, DbConnectionOptions userOptions)
   at System.Data.SqlClient.SqlConnection.TryOpenInner(TaskCompletionSource`1 retry)
   at System.Data.SqlClient.SqlConnection.TryOpen(TaskCompletionSource`1 retry)
   at System.Data.SqlClient.SqlConnection.Open()
   at Umbraco.Core.Persistence.DbConnectionExtensions.IsAvailable(IDbConnection connection)
ClientConnectionId:afd27528-3bdc-49ae-b0fb-9be69dd2bac2
Error Number:18456,State:1,Class:14
 2018-09-20 21:44:25,557 [P2168/D3/T13] INFO  Umbraco.Core.DatabaseContext - CanConnect = False
 2018-09-20 21:44:26,559 [P2168/D3/T13] WARN  Umbraco.Core.Persistence.DbConnectionExtensions - Configured database is reporting as not being available! DataSource: ., InitialCatalog: umbraco. Exception: System.Data.SqlClient.SqlException (0x80131904): Login failed for user 'umbraco_db_user'.
   at System.Data.ProviderBase.DbConnectionPool.TryGetConnection(DbConnection owningObject, UInt32 waitForMultipleObjectsTimeout, Boolean allowCreate, Boolean onlyOneCheckConnection, DbConnectionOptions userOptions, DbConnectionInternal& connection)
   at System.Data.ProviderBase.DbConnectionPool.TryGetConnection(DbConnection owningObject, TaskCompletionSource`1 retry, DbConnectionOptions userOptions, DbConnectionInternal& connection)
   at System.Data.ProviderBase.DbConnectionFactory.TryGetConnection(DbConnection owningConnection, TaskCompletionSource`1 retry, DbConnectionOptions userOptions, DbConnectionInternal oldConnection, DbConnectionInternal& connection)
   at System.Data.ProviderBase.DbConnectionInternal.TryOpenConnectionInternal(DbConnection outerConnection, DbConnectionFactory connectionFactory, TaskCompletionSource`1 retry, DbConnectionOptions userOptions)
   at System.Data.ProviderBase.DbConnectionClosed.TryOpenConnection(DbConnection outerConnection, DbConnectionFactory connectionFactory, TaskCompletionSource`1 retry, DbConnectionOptions userOptions)
   at System.Data.SqlClient.SqlConnection.TryOpenInner(TaskCompletionSource`1 retry)
   at System.Data.SqlClient.SqlConnection.TryOpen(TaskCompletionSource`1 retry)
   at System.Data.SqlClient.SqlConnection.Open()
   at Umbraco.Core.Persistence.DbConnectionExtensions.IsAvailable(IDbConnection connection)
ClientConnectionId:afd27528-3bdc-49ae-b0fb-9be69dd2bac2
Error Number:18456,State:1,Class:14
 2018-09-20 21:44:26,559 [P2168/D3/T13] INFO  Umbraco.Core.DatabaseContext - CanConnect = False
 2018-09-20 21:44:27,560 [P2168/D3/T13] WARN  Umbraco.Core.Persistence.DbConnectionExtensions - Configured database is reporting as not being available! DataSource: ., InitialCatalog: umbraco. Exception: System.Data.SqlClient.SqlException (0x80131904): Login failed for user 'umbraco_db_user'.
   at System.Data.ProviderBase.DbConnectionPool.TryGetConnection(DbConnection owningObject, UInt32 waitForMultipleObjectsTimeout, Boolean allowCreate, Boolean onlyOneCheckConnection, DbConnectionOptions userOptions, DbConnectionInternal& connection)
   at System.Data.ProviderBase.DbConnectionPool.TryGetConnection(DbConnection owningObject, TaskCompletionSource`1 retry, DbConnectionOptions userOptions, DbConnectionInternal& connection)
   at System.Data.ProviderBase.DbConnectionFactory.TryGetConnection(DbConnection owningConnection, TaskCompletionSource`1 retry, DbConnectionOptions userOptions, DbConnectionInternal oldConnection, DbConnectionInternal& connection)
   at System.Data.ProviderBase.DbConnectionInternal.TryOpenConnectionInternal(DbConnection outerConnection, DbConnectionFactory connectionFactory, TaskCompletionSource`1 retry, DbConnectionOptions userOptions)
   at System.Data.ProviderBase.DbConnectionClosed.TryOpenConnection(DbConnection outerConnection, DbConnectionFactory connectionFactory, TaskCompletionSource`1 retry, DbConnectionOptions userOptions)
   at System.Data.SqlClient.SqlConnection.TryOpenInner(TaskCompletionSource`1 retry)
   at System.Data.SqlClient.SqlConnection.TryOpen(TaskCompletionSource`1 retry)
   at System.Data.SqlClient.SqlConnection.Open()
   at Umbraco.Core.Persistence.DbConnectionExtensions.IsAvailable(IDbConnection connection)
ClientConnectionId:afd27528-3bdc-49ae-b0fb-9be69dd2bac2
Error Number:18456,State:1,Class:14
 2018-09-20 21:44:27,561 [P2168/D3/T13] INFO  Umbraco.Core.DatabaseContext - CanConnect = False
 2018-09-20 21:44:28,563 [P2168/D3/T13] WARN  Umbraco.Core.Persistence.DbConnectionExtensions - Configured database is reporting as not being available! DataSource: ., InitialCatalog: umbraco. Exception: System.Data.SqlClient.SqlException (0x80131904): Login failed for user 'umbraco_db_user'.
   at System.Data.ProviderBase.DbConnectionPool.TryGetConnection(DbConnection owningObject, UInt32 waitForMultipleObjectsTimeout, Boolean allowCreate, Boolean onlyOneCheckConnection, DbConnectionOptions userOptions, DbConnectionInternal& connection)
   at System.Data.ProviderBase.DbConnectionPool.TryGetConnection(DbConnection owningObject, TaskCompletionSource`1 retry, DbConnectionOptions userOptions, DbConnectionInternal& connection)
   at System.Data.ProviderBase.DbConnectionFactory.TryGetConnection(DbConnection owningConnection, TaskCompletionSource`1 retry, DbConnectionOptions userOptions, DbConnectionInternal oldConnection, DbConnectionInternal& connection)
   at System.Data.ProviderBase.DbConnectionInternal.TryOpenConnectionInternal(DbConnection outerConnection, DbConnectionFactory connectionFactory, TaskCompletionSource`1 retry, DbConnectionOptions userOptions)
   at System.Data.ProviderBase.DbConnectionClosed.TryOpenConnection(DbConnection outerConnection, DbConnectionFactory connectionFactory, TaskCompletionSource`1 retry, DbConnectionOptions userOptions)
   at System.Data.SqlClient.SqlConnection.TryOpenInner(TaskCompletionSource`1 retry)
   at System.Data.SqlClient.SqlConnection.TryOpen(TaskCompletionSource`1 retry)
   at System.Data.SqlClient.SqlConnection.Open()
   at Umbraco.Core.Persistence.DbConnectionExtensions.IsAvailable(IDbConnection connection)
ClientConnectionId:afd27528-3bdc-49ae-b0fb-9be69dd2bac2
Error Number:18456,State:1,Class:14
 2018-09-20 21:44:28,563 [P2168/D3/T13] INFO  Umbraco.Core.DatabaseContext - CanConnect = False
 2018-09-20 21:44:29,569 [P2168/D3/T13] WARN  Umbraco.Core.Persistence.DbConnectionExtensions - Configured database is reporting as not being available! DataSource: ., InitialCatalog: umbraco. Exception: System.Data.SqlClient.SqlException (0x80131904): Login failed for user 'umbraco_db_user'.
   at System.Data.SqlClient.SqlInternalConnectionTds..ctor(DbConnectionPoolIdentity identity, SqlConnectionString connectionOptions, SqlCredential credential, Object providerInfo, String newPassword, SecureString newSecurePassword, Boolean redirectedUserInstance, SqlConnectionString userConnectionOptions, SessionData reconnectSessionData, DbConnectionPool pool, String accessToken, Boolean applyTransientFaultHandling, SqlAuthenticationProviderManager sqlAuthProviderManager)
   at System.Data.SqlClient.SqlConnectionFactory.CreateConnection(DbConnectionOptions options, DbConnectionPoolKey poolKey, Object poolGroupProviderInfo, DbConnectionPool pool, DbConnection owningConnection, DbConnectionOptions userOptions)
   at System.Data.ProviderBase.DbConnectionFactory.CreatePooledConnection(DbConnectionPool pool, DbConnection owningObject, DbConnectionOptions options, DbConnectionPoolKey poolKey, DbConnectionOptions userOptions)
   at System.Data.ProviderBase.DbConnectionPool.CreateObject(DbConnection owningObject, DbConnectionOptions userOptions, DbConnectionInternal oldConnection)
   at System.Data.ProviderBase.DbConnectionPool.UserCreateRequest(DbConnection owningObject, DbConnectionOptions userOptions, DbConnectionInternal oldConnection)
   at System.Data.ProviderBase.DbConnectionPool.TryGetConnection(DbConnection owningObject, UInt32 waitForMultipleObjectsTimeout, Boolean allowCreate, Boolean onlyOneCheckConnection, DbConnectionOptions userOptions, DbConnectionInternal& connection)
   at System.Data.ProviderBase.DbConnectionPool.TryGetConnection(DbConnection owningObject, TaskCompletionSource`1 retry, DbConnectionOptions userOptions, DbConnectionInternal& connection)
   at System.Data.ProviderBase.DbConnectionFactory.TryGetConnection(DbConnection owningConnection, TaskCompletionSource`1 retry, DbConnectionOptions userOptions, DbConnectionInternal oldConnection, DbConnectionInternal& connection)
   at System.Data.ProviderBase.DbConnectionInternal.TryOpenConnectionInternal(DbConnection outerConnection, DbConnectionFactory connectionFactory, TaskCompletionSource`1 retry, DbConnectionOptions userOptions)
   at System.Data.ProviderBase.DbConnectionClosed.TryOpenConnection(DbConnection outerConnection, DbConnectionFactory connectionFactory, TaskCompletionSource`1 retry, DbConnectionOptions userOptions)
   at System.Data.SqlClient.SqlConnection.TryOpenInner(TaskCompletionSource`1 retry)
   at System.Data.SqlClient.SqlConnection.TryOpen(TaskCompletionSource`1 retry)
   at System.Data.SqlClient.SqlConnection.Open()
   at Umbraco.Core.Persistence.DbConnectionExtensions.IsAvailable(IDbConnection connection)
ClientConnectionId:2f45c43b-4ec2-46db-b107-4cd4dae79e83
Error Number:18456,State:1,Class:14
 2018-09-20 21:44:29,570 [P2168/D3/T13] INFO  Umbraco.Core.DatabaseContext - CanConnect = False
 2018-09-20 21:44:29,577 [P2168/D3/T13] ERROR Umbraco.Core.UmbracoApplicationBase - An unhandled exception occurred
Umbraco.Core.Exceptions.UmbracoStartupFailedException: Umbraco cannot start. A connection string is configured but Umbraco cannot connect to the database.
   at Umbraco.Core.CoreBootManager.EnsureDatabaseConnection()
   at Umbraco.Core.CoreBootManager.Complete(Action`1 afterComplete)
   at Umbraco.Web.WebBootManager.Complete(Action`1 afterComplete)
   at Umbraco.Core.UmbracoApplicationBase.StartApplication(Object sender, EventArgs e)
   at Umbraco.Core.UmbracoApplicationBase.Application_Start(Object sender, EventArgs e)
 2018-09-20 21:44:39,965 [P2168/D3/T8] INFO  Umbraco.Core.MainDom - Stopping...
 2018-09-20 21:44:39,966 [P2168/D3/T8] INFO  Umbraco.Web.ExamineStartup - Examine shutting down
 2018-09-20 21:44:39,968 [P2168/D3/T8] INFO  Umbraco.Web.ExamineStartup - Complete (took 2ms)
 2018-09-20 21:44:39,969 [P2168/D3/T8] INFO  Umbraco.Core.MainDom - Released MainDom.
 2018-09-20 21:44:55,668 [P2168/D4/T13] INFO  Umbraco.Core.CoreBootManager - Umbraco 7.11.1 application starting on SEMEREMEHAR57F0
 2018-09-20 21:44:55,697 [P2168/D4/T13] INFO  Umbraco.Core.PluginManager - Determining hash of code files on disk
 2018-09-20 21:44:57,221 [P2168/D4/T13] INFO  Umbraco.Core.PluginManager - Hash determined (took 1524ms)
 2018-09-20 21:44:57,278 [P2168/D4/T13] INFO  Umbraco.Core.MainDom - Acquiring MainDom...
 2018-09-20 21:44:57,280 [P2168/D4/T13] INFO  Umbraco.Core.MainDom - Acquired MainDom.
 2018-09-20 21:44:57,283 [P2168/D4/T13] INFO  Umbraco.Core.PluginManager - Resolving umbraco.interfaces.IDiscoverable
 2018-09-20 21:44:57,826 [P2168/D4/T13] INFO  Umbraco.Core.PluginManager - Resolved umbraco.interfaces.IDiscoverable (took 543ms)
 2018-09-20 21:44:57,827 [P2168/D4/T13] INFO  Umbraco.Core.PluginManager - Resolving umbraco.interfaces.IApplicationStartupHandler
 2018-09-20 21:44:57,829 [P2168/D4/T13] INFO  Umbraco.Core.PluginManager - Resolved umbraco.interfaces.IApplicationStartupHandler (took 2ms)
 2018-09-20 21:44:57,882 [P2168/D4/T13] INFO  Umbraco.Core.PluginManager - Resolving umbraco.interfaces.IDiscoverable
 2018-09-20 21:44:57,883 [P2168/D4/T13] INFO  Umbraco.Core.PluginManager - Resolved umbraco.interfaces.IDiscoverable (took 0ms)
 2018-09-20 21:44:57,884 [P2168/D4/T13] INFO  Umbraco.Core.PluginManager - Resolving Umbraco.Core.PropertyEditors.IPropertyEditorValueConverter
 2018-09-20 21:44:57,885 [P2168/D4/T13] INFO  Umbraco.Core.PluginManager - Resolved Umbraco.Core.PropertyEditors.IPropertyEditorValueConverter (took 1ms)
 2018-09-20 21:44:57,885 [P2168/D4/T13] INFO  Umbraco.Core.PluginManager - Resolving umbraco.interfaces.IDiscoverable
 2018-09-20 21:44:57,886 [P2168/D4/T13] INFO  Umbraco.Core.PluginManager - Resolved umbraco.interfaces.IDiscoverable (took 0ms)
 2018-09-20 21:44:57,886 [P2168/D4/T13] INFO  Umbraco.Core.PluginManager - Resolving Umbraco.Core.PropertyEditors.IPropertyValueConverter
 2018-09-20 21:44:57,888 [P2168/D4/T13] INFO  Umbraco.Core.PluginManager - Resolved Umbraco.Core.PropertyEditors.IPropertyValueConverter (took 1ms)
 2018-09-20 21:44:57,906 [P2168/D4/T13] INFO  Umbraco.Core.PluginManager - Resolving umbraco.interfaces.IDiscoverable
 2018-09-20 21:44:57,907 [P2168/D4/T13] INFO  Umbraco.Core.PluginManager - Resolved umbraco.interfaces.IDiscoverable (took 0ms)
 2018-09-20 21:44:57,907 [P2168/D4/T13] INFO  Umbraco.Core.PluginManager - Resolving Umbraco.Web.Mvc.SurfaceController
 2018-09-20 21:44:57,908 [P2168/D4/T13] INFO  Umbraco.Core.PluginManager - Resolved Umbraco.Web.Mvc.SurfaceController (took 0ms)
 2018-09-20 21:44:57,909 [P2168/D4/T13] INFO  Umbraco.Core.PluginManager - Resolving umbraco.interfaces.IDiscoverable
 2018-09-20 21:44:57,910 [P2168/D4/T13] INFO  Umbraco.Core.PluginManager - Resolved umbraco.interfaces.IDiscoverable (took 0ms)
 2018-09-20 21:44:57,910 [P2168/D4/T13] INFO  Umbraco.Core.PluginManager - Resolving Umbraco.Web.WebApi.UmbracoApiController
 2018-09-20 21:44:57,913 [P2168/D4/T13] INFO  Umbraco.Core.PluginManager - Resolved Umbraco.Web.WebApi.UmbracoApiController (took 2ms)
 2018-09-20 21:45:00,153 [P2168/D4/T13] WARN  Umbraco.Core.Persistence.DbConnectionExtensions - Configured database is reporting as not being available! DataSource: ., InitialCatalog: umbraco. Exception: System.Data.SqlClient.SqlException (0x80131904): Login failed for user 'umbraco_db_user'.
   at System.Data.SqlClient.SqlInternalConnectionTds..ctor(DbConnectionPoolIdentity identity, SqlConnectionString connectionOptions, SqlCredential credential, Object providerInfo, String newPassword, SecureString newSecurePassword, Boolean redirectedUserInstance, SqlConnectionString userConnectionOptions, SessionData reconnectSessionData, DbConnectionPool pool, String accessToken, Boolean applyTransientFaultHandling, SqlAuthenticationProviderManager sqlAuthProviderManager)
   at System.Data.SqlClient.SqlConnectionFactory.CreateConnection(DbConnectionOptions options, DbConnectionPoolKey poolKey, Object poolGroupProviderInfo, DbConnectionPool pool, DbConnection owningConnection, DbConnectionOptions userOptions)
   at System.Data.ProviderBase.DbConnectionFactory.CreatePooledConnection(DbConnectionPool pool, DbConnection owningObject, DbConnectionOptions options, DbConnectionPoolKey poolKey, DbConnectionOptions userOptions)
   at System.Data.ProviderBase.DbConnectionPool.CreateObject(DbConnection owningObject, DbConnectionOptions userOptions, DbConnectionInternal oldConnection)
   at System.Data.ProviderBase.DbConnectionPool.UserCreateRequest(DbConnection owningObject, DbConnectionOptions userOptions, DbConnectionInternal oldConnection)
   at System.Data.ProviderBase.DbConnectionPool.TryGetConnection(DbConnection owningObject, UInt32 waitForMultipleObjectsTimeout, Boolean allowCreate, Boolean onlyOneCheckConnection, DbConnectionOptions userOptions, DbConnectionInternal& connection)
   at System.Data.ProviderBase.DbConnectionPool.TryGetConnection(DbConnection owningObject, TaskCompletionSource`1 retry, DbConnectionOptions userOptions, DbConnectionInternal& connection)
   at System.Data.ProviderBase.DbConnectionFactory.TryGetConnection(DbConnection owningConnection, TaskCompletionSource`1 retry, DbConnectionOptions userOptions, DbConnectionInternal oldConnection, DbConnectionInternal& connection)
   at System.Data.ProviderBase.DbConnectionInternal.TryOpenConnectionInternal(DbConnection outerConnection, DbConnectionFactory connectionFactory, TaskCompletionSource`1 retry, DbConnectionOptions userOptions)
   at System.Data.ProviderBase.DbConnectionClosed.TryOpenConnection(DbConnection outerConnection, DbConnectionFactory connectionFactory, TaskCompletionSource`1 retry, DbConnectionOptions userOptions)
   at System.Data.SqlClient.SqlConnection.TryOpenInner(TaskCompletionSource`1 retry)
   at System.Data.SqlClient.SqlConnection.TryOpen(TaskCompletionSource`1 retry)
   at System.Data.SqlClient.SqlConnection.Open()
   at Umbraco.Core.Persistence.DbConnectionExtensions.IsAvailable(IDbConnection connection)
ClientConnectionId:3a26a323-3f2f-401e-b5b1-4a573d76d1a9
Error Number:18456,State:1,Class:14
 2018-09-20 21:45:00,153 [P2168/D4/T13] INFO  Umbraco.Core.DatabaseContext - CanConnect = False
 2018-09-20 21:45:00,428 [P2168/D4/T13] WARN  Umbraco.Core.Persistence.DbConnectionExtensions - Configured database is reporting as not being available! DataSource: ., InitialCatalog: umbraco. Exception: System.Data.SqlClient.SqlException (0x80131904): Login failed for user 'umbraco_db_user'.
   at System.Data.ProviderBase.DbConnectionPool.TryGetConnection(DbConnection owningObject, UInt32 waitForMultipleObjectsTimeout, Boolean allowCreate, Boolean onlyOneCheckConnection, DbConnectionOptions userOptions, DbConnectionInternal& connection)
   at System.Data.ProviderBase.DbConnectionPool.TryGetConnection(DbConnection owningObject, TaskCompletionSource`1 retry, DbConnectionOptions userOptions, DbConnectionInternal& connection)
   at System.Data.ProviderBase.DbConnectionFactory.TryGetConnection(DbConnection owningConnection, TaskCompletionSource`1 retry, DbConnectionOptions userOptions, DbConnectionInternal oldConnection, DbConnectionInternal& connection)
   at System.Data.ProviderBase.DbConnectionInternal.TryOpenConnectionInternal(DbConnection outerConnection, DbConnectionFactory connectionFactory, TaskCompletionSource`1 retry, DbConnectionOptions userOptions)
   at System.Data.ProviderBase.DbConnectionClosed.TryOpenConnection(DbConnection outerConnection, DbConnectionFactory connectionFactory, TaskCompletionSource`1 retry, DbConnectionOptions userOptions)
   at System.Data.SqlClient.SqlConnection.TryOpenInner(TaskCompletionSource`1 retry)
   at System.Data.SqlClient.SqlConnection.TryOpen(TaskCompletionSource`1 retry)
   at System.Data.SqlClient.SqlConnection.Open()
   at Umbraco.Core.Persistence.DbConnectionExtensions.IsAvailable(IDbConnection connection)
ClientConnectionId:3a26a323-3f2f-401e-b5b1-4a573d76d1a9
Error Number:18456,State:1,Class:14
 2018-09-20 21:45:00,428 [P2168/D4/T13] INFO  Umbraco.Core.DatabaseContext - CanConnect = False
 2018-09-20 21:45:01,430 [P2168/D4/T13] WARN  Umbraco.Core.Persistence.DbConnectionExtensions - Configured database is reporting as not being available! DataSource: ., InitialCatalog: umbraco. Exception: System.Data.SqlClient.SqlException (0x80131904): Login failed for user 'umbraco_db_user'.
   at System.Data.ProviderBase.DbConnectionPool.TryGetConnection(DbConnection owningObject, UInt32 waitForMultipleObjectsTimeout, Boolean allowCreate, Boolean onlyOneCheckConnection, DbConnectionOptions userOptions, DbConnectionInternal& connection)
   at System.Data.ProviderBase.DbConnectionPool.TryGetConnection(DbConnection owningObject, TaskCompletionSource`1 retry, DbConnectionOptions userOptions, DbConnectionInternal& connection)
   at System.Data.ProviderBase.DbConnectionFactory.TryGetConnection(DbConnection owningConnection, TaskCompletionSource`1 retry, DbConnectionOptions userOptions, DbConnectionInternal oldConnection, DbConnectionInternal& connection)
   at System.Data.ProviderBase.DbConnectionInternal.TryOpenConnectionInternal(DbConnection outerConnection, DbConnectionFactory connectionFactory, TaskCompletionSource`1 retry, DbConnectionOptions userOptions)
   at System.Data.ProviderBase.DbConnectionClosed.TryOpenConnection(DbConnection outerConnection, DbConnectionFactory connectionFactory, TaskCompletionSource`1 retry, DbConnectionOptions userOptions)
   at System.Data.SqlClient.SqlConnection.TryOpenInner(TaskCompletionSource`1 retry)
   at System.Data.SqlClient.SqlConnection.TryOpen(TaskCompletionSource`1 retry)
   at System.Data.SqlClient.SqlConnection.Open()
   at Umbraco.Core.Persistence.DbConnectionExtensions.IsAvailable(IDbConnection connection)
ClientConnectionId:3a26a323-3f2f-401e-b5b1-4a573d76d1a9
Error Number:18456,State:1,Class:14
 2018-09-20 21:45:01,431 [P2168/D4/T13] INFO  Umbraco.Core.DatabaseContext - CanConnect = False
 2018-09-20 21:45:02,432 [P2168/D4/T13] WARN  Umbraco.Core.Persistence.DbConnectionExtensions - Configured database is reporting as not being available! DataSource: ., InitialCatalog: umbraco. Exception: System.Data.SqlClient.SqlException (0x80131904): Login failed for user 'umbraco_db_user'.
   at System.Data.ProviderBase.DbConnectionPool.TryGetConnection(DbConnection owningObject, UInt32 waitForMultipleObjectsTimeout, Boolean allowCreate, Boolean onlyOneCheckConnection, DbConnectionOptions userOptions, DbConnectionInternal& connection)
   at System.Data.ProviderBase.DbConnectionPool.TryGetConnection(DbConnection owningObject, TaskCompletionSource`1 retry, DbConnectionOptions userOptions, DbConnectionInternal& connection)
   at System.Data.ProviderBase.DbConnectionFactory.TryGetConnection(DbConnection owningConnection, TaskCompletionSource`1 retry, DbConnectionOptions userOptions, DbConnectionInternal oldConnection, DbConnectionInternal& connection)
   at System.Data.ProviderBase.DbConnectionInternal.TryOpenConnectionInternal(DbConnection outerConnection, DbConnectionFactory connectionFactory, TaskCompletionSource`1 retry, DbConnectionOptions userOptions)
   at System.Data.ProviderBase.DbConnectionClosed.TryOpenConnection(DbConnection outerConnection, DbConnectionFactory connectionFactory, TaskCompletionSource`1 retry, DbConnectionOptions userOptions)
   at System.Data.SqlClient.SqlConnection.TryOpenInner(TaskCompletionSource`1 retry)
   at System.Data.SqlClient.SqlConnection.TryOpen(TaskCompletionSource`1 retry)
   at System.Data.SqlClient.SqlConnection.Open()
   at Umbraco.Core.Persistence.DbConnectionExtensions.IsAvailable(IDbConnection connection)
ClientConnectionId:3a26a323-3f2f-401e-b5b1-4a573d76d1a9
Error Number:18456,State:1,Class:14
 2018-09-20 21:45:02,433 [P2168/D4/T13] INFO  Umbraco.Core.DatabaseContext - CanConnect = False
 2018-09-20 21:45:03,434 [P2168/D4/T13] WARN  Umbraco.Core.Persistence.DbConnectionExtensions - Configured database is reporting as not being available! DataSource: ., InitialCatalog: umbraco. Exception: System.Data.SqlClient.SqlException (0x80131904): Login failed for user 'umbraco_db_user'.
   at System.Data.ProviderBase.DbConnectionPool.TryGetConnection(DbConnection owningObject, UInt32 waitForMultipleObjectsTimeout, Boolean allowCreate, Boolean onlyOneCheckConnection, DbConnectionOptions userOptions, DbConnectionInternal& connection)
   at System.Data.ProviderBase.DbConnectionPool.TryGetConnection(DbConnection owningObject, TaskCompletionSource`1 retry, DbConnectionOptions userOptions, DbConnectionInternal& connection)
   at System.Data.ProviderBase.DbConnectionFactory.TryGetConnection(DbConnection owningConnection, TaskCompletionSource`1 retry, DbConnectionOptions userOptions, DbConnectionInternal oldConnection, DbConnectionInternal& connection)
   at System.Data.ProviderBase.DbConnectionInternal.TryOpenConnectionInternal(DbConnection outerConnection, DbConnectionFactory connectionFactory, TaskCompletionSource`1 retry, DbConnectionOptions userOptions)
   at System.Data.ProviderBase.DbConnectionClosed.TryOpenConnection(DbConnection outerConnection, DbConnectionFactory connectionFactory, TaskCompletionSource`1 retry, DbConnectionOptions userOptions)
   at System.Data.SqlClient.SqlConnection.TryOpenInner(TaskCompletionSource`1 retry)
   at System.Data.SqlClient.SqlConnection.TryOpen(TaskCompletionSource`1 retry)
   at System.Data.SqlClient.SqlConnection.Open()
   at Umbraco.Core.Persistence.DbConnectionExtensions.IsAvailable(IDbConnection connection)
ClientConnectionId:3a26a323-3f2f-401e-b5b1-4a573d76d1a9
Error Number:18456,State:1,Class:14
 2018-09-20 21:45:03,435 [P2168/D4/T13] INFO  Umbraco.Core.DatabaseContext - CanConnect = False
 2018-09-20 21:45:04,437 [P2168/D4/T13] WARN  Umbraco.Core.Persistence.DbConnectionExtensions - Configured database is reporting as not being available! DataSource: ., InitialCatalog: umbraco. Exception: System.Data.SqlClient.SqlException (0x80131904): Login failed for user 'umbraco_db_user'.
   at System.Data.ProviderBase.DbConnectionPool.TryGetConnection(DbConnection owningObject, UInt32 waitForMultipleObjectsTimeout, Boolean allowCreate, Boolean onlyOneCheckConnection, DbConnectionOptions userOptions, DbConnectionInternal& connection)
   at System.Data.ProviderBase.DbConnectionPool.TryGetConnection(DbConnection owningObject, TaskCompletionSource`1 retry, DbConnectionOptions userOptions, DbConnectionInternal& connection)
   at System.Data.ProviderBase.DbConnectionFactory.TryGetConnection(DbConnection owningConnection, TaskCompletionSource`1 retry, DbConnectionOptions userOptions, DbConnectionInternal oldConnection, DbConnectionInternal& connection)
   at System.Data.ProviderBase.DbConnectionInternal.TryOpenConnectionInternal(DbConnection outerConnection, DbConnectionFactory connectionFactory, TaskCompletionSource`1 retry, DbConnectionOptions userOptions)
   at System.Data.ProviderBase.DbConnectionClosed.TryOpenConnection(DbConnection outerConnection, DbConnectionFactory connectionFactory, TaskCompletionSource`1 retry, DbConnectionOptions userOptions)
   at System.Data.SqlClient.SqlConnection.TryOpenInner(TaskCompletionSource`1 retry)
   at System.Data.SqlClient.SqlConnection.TryOpen(TaskCompletionSource`1 retry)
   at System.Data.SqlClient.SqlConnection.Open()
   at Umbraco.Core.Persistence.DbConnectionExtensions.IsAvailable(IDbConnection connection)
ClientConnectionId:3a26a323-3f2f-401e-b5b1-4a573d76d1a9
Error Number:18456,State:1,Class:14
 2018-09-20 21:45:04,437 [P2168/D4/T13] INFO  Umbraco.Core.DatabaseContext - CanConnect = False
 2018-09-20 21:45:05,444 [P2168/D4/T13] WARN  Umbraco.Core.Persistence.DbConnectionExtensions - Configured database is reporting as not being available! DataSource: ., InitialCatalog: umbraco. Exception: System.Data.SqlClient.SqlException (0x80131904): Login failed for user 'umbraco_db_user'.
   at System.Data.SqlClient.SqlInternalConnectionTds..ctor(DbConnectionPoolIdentity identity, SqlConnectionString connectionOptions, SqlCredential credential, Object providerInfo, String newPassword, SecureString newSecurePassword, Boolean redirectedUserInstance, SqlConnectionString userConnectionOptions, SessionData reconnectSessionData, DbConnectionPool pool, String accessToken, Boolean applyTransientFaultHandling, SqlAuthenticationProviderManager sqlAuthProviderManager)
   at System.Data.SqlClient.SqlConnectionFactory.CreateConnection(DbConnectionOptions options, DbConnectionPoolKey poolKey, Object poolGroupProviderInfo, DbConnectionPool pool, DbConnection owningConnection, DbConnectionOptions userOptions)
   at System.Data.ProviderBase.DbConnectionFactory.CreatePooledConnection(DbConnectionPool pool, DbConnection owningObject, DbConnectionOptions options, DbConnectionPoolKey poolKey, DbConnectionOptions userOptions)
   at System.Data.ProviderBase.DbConnectionPool.CreateObject(DbConnection owningObject, DbConnectionOptions userOptions, DbConnectionInternal oldConnection)
   at System.Data.ProviderBase.DbConnectionPool.UserCreateRequest(DbConnection owningObject, DbConnectionOptions userOptions, DbConnectionInternal oldConnection)
   at System.Data.ProviderBase.DbConnectionPool.TryGetConnection(DbConnection owningObject, UInt32 waitForMultipleObjectsTimeout, Boolean allowCreate, Boolean onlyOneCheckConnection, DbConnectionOptions userOptions, DbConnectionInternal& connection)
   at System.Data.ProviderBase.DbConnectionPool.TryGetConnection(DbConnection owningObject, TaskCompletionSource`1 retry, DbConnectionOptions userOptions, DbConnectionInternal& connection)
   at System.Data.ProviderBase.DbConnectionFactory.TryGetConnection(DbConnection owningConnection, TaskCompletionSource`1 retry, DbConnectionOptions userOptions, DbConnectionInternal oldConnection, DbConnectionInternal& connection)
   at System.Data.ProviderBase.DbConnectionInternal.TryOpenConnectionInternal(DbConnection outerConnection, DbConnectionFactory connectionFactory, TaskCompletionSource`1 retry, DbConnectionOptions userOptions)
   at System.Data.ProviderBase.DbConnectionClosed.TryOpenConnection(DbConnection outerConnection, DbConnectionFactory connectionFactory, TaskCompletionSource`1 retry, DbConnectionOptions userOptions)
   at System.Data.SqlClient.SqlConnection.TryOpenInner(TaskCompletionSource`1 retry)
   at System.Data.SqlClient.SqlConnection.TryOpen(TaskCompletionSource`1 retry)
   at System.Data.SqlClient.SqlConnection.Open()
   at Umbraco.Core.Persistence.DbConnectionExtensions.IsAvailable(IDbConnection connection)
ClientConnectionId:824510de-c85e-4ea1-84f9-037a795d1c78
Error Number:18456,State:1,Class:14
 2018-09-20 21:45:05,445 [P2168/D4/T13] INFO  Umbraco.Core.DatabaseContext - CanConnect = False
 2018-09-20 21:45:05,449 [P2168/D4/T13] ERROR Umbraco.Core.UmbracoApplicationBase - An unhandled exception occurred
Umbraco.Core.Exceptions.UmbracoStartupFailedException: Umbraco cannot start. A connection string is configured but Umbraco cannot connect to the database.
   at Umbraco.Core.CoreBootManager.EnsureDatabaseConnection()
   at Umbraco.Core.CoreBootManager.Complete(Action`1 afterComplete)
   at Umbraco.Web.WebBootManager.Complete(Action`1 afterComplete)
   at Umbraco.Core.UmbracoApplicationBase.StartApplication(Object sender, EventArgs e)
   at Umbraco.Core.UmbracoApplicationBase.Application_Start(Object sender, EventArgs e)
 2018-09-20 21:45:10,098 [P2168/D3/T12] INFO  Umbraco.Core.UmbracoApplicationBase - Application shutdown. Details: InitializationError

_shutDownMessage=Initialization Error
HostingEnvironment initiated shutdown
HostingEnvironment caused shutdown

_shutDownStack=   at System.Environment.GetStackTrace(Exception e, Boolean needFileInfo)
   at System.Environment.get_StackTrace()
   at System.Web.Hosting.HostingEnvironment.InitiateShutdownInternal()
   at System.Web.Hosting.HostingEnvironment.InitiateShutdownWithoutDemand()
   at System.Web.HttpRuntime.ShutdownAppDomain(String stackTrace)
   at System.Web.HttpRuntime.AppDomainShutdownTimerCallback(Object state)
   at System.Threading.TimerQueueTimer.CallCallbackInContext(Object state)
   at System.Threading.ExecutionContext.RunInternal(ExecutionContext executionContext, ContextCallback callback, Object state, Boolean preserveSyncCtx)
   at System.Threading.ExecutionContext.Run(ExecutionContext executionContext, ContextCallback callback, Object state, Boolean preserveSyncCtx)
   at System.Threading.TimerQueueTimer.CallCallback()
   at System.Threading.TimerQueueTimer.Fire()
   at System.Threading.TimerQueue.FireNextTimers()
   at System.Threading.TimerQueue.AppDomainTimerCallback()
 2018-09-20 21:45:15,754 [P2168/D4/T11] INFO  Umbraco.Core.MainDom - Stopping...
 2018-09-20 21:45:15,755 [P2168/D4/T11] INFO  Umbraco.Web.ExamineStartup - Examine shutting down
 2018-09-20 21:45:15,757 [P2168/D4/T11] INFO  Umbraco.Web.ExamineStartup - Complete (took 2ms)
 2018-09-20 21:45:15,758 [P2168/D4/T11] INFO  Umbraco.Core.MainDom - Released MainDom.
 2018-09-20 21:45:45,868 [P2168/D4/T12] INFO  Umbraco.Core.UmbracoApplicationBase - Application shutdown. Details: InitializationError

_shutDownMessage=Initialization Error
HostingEnvironment initiated shutdown
HostingEnvironment caused shutdown

_shutDownStack=   at System.Environment.GetStackTrace(Exception e, Boolean needFileInfo)
   at System.Environment.get_StackTrace()
   at System.Web.Hosting.HostingEnvironment.InitiateShutdownInternal()
   at System.Web.Hosting.HostingEnvironment.InitiateShutdownWithoutDemand()
   at System.Web.HttpRuntime.ShutdownAppDomain(String stackTrace)
   at System.Web.HttpRuntime.AppDomainShutdownTimerCallback(Object state)
   at System.Threading.TimerQueueTimer.CallCallbackInContext(Object state)
   at System.Threading.ExecutionContext.RunInternal(ExecutionContext executionContext, ContextCallback callback, Object state, Boolean preserveSyncCtx)
   at System.Threading.ExecutionContext.Run(ExecutionContext executionContext, ContextCallback callback, Object state, Boolean preserveSyncCtx)
   at System.Threading.TimerQueueTimer.CallCallback()
   at System.Threading.TimerQueueTimer.Fire()
   at System.Threading.TimerQueue.FireNextTimers()
   at System.Threading.TimerQueue.AppDomainTimerCallback()
 2018-09-20 21:47:12,043 [P2168/D5/T1] INFO  Umbraco.Core.CoreBootManager - Umbraco 7.11.1 application starting on SEMEREMEHAR57F0
 2018-09-20 21:47:12,062 [P2168/D5/T1] INFO  Umbraco.Core.PluginManager - Determining hash of code files on disk
 2018-09-20 21:47:13,570 [P2168/D5/T1] INFO  Umbraco.Core.PluginManager - Hash determined (took 1507ms)
 2018-09-20 21:47:13,590 [P2168/D5/T1] INFO  Umbraco.Core.MainDom - Acquiring MainDom...
 2018-09-20 21:47:13,591 [P2168/D5/T1] INFO  Umbraco.Core.MainDom - Acquired MainDom.
 2018-09-20 21:47:13,593 [P2168/D5/T1] INFO  Umbraco.Core.PluginManager - Resolving umbraco.interfaces.IDiscoverable
 2018-09-20 21:47:14,115 [P2168/D5/T1] INFO  Umbraco.Core.PluginManager - Resolved umbraco.interfaces.IDiscoverable (took 522ms)
 2018-09-20 21:47:14,115 [P2168/D5/T1] INFO  Umbraco.Core.PluginManager - Resolving umbraco.interfaces.IApplicationStartupHandler
 2018-09-20 21:47:14,118 [P2168/D5/T1] INFO  Umbraco.Core.PluginManager - Resolved umbraco.interfaces.IApplicationStartupHandler (took 2ms)
 2018-09-20 21:47:14,188 [P2168/D5/T1] INFO  Umbraco.Core.PluginManager - Resolving umbraco.interfaces.IDiscoverable
 2018-09-20 21:47:14,189 [P2168/D5/T1] INFO  Umbraco.Core.PluginManager - Resolved umbraco.interfaces.IDiscoverable (took 0ms)
 2018-09-20 21:47:14,189 [P2168/D5/T1] INFO  Umbraco.Core.PluginManager - Resolving Umbraco.Core.PropertyEditors.IPropertyEditorValueConverter
 2018-09-20 21:47:14,190 [P2168/D5/T1] INFO  Umbraco.Core.PluginManager - Resolved Umbraco.Core.PropertyEditors.IPropertyEditorValueConverter (took 0ms)
 2018-09-20 21:47:14,191 [P2168/D5/T1] INFO  Umbraco.Core.PluginManager - Resolving umbraco.interfaces.IDiscoverable
 2018-09-20 21:47:14,191 [P2168/D5/T1] INFO  Umbraco.Core.PluginManager - Resolved umbraco.interfaces.IDiscoverable (took 0ms)
 2018-09-20 21:47:14,192 [P2168/D5/T1] INFO  Umbraco.Core.PluginManager - Resolving Umbraco.Core.PropertyEditors.IPropertyValueConverter
 2018-09-20 21:47:14,194 [P2168/D5/T1] INFO  Umbraco.Core.PluginManager - Resolved Umbraco.Core.PropertyEditors.IPropertyValueConverter (took 2ms)
 2018-09-20 21:47:14,209 [P2168/D5/T1] INFO  Umbraco.Core.PluginManager - Resolving umbraco.interfaces.IDiscoverable
 2018-09-20 21:47:14,209 [P2168/D5/T1] INFO  Umbraco.Core.PluginManager - Resolved umbraco.interfaces.IDiscoverable (took 0ms)
 2018-09-20 21:47:14,210 [P2168/D5/T1] INFO  Umbraco.Core.PluginManager - Resolving Umbraco.Web.Mvc.SurfaceController
 2018-09-20 21:47:14,211 [P2168/D5/T1] INFO  Umbraco.Core.PluginManager - Resolved Umbraco.Web.Mvc.SurfaceController (took 1ms)
 2018-09-20 21:47:14,212 [P2168/D5/T1] INFO  Umbraco.Core.PluginManager - Resolving umbraco.interfaces.IDiscoverable
 2018-09-20 21:47:14,212 [P2168/D5/T1] INFO  Umbraco.Core.PluginManager - Resolved umbraco.interfaces.IDiscoverable (took 0ms)
 2018-09-20 21:47:14,213 [P2168/D5/T1] INFO  Umbraco.Core.PluginManager - Resolving Umbraco.Web.WebApi.UmbracoApiController
 2018-09-20 21:47:14,214 [P2168/D5/T1] INFO  Umbraco.Core.PluginManager - Resolved Umbraco.Web.WebApi.UmbracoApiController (took 1ms)
 2018-09-20 21:47:16,099 [P2168/D5/T1] WARN  Umbraco.Core.Persistence.DbConnectionExtensions - Configured database is reporting as not being available! DataSource: ., InitialCatalog: umbraco. Exception: System.Data.SqlClient.SqlException (0x80131904): Login failed for user 'umbraco_db_user'.
   at System.Data.SqlClient.SqlInternalConnectionTds..ctor(DbConnectionPoolIdentity identity, SqlConnectionString connectionOptions, SqlCredential credential, Object providerInfo, String newPassword, SecureString newSecurePassword, Boolean redirectedUserInstance, SqlConnectionString userConnectionOptions, SessionData reconnectSessionData, DbConnectionPool pool, String accessToken, Boolean applyTransientFaultHandling, SqlAuthenticationProviderManager sqlAuthProviderManager)
   at System.Data.SqlClient.SqlConnectionFactory.CreateConnection(DbConnectionOptions options, DbConnectionPoolKey poolKey, Object poolGroupProviderInfo, DbConnectionPool pool, DbConnection owningConnection, DbConnectionOptions userOptions)
   at System.Data.ProviderBase.DbConnectionFactory.CreatePooledConnection(DbConnectionPool pool, DbConnection owningObject, DbConnectionOptions options, DbConnectionPoolKey poolKey, DbConnectionOptions userOptions)
   at System.Data.ProviderBase.DbConnectionPool.CreateObject(DbConnection owningObject, DbConnectionOptions userOptions, DbConnectionInternal oldConnection)
   at System.Data.ProviderBase.DbConnectionPool.UserCreateRequest(DbConnection owningObject, DbConnectionOptions userOptions, DbConnectionInternal oldConnection)
   at System.Data.ProviderBase.DbConnectionPool.TryGetConnection(DbConnection owningObject, UInt32 waitForMultipleObjectsTimeout, Boolean allowCreate, Boolean onlyOneCheckConnection, DbConnectionOptions userOptions, DbConnectionInternal& connection)
   at System.Data.ProviderBase.DbConnectionPool.TryGetConnection(DbConnection owningObject, TaskCompletionSource`1 retry, DbConnectionOptions userOptions, DbConnectionInternal& connection)
   at System.Data.ProviderBase.DbConnectionFactory.TryGetConnection(DbConnection owningConnection, TaskCompletionSource`1 retry, DbConnectionOptions userOptions, DbConnectionInternal oldConnection, DbConnectionInternal& connection)
   at System.Data.ProviderBase.DbConnectionInternal.TryOpenConnectionInternal(DbConnection outerConnection, DbConnectionFactory connectionFactory, TaskCompletionSource`1 retry, DbConnectionOptions userOptions)
   at System.Data.ProviderBase.DbConnectionClosed.TryOpenConnection(DbConnection outerConnection, DbConnectionFactory connectionFactory, TaskCompletionSource`1 retry, DbConnectionOptions userOptions)
   at System.Data.SqlClient.SqlConnection.TryOpenInner(TaskCompletionSource`1 retry)
   at System.Data.SqlClient.SqlConnection.TryOpen(TaskCompletionSource`1 retry)
   at System.Data.SqlClient.SqlConnection.Open()
   at Umbraco.Core.Persistence.DbConnectionExtensions.IsAvailable(IDbConnection connection)
ClientConnectionId:4c150502-8d93-4857-ba21-5485f36da350
Error Number:18456,State:1,Class:14
 2018-09-20 21:47:16,099 [P2168/D5/T1] INFO  Umbraco.Core.DatabaseContext - CanConnect = False
 2018-09-20 21:47:16,290 [P2168/D5/T1] WARN  Umbraco.Core.Persistence.DbConnectionExtensions - Configured database is reporting as not being available! DataSource: ., InitialCatalog: umbraco. Exception: System.Data.SqlClient.SqlException (0x80131904): Login failed for user 'umbraco_db_user'.
   at System.Data.ProviderBase.DbConnectionPool.TryGetConnection(DbConnection owningObject, UInt32 waitForMultipleObjectsTimeout, Boolean allowCreate, Boolean onlyOneCheckConnection, DbConnectionOptions userOptions, DbConnectionInternal& connection)
   at System.Data.ProviderBase.DbConnectionPool.TryGetConnection(DbConnection owningObject, TaskCompletionSource`1 retry, DbConnectionOptions userOptions, DbConnectionInternal& connection)
   at System.Data.ProviderBase.DbConnectionFactory.TryGetConnection(DbConnection owningConnection, TaskCompletionSource`1 retry, DbConnectionOptions userOptions, DbConnectionInternal oldConnection, DbConnectionInternal& connection)
   at System.Data.ProviderBase.DbConnectionInternal.TryOpenConnectionInternal(DbConnection outerConnection, DbConnectionFactory connectionFactory, TaskCompletionSource`1 retry, DbConnectionOptions userOptions)
   at System.Data.ProviderBase.DbConnectionClosed.TryOpenConnection(DbConnection outerConnection, DbConnectionFactory connectionFactory, TaskCompletionSource`1 retry, DbConnectionOptions userOptions)
   at System.Data.SqlClient.SqlConnection.TryOpenInner(TaskCompletionSource`1 retry)
   at System.Data.SqlClient.SqlConnection.TryOpen(TaskCompletionSource`1 retry)
   at System.Data.SqlClient.SqlConnection.Open()
   at Umbraco.Core.Persistence.DbConnectionExtensions.IsAvailable(IDbConnection connection)
ClientConnectionId:4c150502-8d93-4857-ba21-5485f36da350
Error Number:18456,State:1,Class:14
 2018-09-20 21:47:16,291 [P2168/D5/T1] INFO  Umbraco.Core.DatabaseContext - CanConnect = False
 2018-09-20 21:47:17,292 [P2168/D5/T1] WARN  Umbraco.Core.Persistence.DbConnectionExtensions - Configured database is reporting as not being available! DataSource: ., InitialCatalog: umbraco. Exception: System.Data.SqlClient.SqlException (0x80131904): Login failed for user 'umbraco_db_user'.
   at System.Data.ProviderBase.DbConnectionPool.TryGetConnection(DbConnection owningObject, UInt32 waitForMultipleObjectsTimeout, Boolean allowCreate, Boolean onlyOneCheckConnection, DbConnectionOptions userOptions, DbConnectionInternal& connection)
   at System.Data.ProviderBase.DbConnectionPool.TryGetConnection(DbConnection owningObject, TaskCompletionSource`1 retry, DbConnectionOptions userOptions, DbConnectionInternal& connection)
   at System.Data.ProviderBase.DbConnectionFactory.TryGetConnection(DbConnection owningConnection, TaskCompletionSource`1 retry, DbConnectionOptions userOptions, DbConnectionInternal oldConnection, DbConnectionInternal& connection)
   at System.Data.ProviderBase.DbConnectionInternal.TryOpenConnectionInternal(DbConnection outerConnection, DbConnectionFactory connectionFactory, TaskCompletionSource`1 retry, DbConnectionOptions userOptions)
   at System.Data.ProviderBase.DbConnectionClosed.TryOpenConnection(DbConnection outerConnection, DbConnectionFactory connectionFactory, TaskCompletionSource`1 retry, DbConnectionOptions userOptions)
   at System.Data.SqlClient.SqlConnection.TryOpenInner(TaskCompletionSource`1 retry)
   at System.Data.SqlClient.SqlConnection.TryOpen(TaskCompletionSource`1 retry)
   at System.Data.SqlClient.SqlConnection.Open()
   at Umbraco.Core.Persistence.DbConnectionExtensions.IsAvailable(IDbConnection connection)
ClientConnectionId:4c150502-8d93-4857-ba21-5485f36da350
Error Number:18456,State:1,Class:14
 2018-09-20 21:47:17,293 [P2168/D5/T1] INFO  Umbraco.Core.DatabaseContext - CanConnect = False
 2018-09-20 21:47:18,294 [P2168/D5/T1] WARN  Umbraco.Core.Persistence.DbConnectionExtensions - Configured database is reporting as not being available! DataSource: ., InitialCatalog: umbraco. Exception: System.Data.SqlClient.SqlException (0x80131904): Login failed for user 'umbraco_db_user'.
   at System.Data.ProviderBase.DbConnectionPool.TryGetConnection(DbConnection owningObject, UInt32 waitForMultipleObjectsTimeout, Boolean allowCreate, Boolean onlyOneCheckConnection, DbConnectionOptions userOptions, DbConnectionInternal& connection)
   at System.Data.ProviderBase.DbConnectionPool.TryGetConnection(DbConnection owningObject, TaskCompletionSource`1 retry, DbConnectionOptions userOptions, DbConnectionInternal& connection)
   at System.Data.ProviderBase.DbConnectionFactory.TryGetConnection(DbConnection owningConnection, TaskCompletionSource`1 retry, DbConnectionOptions userOptions, DbConnectionInternal oldConnection, DbConnectionInternal& connection)
   at System.Data.ProviderBase.DbConnectionInternal.TryOpenConnectionInternal(DbConnection outerConnection, DbConnectionFactory connectionFactory, TaskCompletionSource`1 retry, DbConnectionOptions userOptions)
   at System.Data.ProviderBase.DbConnectionClosed.TryOpenConnection(DbConnection outerConnection, DbConnectionFactory connectionFactory, TaskCompletionSource`1 retry, DbConnectionOptions userOptions)
   at System.Data.SqlClient.SqlConnection.TryOpenInner(TaskCompletionSource`1 retry)
   at System.Data.SqlClient.SqlConnection.TryOpen(TaskCompletionSource`1 retry)
   at System.Data.SqlClient.SqlConnection.Open()
   at Umbraco.Core.Persistence.DbConnectionExtensions.IsAvailable(IDbConnection connection)
ClientConnectionId:4c150502-8d93-4857-ba21-5485f36da350
Error Number:18456,State:1,Class:14
 2018-09-20 21:47:18,295 [P2168/D5/T1] INFO  Umbraco.Core.DatabaseContext - CanConnect = False
 2018-09-20 21:47:19,296 [P2168/D5/T1] WARN  Umbraco.Core.Persistence.DbConnectionExtensions - Configured database is reporting as not being available! DataSource: ., InitialCatalog: umbraco. Exception: System.Data.SqlClient.SqlException (0x80131904): Login failed for user 'umbraco_db_user'.
   at System.Data.ProviderBase.DbConnectionPool.TryGetConnection(DbConnection owningObject, UInt32 waitForMultipleObjectsTimeout, Boolean allowCreate, Boolean onlyOneCheckConnection, DbConnectionOptions userOptions, DbConnectionInternal& connection)
   at System.Data.ProviderBase.DbConnectionPool.TryGetConnection(DbConnection owningObject, TaskCompletionSource`1 retry, DbConnectionOptions userOptions, DbConnectionInternal& connection)
   at System.Data.ProviderBase.DbConnectionFactory.TryGetConnection(DbConnection owningConnection, TaskCompletionSource`1 retry, DbConnectionOptions userOptions, DbConnectionInternal oldConnection, DbConnectionInternal& connection)
   at System.Data.ProviderBase.DbConnectionInternal.TryOpenConnectionInternal(DbConnection outerConnection, DbConnectionFactory connectionFactory, TaskCompletionSource`1 retry, DbConnectionOptions userOptions)
   at System.Data.ProviderBase.DbConnectionClosed.TryOpenConnection(DbConnection outerConnection, DbConnectionFactory connectionFactory, TaskCompletionSource`1 retry, DbConnectionOptions userOptions)
   at System.Data.SqlClient.SqlConnection.TryOpenInner(TaskCompletionSource`1 retry)
   at System.Data.SqlClient.SqlConnection.TryOpen(TaskCompletionSource`1 retry)
   at System.Data.SqlClient.SqlConnection.Open()
   at Umbraco.Core.Persistence.DbConnectionExtensions.IsAvailable(IDbConnection connection)
ClientConnectionId:4c150502-8d93-4857-ba21-5485f36da350
Error Number:18456,State:1,Class:14
 2018-09-20 21:47:19,297 [P2168/D5/T1] INFO  Umbraco.Core.DatabaseContext - CanConnect = False
 2018-09-20 21:47:20,298 [P2168/D5/T1] WARN  Umbraco.Core.Persistence.DbConnectionExtensions - Configured database is reporting as not being available! DataSource: ., InitialCatalog: umbraco. Exception: System.Data.SqlClient.SqlException (0x80131904): Login failed for user 'umbraco_db_user'.
   at System.Data.ProviderBase.DbConnectionPool.TryGetConnection(DbConnection owningObject, UInt32 waitForMultipleObjectsTimeout, Boolean allowCreate, Boolean onlyOneCheckConnection, DbConnectionOptions userOptions, DbConnectionInternal& connection)
   at System.Data.ProviderBase.DbConnectionPool.TryGetConnection(DbConnection owningObject, TaskCompletionSource`1 retry, DbConnectionOptions userOptions, DbConnectionInternal& connection)
   at System.Data.ProviderBase.DbConnectionFactory.TryGetConnection(DbConnection owningConnection, TaskCompletionSource`1 retry, DbConnectionOptions userOptions, DbConnectionInternal oldConnection, DbConnectionInternal& connection)
   at System.Data.ProviderBase.DbConnectionInternal.TryOpenConnectionInternal(DbConnection outerConnection, DbConnectionFactory connectionFactory, TaskCompletionSource`1 retry, DbConnectionOptions userOptions)
   at System.Data.ProviderBase.DbConnectionClosed.TryOpenConnection(DbConnection outerConnection, DbConnectionFactory connectionFactory, TaskCompletionSource`1 retry, DbConnectionOptions userOptions)
   at System.Data.SqlClient.SqlConnection.TryOpenInner(TaskCompletionSource`1 retry)
   at System.Data.SqlClient.SqlConnection.TryOpen(TaskCompletionSource`1 retry)
   at System.Data.SqlClient.SqlConnection.Open()
   at Umbraco.Core.Persistence.DbConnectionExtensions.IsAvailable(IDbConnection connection)
ClientConnectionId:4c150502-8d93-4857-ba21-5485f36da350
Error Number:18456,State:1,Class:14
 2018-09-20 21:47:20,299 [P2168/D5/T1] INFO  Umbraco.Core.DatabaseContext - CanConnect = False
 2018-09-20 21:47:21,304 [P2168/D5/T1] WARN  Umbraco.Core.Persistence.DbConnectionExtensions - Configured database is reporting as not being available! DataSource: ., InitialCatalog: umbraco. Exception: System.Data.SqlClient.SqlException (0x80131904): Login failed for user 'umbraco_db_user'.
   at System.Data.SqlClient.SqlInternalConnectionTds..ctor(DbConnectionPoolIdentity identity, SqlConnectionString connectionOptions, SqlCredential credential, Object providerInfo, String newPassword, SecureString newSecurePassword, Boolean redirectedUserInstance, SqlConnectionString userConnectionOptions, SessionData reconnectSessionData, DbConnectionPool pool, String accessToken, Boolean applyTransientFaultHandling, SqlAuthenticationProviderManager sqlAuthProviderManager)
   at System.Data.SqlClient.SqlConnectionFactory.CreateConnection(DbConnectionOptions options, DbConnectionPoolKey poolKey, Object poolGroupProviderInfo, DbConnectionPool pool, DbConnection owningConnection, DbConnectionOptions userOptions)
   at System.Data.ProviderBase.DbConnectionFactory.CreatePooledConnection(DbConnectionPool pool, DbConnection owningObject, DbConnectionOptions options, DbConnectionPoolKey poolKey, DbConnectionOptions userOptions)
   at System.Data.ProviderBase.DbConnectionPool.CreateObject(DbConnection owningObject, DbConnectionOptions userOptions, DbConnectionInternal oldConnection)
   at System.Data.ProviderBase.DbConnectionPool.UserCreateRequest(DbConnection owningObject, DbConnectionOptions userOptions, DbConnectionInternal oldConnection)
   at System.Data.ProviderBase.DbConnectionPool.TryGetConnection(DbConnection owningObject, UInt32 waitForMultipleObjectsTimeout, Boolean allowCreate, Boolean onlyOneCheckConnection, DbConnectionOptions userOptions, DbConnectionInternal& connection)
   at System.Data.ProviderBase.DbConnectionPool.TryGetConnection(DbConnection owningObject, TaskCompletionSource`1 retry, DbConnectionOptions userOptions, DbConnectionInternal& connection)
   at System.Data.ProviderBase.DbConnectionFactory.TryGetConnection(DbConnection owningConnection, TaskCompletionSource`1 retry, DbConnectionOptions userOptions, DbConnectionInternal oldConnection, DbConnectionInternal& connection)
   at System.Data.ProviderBase.DbConnectionInternal.TryOpenConnectionInternal(DbConnection outerConnection, DbConnectionFactory connectionFactory, TaskCompletionSource`1 retry, DbConnectionOptions userOptions)
   at System.Data.ProviderBase.DbConnectionClosed.TryOpenConnection(DbConnection outerConnection, DbConnectionFactory connectionFactory, TaskCompletionSource`1 retry, DbConnectionOptions userOptions)
   at System.Data.SqlClient.SqlConnection.TryOpenInner(TaskCompletionSource`1 retry)
   at System.Data.SqlClient.SqlConnection.TryOpen(TaskCompletionSource`1 retry)
   at System.Data.SqlClient.SqlConnection.Open()
   at Umbraco.Core.Persistence.DbConnectionExtensions.IsAvailable(IDbConnection connection)
ClientConnectionId:04d00452-59df-4f85-be6d-e602a931dc4b
Error Number:18456,State:1,Class:14
 2018-09-20 21:47:21,305 [P2168/D5/T1] INFO  Umbraco.Core.DatabaseContext - CanConnect = False
 2018-09-20 21:47:21,307 [P2168/D5/T1] ERROR Umbraco.Core.UmbracoApplicationBase - An unhandled exception occurred
Umbraco.Core.Exceptions.UmbracoStartupFailedException: Umbraco cannot start. A connection string is configured but Umbraco cannot connect to the database.
   at Umbraco.Core.CoreBootManager.EnsureDatabaseConnection()
   at Umbraco.Core.CoreBootManager.Complete(Action`1 afterComplete)
   at Umbraco.Web.WebBootManager.Complete(Action`1 afterComplete)
   at Umbraco.Core.UmbracoApplicationBase.StartApplication(Object sender, EventArgs e)
   at Umbraco.Core.UmbracoApplicationBase.Application_Start(Object sender, EventArgs e)
 2018-09-20 21:47:31,324 [P2168/D5/T8] INFO  Umbraco.Core.MainDom - Stopping...
 2018-09-20 21:47:31,325 [P2168/D5/T8] INFO  Umbraco.Web.ExamineStartup - Examine shutting down
 2018-09-20 21:47:31,589 [P2168/D5/T8] INFO  Umbraco.Web.ExamineStartup - Complete (took 264ms)
 2018-09-20 21:47:31,590 [P2168/D5/T8] INFO  Umbraco.Core.MainDom - Released MainDom.
 2018-09-20 21:48:01,699 [P2168/D5/T12] INFO  Umbraco.Core.UmbracoApplicationBase - Application shutdown. Details: InitializationError

_shutDownMessage=Initialization Error
HostingEnvironment initiated shutdown
HostingEnvironment caused shutdown

_shutDownStack=   at System.Environment.GetStackTrace(Exception e, Boolean needFileInfo)
   at System.Environment.get_StackTrace()
   at System.Web.Hosting.HostingEnvironment.InitiateShutdownInternal()
   at System.Web.Hosting.HostingEnvironment.InitiateShutdownWithoutDemand()
   at System.Web.HttpRuntime.ShutdownAppDomain(String stackTrace)
   at System.Web.HttpRuntime.AppDomainShutdownTimerCallback(Object state)
   at System.Threading.TimerQueueTimer.CallCallbackInContext(Object state)
   at System.Threading.ExecutionContext.RunInternal(ExecutionContext executionContext, ContextCallback callback, Object state, Boolean preserveSyncCtx)
   at System.Threading.ExecutionContext.Run(ExecutionContext executionContext, ContextCallback callback, Object state, Boolean preserveSyncCtx)
   at System.Threading.TimerQueueTimer.CallCallback()
   at System.Threading.TimerQueueTimer.Fire()
   at System.Threading.TimerQueue.FireNextTimers()
   at System.Threading.TimerQueue.AppDomainTimerCallback()
 2018-09-20 21:58:56,738 [P2168/D6/T1] INFO  Umbraco.Core.CoreBootManager - Umbraco 7.11.1 application starting on SEMEREMEHAR57F0
 2018-09-20 21:58:56,820 [P2168/D6/T1] INFO  Umbraco.Core.PluginManager - Determining hash of code files on disk
 2018-09-20 21:58:58,489 [P2168/D6/T1] INFO  Umbraco.Core.PluginManager - Hash determined (took 1669ms)
 2018-09-20 21:58:58,511 [P2168/D6/T1] INFO  Umbraco.Core.MainDom - Acquiring MainDom...
 2018-09-20 21:58:58,511 [P2168/D6/T1] INFO  Umbraco.Core.MainDom - Acquired MainDom.
 2018-09-20 21:58:58,513 [P2168/D6/T1] INFO  Umbraco.Core.PluginManager - Resolving umbraco.interfaces.IDiscoverable
 2018-09-20 21:58:59,042 [P2168/D6/T1] INFO  Umbraco.Core.PluginManager - Resolved umbraco.interfaces.IDiscoverable (took 529ms)
 2018-09-20 21:58:59,043 [P2168/D6/T1] INFO  Umbraco.Core.PluginManager - Resolving umbraco.interfaces.IApplicationStartupHandler
 2018-09-20 21:58:59,045 [P2168/D6/T1] INFO  Umbraco.Core.PluginManager - Resolved umbraco.interfaces.IApplicationStartupHandler (took 2ms)
 2018-09-20 21:58:59,107 [P2168/D6/T1] INFO  Umbraco.Core.PluginManager - Resolving umbraco.interfaces.IDiscoverable
 2018-09-20 21:58:59,108 [P2168/D6/T1] INFO  Umbraco.Core.PluginManager - Resolved umbraco.interfaces.IDiscoverable (took 1ms)
 2018-09-20 21:58:59,108 [P2168/D6/T1] INFO  Umbraco.Core.PluginManager - Resolving Umbraco.Core.PropertyEditors.IPropertyEditorValueConverter
 2018-09-20 21:58:59,109 [P2168/D6/T1] INFO  Umbraco.Core.PluginManager - Resolved Umbraco.Core.PropertyEditors.IPropertyEditorValueConverter (took 0ms)
 2018-09-20 21:58:59,110 [P2168/D6/T1] INFO  Umbraco.Core.PluginManager - Resolving umbraco.interfaces.IDiscoverable
 2018-09-20 21:58:59,110 [P2168/D6/T1] INFO  Umbraco.Core.PluginManager - Resolved umbraco.interfaces.IDiscoverable (took 0ms)
 2018-09-20 21:58:59,110 [P2168/D6/T1] INFO  Umbraco.Core.PluginManager - Resolving Umbraco.Core.PropertyEditors.IPropertyValueConverter
 2018-09-20 21:58:59,113 [P2168/D6/T1] INFO  Umbraco.Core.PluginManager - Resolved Umbraco.Core.PropertyEditors.IPropertyValueConverter (took 2ms)
 2018-09-20 21:58:59,122 [P2168/D6/T1] INFO  Umbraco.Core.PluginManager - Resolving umbraco.interfaces.IDiscoverable
 2018-09-20 21:58:59,122 [P2168/D6/T1] INFO  Umbraco.Core.PluginManager - Resolved umbraco.interfaces.IDiscoverable (took 0ms)
 2018-09-20 21:58:59,123 [P2168/D6/T1] INFO  Umbraco.Core.PluginManager - Resolving Umbraco.Web.Mvc.SurfaceController
 2018-09-20 21:58:59,124 [P2168/D6/T1] INFO  Umbraco.Core.PluginManager - Resolved Umbraco.Web.Mvc.SurfaceController (took 1ms)
 2018-09-20 21:58:59,125 [P2168/D6/T1] INFO  Umbraco.Core.PluginManager - Resolving umbraco.interfaces.IDiscoverable
 2018-09-20 21:58:59,125 [P2168/D6/T1] INFO  Umbraco.Core.PluginManager - Resolved umbraco.interfaces.IDiscoverable (took 0ms)
 2018-09-20 21:58:59,125 [P2168/D6/T1] INFO  Umbraco.Core.PluginManager - Resolving Umbraco.Web.WebApi.UmbracoApiController
 2018-09-20 21:58:59,127 [P2168/D6/T1] INFO  Umbraco.Core.PluginManager - Resolved Umbraco.Web.WebApi.UmbracoApiController (took 1ms)
 2018-09-20 21:59:00,945 [P2168/D6/T1] WARN  Umbraco.Core.Persistence.DbConnectionExtensions - Configured database is reporting as not being available! DataSource: ., InitialCatalog: umbraco. Exception: System.Data.SqlClient.SqlException (0x80131904): Login failed for user 'umbraco_db_user'.
   at System.Data.SqlClient.SqlInternalConnectionTds..ctor(DbConnectionPoolIdentity identity, SqlConnectionString connectionOptions, SqlCredential credential, Object providerInfo, String newPassword, SecureString newSecurePassword, Boolean redirectedUserInstance, SqlConnectionString userConnectionOptions, SessionData reconnectSessionData, DbConnectionPool pool, String accessToken, Boolean applyTransientFaultHandling, SqlAuthenticationProviderManager sqlAuthProviderManager)
   at System.Data.SqlClient.SqlConnectionFactory.CreateConnection(DbConnectionOptions options, DbConnectionPoolKey poolKey, Object poolGroupProviderInfo, DbConnectionPool pool, DbConnection owningConnection, DbConnectionOptions userOptions)
   at System.Data.ProviderBase.DbConnectionFactory.CreatePooledConnection(DbConnectionPool pool, DbConnection owningObject, DbConnectionOptions options, DbConnectionPoolKey poolKey, DbConnectionOptions userOptions)
   at System.Data.ProviderBase.DbConnectionPool.CreateObject(DbConnection owningObject, DbConnectionOptions userOptions, DbConnectionInternal oldConnection)
   at System.Data.ProviderBase.DbConnectionPool.UserCreateRequest(DbConnection owningObject, DbConnectionOptions userOptions, DbConnectionInternal oldConnection)
   at System.Data.ProviderBase.DbConnectionPool.TryGetConnection(DbConnection owningObject, UInt32 waitForMultipleObjectsTimeout, Boolean allowCreate, Boolean onlyOneCheckConnection, DbConnectionOptions userOptions, DbConnectionInternal& connection)
   at System.Data.ProviderBase.DbConnectionPool.TryGetConnection(DbConnection owningObject, TaskCompletionSource`1 retry, DbConnectionOptions userOptions, DbConnectionInternal& connection)
   at System.Data.ProviderBase.DbConnectionFactory.TryGetConnection(DbConnection owningConnection, TaskCompletionSource`1 retry, DbConnectionOptions userOptions, DbConnectionInternal oldConnection, DbConnectionInternal& connection)
   at System.Data.ProviderBase.DbConnectionInternal.TryOpenConnectionInternal(DbConnection outerConnection, DbConnectionFactory connectionFactory, TaskCompletionSource`1 retry, DbConnectionOptions userOptions)
   at System.Data.ProviderBase.DbConnectionClosed.TryOpenConnection(DbConnection outerConnection, DbConnectionFactory connectionFactory, TaskCompletionSource`1 retry, DbConnectionOptions userOptions)
   at System.Data.SqlClient.SqlConnection.TryOpenInner(TaskCompletionSource`1 retry)
   at System.Data.SqlClient.SqlConnection.TryOpen(TaskCompletionSource`1 retry)
   at System.Data.SqlClient.SqlConnection.Open()
   at Umbraco.Core.Persistence.DbConnectionExtensions.IsAvailable(IDbConnection connection)
ClientConnectionId:06b454d3-f7dc-4866-810d-0a1b80dbd6af
Error Number:18456,State:1,Class:14
 2018-09-20 21:59:00,945 [P2168/D6/T1] INFO  Umbraco.Core.DatabaseContext - CanConnect = False
 2018-09-20 21:59:01,132 [P2168/D6/T1] WARN  Umbraco.Core.Persistence.DbConnectionExtensions - Configured database is reporting as not being available! DataSource: ., InitialCatalog: umbraco. Exception: System.Data.SqlClient.SqlException (0x80131904): Login failed for user 'umbraco_db_user'.
   at System.Data.ProviderBase.DbConnectionPool.TryGetConnection(DbConnection owningObject, UInt32 waitForMultipleObjectsTimeout, Boolean allowCreate, Boolean onlyOneCheckConnection, DbConnectionOptions userOptions, DbConnectionInternal& connection)
   at System.Data.ProviderBase.DbConnectionPool.TryGetConnection(DbConnection owningObject, TaskCompletionSource`1 retry, DbConnectionOptions userOptions, DbConnectionInternal& connection)
   at System.Data.ProviderBase.DbConnectionFactory.TryGetConnection(DbConnection owningConnection, TaskCompletionSource`1 retry, DbConnectionOptions userOptions, DbConnectionInternal oldConnection, DbConnectionInternal& connection)
   at System.Data.ProviderBase.DbConnectionInternal.TryOpenConnectionInternal(DbConnection outerConnection, DbConnectionFactory connectionFactory, TaskCompletionSource`1 retry, DbConnectionOptions userOptions)
   at System.Data.ProviderBase.DbConnectionClosed.TryOpenConnection(DbConnection outerConnection, DbConnectionFactory connectionFactory, TaskCompletionSource`1 retry, DbConnectionOptions userOptions)
   at System.Data.SqlClient.SqlConnection.TryOpenInner(TaskCompletionSource`1 retry)
   at System.Data.SqlClient.SqlConnection.TryOpen(TaskCompletionSource`1 retry)
   at System.Data.SqlClient.SqlConnection.Open()
   at Umbraco.Core.Persistence.DbConnectionExtensions.IsAvailable(IDbConnection connection)
ClientConnectionId:06b454d3-f7dc-4866-810d-0a1b80dbd6af
Error Number:18456,State:1,Class:14
 2018-09-20 21:59:01,133 [P2168/D6/T1] INFO  Umbraco.Core.DatabaseContext - CanConnect = False
 2018-09-20 21:59:02,134 [P2168/D6/T1] WARN  Umbraco.Core.Persistence.DbConnectionExtensions - Configured database is reporting as not being available! DataSource: ., InitialCatalog: umbraco. Exception: System.Data.SqlClient.SqlException (0x80131904): Login failed for user 'umbraco_db_user'.
   at System.Data.ProviderBase.DbConnectionPool.TryGetConnection(DbConnection owningObject, UInt32 waitForMultipleObjectsTimeout, Boolean allowCreate, Boolean onlyOneCheckConnection, DbConnectionOptions userOptions, DbConnectionInternal& connection)
   at System.Data.ProviderBase.DbConnectionPool.TryGetConnection(DbConnection owningObject, TaskCompletionSource`1 retry, DbConnectionOptions userOptions, DbConnectionInternal& connection)
   at System.Data.ProviderBase.DbConnectionFactory.TryGetConnection(DbConnection owningConnection, TaskCompletionSource`1 retry, DbConnectionOptions userOptions, DbConnectionInternal oldConnection, DbConnectionInternal& connection)
   at System.Data.ProviderBase.DbConnectionInternal.TryOpenConnectionInternal(DbConnection outerConnection, DbConnectionFactory connectionFactory, TaskCompletionSource`1 retry, DbConnectionOptions userOptions)
   at System.Data.ProviderBase.DbConnectionClosed.TryOpenConnection(DbConnection outerConnection, DbConnectionFactory connectionFactory, TaskCompletionSource`1 retry, DbConnectionOptions userOptions)
   at System.Data.SqlClient.SqlConnection.TryOpenInner(TaskCompletionSource`1 retry)
   at System.Data.SqlClient.SqlConnection.TryOpen(TaskCompletionSource`1 retry)
   at System.Data.SqlClient.SqlConnection.Open()
   at Umbraco.Core.Persistence.DbConnectionExtensions.IsAvailable(IDbConnection connection)
ClientConnectionId:06b454d3-f7dc-4866-810d-0a1b80dbd6af
Error Number:18456,State:1,Class:14
 2018-09-20 21:59:02,135 [P2168/D6/T1] INFO  Umbraco.Core.DatabaseContext - CanConnect = False
 2018-09-20 21:59:03,136 [P2168/D6/T1] WARN  Umbraco.Core.Persistence.DbConnectionExtensions - Configured database is reporting as not being available! DataSource: ., InitialCatalog: umbraco. Exception: System.Data.SqlClient.SqlException (0x80131904): Login failed for user 'umbraco_db_user'.
   at System.Data.ProviderBase.DbConnectionPool.TryGetConnection(DbConnection owningObject, UInt32 waitForMultipleObjectsTimeout, Boolean allowCreate, Boolean onlyOneCheckConnection, DbConnectionOptions userOptions, DbConnectionInternal& connection)
   at System.Data.ProviderBase.DbConnectionPool.TryGetConnection(DbConnection owningObject, TaskCompletionSource`1 retry, DbConnectionOptions userOptions, DbConnectionInternal& connection)
   at System.Data.ProviderBase.DbConnectionFactory.TryGetConnection(DbConnection owningConnection, TaskCompletionSource`1 retry, DbConnectionOptions userOptions, DbConnectionInternal oldConnection, DbConnectionInternal& connection)
   at System.Data.ProviderBase.DbConnectionInternal.TryOpenConnectionInternal(DbConnection outerConnection, DbConnectionFactory connectionFactory, TaskCompletionSource`1 retry, DbConnectionOptions userOptions)
   at System.Data.ProviderBase.DbConnectionClosed.TryOpenConnection(DbConnection outerConnection, DbConnectionFactory connectionFactory, TaskCompletionSource`1 retry, DbConnectionOptions userOptions)
   at System.Data.SqlClient.SqlConnection.TryOpenInner(TaskCompletionSource`1 retry)
   at System.Data.SqlClient.SqlConnection.TryOpen(TaskCompletionSource`1 retry)
   at System.Data.SqlClient.SqlConnection.Open()
   at Umbraco.Core.Persistence.DbConnectionExtensions.IsAvailable(IDbConnection connection)
ClientConnectionId:06b454d3-f7dc-4866-810d-0a1b80dbd6af
Error Number:18456,State:1,Class:14
 2018-09-20 21:59:03,137 [P2168/D6/T1] INFO  Umbraco.Core.DatabaseContext - CanConnect = False
 2018-09-20 21:59:04,138 [P2168/D6/T1] WARN  Umbraco.Core.Persistence.DbConnectionExtensions - Configured database is reporting as not being available! DataSource: ., InitialCatalog: umbraco. Exception: System.Data.SqlClient.SqlException (0x80131904): Login failed for user 'umbraco_db_user'.
   at System.Data.ProviderBase.DbConnectionPool.TryGetConnection(DbConnection owningObject, UInt32 waitForMultipleObjectsTimeout, Boolean allowCreate, Boolean onlyOneCheckConnection, DbConnectionOptions userOptions, DbConnectionInternal& connection)
   at System.Data.ProviderBase.DbConnectionPool.TryGetConnection(DbConnection owningObject, TaskCompletionSource`1 retry, DbConnectionOptions userOptions, DbConnectionInternal& connection)
   at System.Data.ProviderBase.DbConnectionFactory.TryGetConnection(DbConnection owningConnection, TaskCompletionSource`1 retry, DbConnectionOptions userOptions, DbConnectionInternal oldConnection, DbConnectionInternal& connection)
   at System.Data.ProviderBase.DbConnectionInternal.TryOpenConnectionInternal(DbConnection outerConnection, DbConnectionFactory connectionFactory, TaskCompletionSource`1 retry, DbConnectionOptions userOptions)
   at System.Data.ProviderBase.DbConnectionClosed.TryOpenConnection(DbConnection outerConnection, DbConnectionFactory connectionFactory, TaskCompletionSource`1 retry, DbConnectionOptions userOptions)
   at System.Data.SqlClient.SqlConnection.TryOpenInner(TaskCompletionSource`1 retry)
   at System.Data.SqlClient.SqlConnection.TryOpen(TaskCompletionSource`1 retry)
   at System.Data.SqlClient.SqlConnection.Open()
   at Umbraco.Core.Persistence.DbConnectionExtensions.IsAvailable(IDbConnection connection)
ClientConnectionId:06b454d3-f7dc-4866-810d-0a1b80dbd6af
Error Number:18456,State:1,Class:14
 2018-09-20 21:59:04,139 [P2168/D6/T1] INFO  Umbraco.Core.DatabaseContext - CanConnect = False
 2018-09-20 21:59:05,140 [P2168/D6/T1] WARN  Umbraco.Core.Persistence.DbConnectionExtensions - Configured database is reporting as not being available! DataSource: ., InitialCatalog: umbraco. Exception: System.Data.SqlClient.SqlException (0x80131904): Login failed for user 'umbraco_db_user'.
   at System.Data.ProviderBase.DbConnectionPool.TryGetConnection(DbConnection owningObject, UInt32 waitForMultipleObjectsTimeout, Boolean allowCreate, Boolean onlyOneCheckConnection, DbConnectionOptions userOptions, DbConnectionInternal& connection)
   at System.Data.ProviderBase.DbConnectionPool.TryGetConnection(DbConnection owningObject, TaskCompletionSource`1 retry, DbConnectionOptions userOptions, DbConnectionInternal& connection)
   at System.Data.ProviderBase.DbConnectionFactory.TryGetConnection(DbConnection owningConnection, TaskCompletionSource`1 retry, DbConnectionOptions userOptions, DbConnectionInternal oldConnection, DbConnectionInternal& connection)
   at System.Data.ProviderBase.DbConnectionInternal.TryOpenConnectionInternal(DbConnection outerConnection, DbConnectionFactory connectionFactory, TaskCompletionSource`1 retry, DbConnectionOptions userOptions)
   at System.Data.ProviderBase.DbConnectionClosed.TryOpenConnection(DbConnection outerConnection, DbConnectionFactory connectionFactory, TaskCompletionSource`1 retry, DbConnectionOptions userOptions)
   at System.Data.SqlClient.SqlConnection.TryOpenInner(TaskCompletionSource`1 retry)
   at System.Data.SqlClient.SqlConnection.TryOpen(TaskCompletionSource`1 retry)
   at System.Data.SqlClient.SqlConnection.Open()
   at Umbraco.Core.Persistence.DbConnectionExtensions.IsAvailable(IDbConnection connection)
ClientConnectionId:06b454d3-f7dc-4866-810d-0a1b80dbd6af
Error Number:18456,State:1,Class:14
 2018-09-20 21:59:05,141 [P2168/D6/T1] INFO  Umbraco.Core.DatabaseContext - CanConnect = False
 2018-09-20 21:59:06,147 [P2168/D6/T1] WARN  Umbraco.Core.Persistence.DbConnectionExtensions - Configured database is reporting as not being available! DataSource: ., InitialCatalog: umbraco. Exception: System.Data.SqlClient.SqlException (0x80131904): Login failed for user 'umbraco_db_user'.
   at System.Data.SqlClient.SqlInternalConnectionTds..ctor(DbConnectionPoolIdentity identity, SqlConnectionString connectionOptions, SqlCredential credential, Object providerInfo, String newPassword, SecureString newSecurePassword, Boolean redirectedUserInstance, SqlConnectionString userConnectionOptions, SessionData reconnectSessionData, DbConnectionPool pool, String accessToken, Boolean applyTransientFaultHandling, SqlAuthenticationProviderManager sqlAuthProviderManager)
   at System.Data.SqlClient.SqlConnectionFactory.CreateConnection(DbConnectionOptions options, DbConnectionPoolKey poolKey, Object poolGroupProviderInfo, DbConnectionPool pool, DbConnection owningConnection, DbConnectionOptions userOptions)
   at System.Data.ProviderBase.DbConnectionFactory.CreatePooledConnection(DbConnectionPool pool, DbConnection owningObject, DbConnectionOptions options, DbConnectionPoolKey poolKey, DbConnectionOptions userOptions)
   at System.Data.ProviderBase.DbConnectionPool.CreateObject(DbConnection owningObject, DbConnectionOptions userOptions, DbConnectionInternal oldConnection)
   at System.Data.ProviderBase.DbConnectionPool.UserCreateRequest(DbConnection owningObject, DbConnectionOptions userOptions, DbConnectionInternal oldConnection)
   at System.Data.ProviderBase.DbConnectionPool.TryGetConnection(DbConnection owningObject, UInt32 waitForMultipleObjectsTimeout, Boolean allowCreate, Boolean onlyOneCheckConnection, DbConnectionOptions userOptions, DbConnectionInternal& connection)
   at System.Data.ProviderBase.DbConnectionPool.TryGetConnection(DbConnection owningObject, TaskCompletionSource`1 retry, DbConnectionOptions userOptions, DbConnectionInternal& connection)
   at System.Data.ProviderBase.DbConnectionFactory.TryGetConnection(DbConnection owningConnection, TaskCompletionSource`1 retry, DbConnectionOptions userOptions, DbConnectionInternal oldConnection, DbConnectionInternal& connection)
   at System.Data.ProviderBase.DbConnectionInternal.TryOpenConnectionInternal(DbConnection outerConnection, DbConnectionFactory connectionFactory, TaskCompletionSource`1 retry, DbConnectionOptions userOptions)
   at System.Data.ProviderBase.DbConnectionClosed.TryOpenConnection(DbConnection outerConnection, DbConnectionFactory connectionFactory, TaskCompletionSource`1 retry, DbConnectionOptions userOptions)
   at System.Data.SqlClient.SqlConnection.TryOpenInner(TaskCompletionSource`1 retry)
   at System.Data.SqlClient.SqlConnection.TryOpen(TaskCompletionSource`1 retry)
   at System.Data.SqlClient.SqlConnection.Open()
   at Umbraco.Core.Persistence.DbConnectionExtensions.IsAvailable(IDbConnection connection)
ClientConnectionId:8eaa00de-7058-4054-b517-a1de81a3b65c
Error Number:18456,State:1,Class:14
 2018-09-20 21:59:06,148 [P2168/D6/T1] INFO  Umbraco.Core.DatabaseContext - CanConnect = False
 2018-09-20 21:59:06,149 [P2168/D6/T1] ERROR Umbraco.Core.UmbracoApplicationBase - An unhandled exception occurred
Umbraco.Core.Exceptions.UmbracoStartupFailedException: Umbraco cannot start. A connection string is configured but Umbraco cannot connect to the database.
   at Umbraco.Core.CoreBootManager.EnsureDatabaseConnection()
   at Umbraco.Core.CoreBootManager.Complete(Action`1 afterComplete)
   at Umbraco.Web.WebBootManager.Complete(Action`1 afterComplete)
   at Umbraco.Core.UmbracoApplicationBase.StartApplication(Object sender, EventArgs e)
   at Umbraco.Core.UmbracoApplicationBase.Application_Start(Object sender, EventArgs e)
 2018-09-20 21:59:16,165 [P2168/D6/T15] INFO  Umbraco.Core.MainDom - Stopping...
 2018-09-20 21:59:16,166 [P2168/D6/T15] INFO  Umbraco.Web.ExamineStartup - Examine shutting down
 2018-09-20 21:59:16,432 [P2168/D6/T15] INFO  Umbraco.Web.ExamineStartup - Complete (took 266ms)
 2018-09-20 21:59:16,432 [P2168/D6/T15] INFO  Umbraco.Core.MainDom - Released MainDom.
 2018-09-20 21:59:46,559 [P2168/D6/T8] INFO  Umbraco.Core.UmbracoApplicationBase - Application shutdown. Details: InitializationError

_shutDownMessage=Initialization Error
HostingEnvironment initiated shutdown
HostingEnvironment caused shutdown

_shutDownStack=   at System.Environment.GetStackTrace(Exception e, Boolean needFileInfo)
   at System.Environment.get_StackTrace()
   at System.Web.Hosting.HostingEnvironment.InitiateShutdownInternal()
   at System.Web.Hosting.HostingEnvironment.InitiateShutdownWithoutDemand()
   at System.Web.HttpRuntime.ShutdownAppDomain(String stackTrace)
   at System.Web.HttpRuntime.AppDomainShutdownTimerCallback(Object state)
   at System.Threading.TimerQueueTimer.CallCallbackInContext(Object state)
   at System.Threading.ExecutionContext.RunInternal(ExecutionContext executionContext, ContextCallback callback, Object state, Boolean preserveSyncCtx)
   at System.Threading.ExecutionContext.Run(ExecutionContext executionContext, ContextCallback callback, Object state, Boolean preserveSyncCtx)
   at System.Threading.TimerQueueTimer.CallCallback()
   at System.Threading.TimerQueueTimer.Fire()
   at System.Threading.TimerQueue.FireNextTimers()
   at System.Threading.TimerQueue.AppDomainTimerCallback()
 2018-09-20 22:03:08,992 [P2168/D7/T9] INFO  Umbraco.Core.CoreBootManager - Umbraco 7.11.1 application starting on SEMEREMEHAR57F0
 2018-09-20 22:03:09,026 [P2168/D7/T9] INFO  Umbraco.Core.PluginManager - Determining hash of code files on disk
 2018-09-20 22:03:10,492 [P2168/D7/T9] INFO  Umbraco.Core.PluginManager - Hash determined (took 1466ms)
 2018-09-20 22:03:10,513 [P2168/D7/T9] INFO  Umbraco.Core.MainDom - Acquiring MainDom...
 2018-09-20 22:03:10,514 [P2168/D7/T9] INFO  Umbraco.Core.MainDom - Acquired MainDom.
 2018-09-20 22:03:10,517 [P2168/D7/T9] INFO  Umbraco.Core.PluginManager - Resolving umbraco.interfaces.IDiscoverable
 2018-09-20 22:03:11,041 [P2168/D7/T9] INFO  Umbraco.Core.PluginManager - Resolved umbraco.interfaces.IDiscoverable (took 523ms)
 2018-09-20 22:03:11,041 [P2168/D7/T9] INFO  Umbraco.Core.PluginManager - Resolving umbraco.interfaces.IApplicationStartupHandler
 2018-09-20 22:03:11,043 [P2168/D7/T9] INFO  Umbraco.Core.PluginManager - Resolved umbraco.interfaces.IApplicationStartupHandler (took 2ms)
 2018-09-20 22:03:11,104 [P2168/D7/T9] INFO  Umbraco.Core.PluginManager - Resolving umbraco.interfaces.IDiscoverable
 2018-09-20 22:03:11,105 [P2168/D7/T9] INFO  Umbraco.Core.PluginManager - Resolved umbraco.interfaces.IDiscoverable (took 1ms)
 2018-09-20 22:03:11,106 [P2168/D7/T9] INFO  Umbraco.Core.PluginManager - Resolving Umbraco.Core.PropertyEditors.IPropertyEditorValueConverter
 2018-09-20 22:03:11,106 [P2168/D7/T9] INFO  Umbraco.Core.PluginManager - Resolved Umbraco.Core.PropertyEditors.IPropertyEditorValueConverter (took 0ms)
 2018-09-20 22:03:11,107 [P2168/D7/T9] INFO  Umbraco.Core.PluginManager - Resolving umbraco.interfaces.IDiscoverable
 2018-09-20 22:03:11,108 [P2168/D7/T9] INFO  Umbraco.Core.PluginManager - Resolved umbraco.interfaces.IDiscoverable (took 0ms)
 2018-09-20 22:03:11,108 [P2168/D7/T9] INFO  Umbraco.Core.PluginManager - Resolving Umbraco.Core.PropertyEditors.IPropertyValueConverter
 2018-09-20 22:03:11,110 [P2168/D7/T9] INFO  Umbraco.Core.PluginManager - Resolved Umbraco.Core.PropertyEditors.IPropertyValueConverter (took 1ms)
 2018-09-20 22:03:11,119 [P2168/D7/T9] INFO  Umbraco.Core.PluginManager - Resolving umbraco.interfaces.IDiscoverable
 2018-09-20 22:03:11,119 [P2168/D7/T9] INFO  Umbraco.Core.PluginManager - Resolved umbraco.interfaces.IDiscoverable (took 0ms)
 2018-09-20 22:03:11,119 [P2168/D7/T9] INFO  Umbraco.Core.PluginManager - Resolving Umbraco.Web.Mvc.SurfaceController
 2018-09-20 22:03:11,120 [P2168/D7/T9] INFO  Umbraco.Core.PluginManager - Resolved Umbraco.Web.Mvc.SurfaceController (took 1ms)
 2018-09-20 22:03:11,121 [P2168/D7/T9] INFO  Umbraco.Core.PluginManager - Resolving umbraco.interfaces.IDiscoverable
 2018-09-20 22:03:11,121 [P2168/D7/T9] INFO  Umbraco.Core.PluginManager - Resolved umbraco.interfaces.IDiscoverable (took 0ms)
 2018-09-20 22:03:11,122 [P2168/D7/T9] INFO  Umbraco.Core.PluginManager - Resolving Umbraco.Web.WebApi.UmbracoApiController
 2018-09-20 22:03:11,124 [P2168/D7/T9] INFO  Umbraco.Core.PluginManager - Resolved Umbraco.Web.WebApi.UmbracoApiController (took 1ms)
 2018-09-20 22:03:13,013 [P2168/D7/T9] WARN  Umbraco.Core.Persistence.DbConnectionExtensions - Configured database is reporting as not being available! DataSource: ., InitialCatalog: umbraco. Exception: System.Data.SqlClient.SqlException (0x80131904): Login failed for user 'umbraco_db_user'.
   at System.Data.SqlClient.SqlInternalConnectionTds..ctor(DbConnectionPoolIdentity identity, SqlConnectionString connectionOptions, SqlCredential credential, Object providerInfo, String newPassword, SecureString newSecurePassword, Boolean redirectedUserInstance, SqlConnectionString userConnectionOptions, SessionData reconnectSessionData, DbConnectionPool pool, String accessToken, Boolean applyTransientFaultHandling, SqlAuthenticationProviderManager sqlAuthProviderManager)
   at System.Data.SqlClient.SqlConnectionFactory.CreateConnection(DbConnectionOptions options, DbConnectionPoolKey poolKey, Object poolGroupProviderInfo, DbConnectionPool pool, DbConnection owningConnection, DbConnectionOptions userOptions)
   at System.Data.ProviderBase.DbConnectionFactory.CreatePooledConnection(DbConnectionPool pool, DbConnection owningObject, DbConnectionOptions options, DbConnectionPoolKey poolKey, DbConnectionOptions userOptions)
   at System.Data.ProviderBase.DbConnectionPool.CreateObject(DbConnection owningObject, DbConnectionOptions userOptions, DbConnectionInternal oldConnection)
   at System.Data.ProviderBase.DbConnectionPool.UserCreateRequest(DbConnection owningObject, DbConnectionOptions userOptions, DbConnectionInternal oldConnection)
   at System.Data.ProviderBase.DbConnectionPool.TryGetConnection(DbConnection owningObject, UInt32 waitForMultipleObjectsTimeout, Boolean allowCreate, Boolean onlyOneCheckConnection, DbConnectionOptions userOptions, DbConnectionInternal& connection)
   at System.Data.ProviderBase.DbConnectionPool.TryGetConnection(DbConnection owningObject, TaskCompletionSource`1 retry, DbConnectionOptions userOptions, DbConnectionInternal& connection)
   at System.Data.ProviderBase.DbConnectionFactory.TryGetConnection(DbConnection owningConnection, TaskCompletionSource`1 retry, DbConnectionOptions userOptions, DbConnectionInternal oldConnection, DbConnectionInternal& connection)
   at System.Data.ProviderBase.DbConnectionInternal.TryOpenConnectionInternal(DbConnection outerConnection, DbConnectionFactory connectionFactory, TaskCompletionSource`1 retry, DbConnectionOptions userOptions)
   at System.Data.ProviderBase.DbConnectionClosed.TryOpenConnection(DbConnection outerConnection, DbConnectionFactory connectionFactory, TaskCompletionSource`1 retry, DbConnectionOptions userOptions)
   at System.Data.SqlClient.SqlConnection.TryOpenInner(TaskCompletionSource`1 retry)
   at System.Data.SqlClient.SqlConnection.TryOpen(TaskCompletionSource`1 retry)
   at System.Data.SqlClient.SqlConnection.Open()
   at Umbraco.Core.Persistence.DbConnectionExtensions.IsAvailable(IDbConnection connection)
ClientConnectionId:71bfcda9-68bd-4a1d-9642-215b1036c493
Error Number:18456,State:1,Class:14
 2018-09-20 22:03:13,014 [P2168/D7/T9] INFO  Umbraco.Core.DatabaseContext - CanConnect = False
 2018-09-20 22:03:13,199 [P2168/D7/T9] WARN  Umbraco.Core.Persistence.DbConnectionExtensions - Configured database is reporting as not being available! DataSource: ., InitialCatalog: umbraco. Exception: System.Data.SqlClient.SqlException (0x80131904): Login failed for user 'umbraco_db_user'.
   at System.Data.ProviderBase.DbConnectionPool.TryGetConnection(DbConnection owningObject, UInt32 waitForMultipleObjectsTimeout, Boolean allowCreate, Boolean onlyOneCheckConnection, DbConnectionOptions userOptions, DbConnectionInternal& connection)
   at System.Data.ProviderBase.DbConnectionPool.TryGetConnection(DbConnection owningObject, TaskCompletionSource`1 retry, DbConnectionOptions userOptions, DbConnectionInternal& connection)
   at System.Data.ProviderBase.DbConnectionFactory.TryGetConnection(DbConnection owningConnection, TaskCompletionSource`1 retry, DbConnectionOptions userOptions, DbConnectionInternal oldConnection, DbConnectionInternal& connection)
   at System.Data.ProviderBase.DbConnectionInternal.TryOpenConnectionInternal(DbConnection outerConnection, DbConnectionFactory connectionFactory, TaskCompletionSource`1 retry, DbConnectionOptions userOptions)
   at System.Data.ProviderBase.DbConnectionClosed.TryOpenConnection(DbConnection outerConnection, DbConnectionFactory connectionFactory, TaskCompletionSource`1 retry, DbConnectionOptions userOptions)
   at System.Data.SqlClient.SqlConnection.TryOpenInner(TaskCompletionSource`1 retry)
   at System.Data.SqlClient.SqlConnection.TryOpen(TaskCompletionSource`1 retry)
   at System.Data.SqlClient.SqlConnection.Open()
   at Umbraco.Core.Persistence.DbConnectionExtensions.IsAvailable(IDbConnection connection)
ClientConnectionId:71bfcda9-68bd-4a1d-9642-215b1036c493
Error Number:18456,State:1,Class:14
 2018-09-20 22:03:13,200 [P2168/D7/T9] INFO  Umbraco.Core.DatabaseContext - CanConnect = False
 2018-09-20 22:03:14,201 [P2168/D7/T9] WARN  Umbraco.Core.Persistence.DbConnectionExtensions - Configured database is reporting as not being available! DataSource: ., InitialCatalog: umbraco. Exception: System.Data.SqlClient.SqlException (0x80131904): Login failed for user 'umbraco_db_user'.
   at System.Data.ProviderBase.DbConnectionPool.TryGetConnection(DbConnection owningObject, UInt32 waitForMultipleObjectsTimeout, Boolean allowCreate, Boolean onlyOneCheckConnection, DbConnectionOptions userOptions, DbConnectionInternal& connection)
   at System.Data.ProviderBase.DbConnectionPool.TryGetConnection(DbConnection owningObject, TaskCompletionSource`1 retry, DbConnectionOptions userOptions, DbConnectionInternal& connection)
   at System.Data.ProviderBase.DbConnectionFactory.TryGetConnection(DbConnection owningConnection, TaskCompletionSource`1 retry, DbConnectionOptions userOptions, DbConnectionInternal oldConnection, DbConnectionInternal& connection)
   at System.Data.ProviderBase.DbConnectionInternal.TryOpenConnectionInternal(DbConnection outerConnection, DbConnectionFactory connectionFactory, TaskCompletionSource`1 retry, DbConnectionOptions userOptions)
   at System.Data.ProviderBase.DbConnectionClosed.TryOpenConnection(DbConnection outerConnection, DbConnectionFactory connectionFactory, TaskCompletionSource`1 retry, DbConnectionOptions userOptions)
   at System.Data.SqlClient.SqlConnection.TryOpenInner(TaskCompletionSource`1 retry)
   at System.Data.SqlClient.SqlConnection.TryOpen(TaskCompletionSource`1 retry)
   at System.Data.SqlClient.SqlConnection.Open()
   at Umbraco.Core.Persistence.DbConnectionExtensions.IsAvailable(IDbConnection connection)
ClientConnectionId:71bfcda9-68bd-4a1d-9642-215b1036c493
Error Number:18456,State:1,Class:14
 2018-09-20 22:03:14,202 [P2168/D7/T9] INFO  Umbraco.Core.DatabaseContext - CanConnect = False
 2018-09-20 22:03:15,203 [P2168/D7/T9] WARN  Umbraco.Core.Persistence.DbConnectionExtensions - Configured database is reporting as not being available! DataSource: ., InitialCatalog: umbraco. Exception: System.Data.SqlClient.SqlException (0x80131904): Login failed for user 'umbraco_db_user'.
   at System.Data.ProviderBase.DbConnectionPool.TryGetConnection(DbConnection owningObject, UInt32 waitForMultipleObjectsTimeout, Boolean allowCreate, Boolean onlyOneCheckConnection, DbConnectionOptions userOptions, DbConnectionInternal& connection)
   at System.Data.ProviderBase.DbConnectionPool.TryGetConnection(DbConnection owningObject, TaskCompletionSource`1 retry, DbConnectionOptions userOptions, DbConnectionInternal& connection)
   at System.Data.ProviderBase.DbConnectionFactory.TryGetConnection(DbConnection owningConnection, TaskCompletionSource`1 retry, DbConnectionOptions userOptions, DbConnectionInternal oldConnection, DbConnectionInternal& connection)
   at System.Data.ProviderBase.DbConnectionInternal.TryOpenConnectionInternal(DbConnection outerConnection, DbConnectionFactory connectionFactory, TaskCompletionSource`1 retry, DbConnectionOptions userOptions)
   at System.Data.ProviderBase.DbConnectionClosed.TryOpenConnection(DbConnection outerConnection, DbConnectionFactory connectionFactory, TaskCompletionSource`1 retry, DbConnectionOptions userOptions)
   at System.Data.SqlClient.SqlConnection.TryOpenInner(TaskCompletionSource`1 retry)
   at System.Data.SqlClient.SqlConnection.TryOpen(TaskCompletionSource`1 retry)
   at System.Data.SqlClient.SqlConnection.Open()
   at Umbraco.Core.Persistence.DbConnectionExtensions.IsAvailable(IDbConnection connection)
ClientConnectionId:71bfcda9-68bd-4a1d-9642-215b1036c493
Error Number:18456,State:1,Class:14
 2018-09-20 22:03:15,204 [P2168/D7/T9] INFO  Umbraco.Core.DatabaseContext - CanConnect = False
 2018-09-20 22:03:16,205 [P2168/D7/T9] WARN  Umbraco.Core.Persistence.DbConnectionExtensions - Configured database is reporting as not being available! DataSource: ., InitialCatalog: umbraco. Exception: System.Data.SqlClient.SqlException (0x80131904): Login failed for user 'umbraco_db_user'.
   at System.Data.ProviderBase.DbConnectionPool.TryGetConnection(DbConnection owningObject, UInt32 waitForMultipleObjectsTimeout, Boolean allowCreate, Boolean onlyOneCheckConnection, DbConnectionOptions userOptions, DbConnectionInternal& connection)
   at System.Data.ProviderBase.DbConnectionPool.TryGetConnection(DbConnection owningObject, TaskCompletionSource`1 retry, DbConnectionOptions userOptions, DbConnectionInternal& connection)
   at System.Data.ProviderBase.DbConnectionFactory.TryGetConnection(DbConnection owningConnection, TaskCompletionSource`1 retry, DbConnectionOptions userOptions, DbConnectionInternal oldConnection, DbConnectionInternal& connection)
   at System.Data.ProviderBase.DbConnectionInternal.TryOpenConnectionInternal(DbConnection outerConnection, DbConnectionFactory connectionFactory, TaskCompletionSource`1 retry, DbConnectionOptions userOptions)
   at System.Data.ProviderBase.DbConnectionClosed.TryOpenConnection(DbConnection outerConnection, DbConnectionFactory connectionFactory, TaskCompletionSource`1 retry, DbConnectionOptions userOptions)
   at System.Data.SqlClient.SqlConnection.TryOpenInner(TaskCompletionSource`1 retry)
   at System.Data.SqlClient.SqlConnection.TryOpen(TaskCompletionSource`1 retry)
   at System.Data.SqlClient.SqlConnection.Open()
   at Umbraco.Core.Persistence.DbConnectionExtensions.IsAvailable(IDbConnection connection)
ClientConnectionId:71bfcda9-68bd-4a1d-9642-215b1036c493
Error Number:18456,State:1,Class:14
 2018-09-20 22:03:16,206 [P2168/D7/T9] INFO  Umbraco.Core.DatabaseContext - CanConnect = False
 2018-09-20 22:03:17,208 [P2168/D7/T9] WARN  Umbraco.Core.Persistence.DbConnectionExtensions - Configured database is reporting as not being available! DataSource: ., InitialCatalog: umbraco. Exception: System.Data.SqlClient.SqlException (0x80131904): Login failed for user 'umbraco_db_user'.
   at System.Data.ProviderBase.DbConnectionPool.TryGetConnection(DbConnection owningObject, UInt32 waitForMultipleObjectsTimeout, Boolean allowCreate, Boolean onlyOneCheckConnection, DbConnectionOptions userOptions, DbConnectionInternal& connection)
   at System.Data.ProviderBase.DbConnectionPool.TryGetConnection(DbConnection owningObject, TaskCompletionSource`1 retry, DbConnectionOptions userOptions, DbConnectionInternal& connection)
   at System.Data.ProviderBase.DbConnectionFactory.TryGetConnection(DbConnection owningConnection, TaskCompletionSource`1 retry, DbConnectionOptions userOptions, DbConnectionInternal oldConnection, DbConnectionInternal& connection)
   at System.Data.ProviderBase.DbConnectionInternal.TryOpenConnectionInternal(DbConnection outerConnection, DbConnectionFactory connectionFactory, TaskCompletionSource`1 retry, DbConnectionOptions userOptions)
   at System.Data.ProviderBase.DbConnectionClosed.TryOpenConnection(DbConnection outerConnection, DbConnectionFactory connectionFactory, TaskCompletionSource`1 retry, DbConnectionOptions userOptions)
   at System.Data.SqlClient.SqlConnection.TryOpenInner(TaskCompletionSource`1 retry)
   at System.Data.SqlClient.SqlConnection.TryOpen(TaskCompletionSource`1 retry)
   at System.Data.SqlClient.SqlConnection.Open()
   at Umbraco.Core.Persistence.DbConnectionExtensions.IsAvailable(IDbConnection connection)
ClientConnectionId:71bfcda9-68bd-4a1d-9642-215b1036c493
Error Number:18456,State:1,Class:14
 2018-09-20 22:03:17,208 [P2168/D7/T9] INFO  Umbraco.Core.DatabaseContext - CanConnect = False
 2018-09-20 22:03:18,215 [P2168/D7/T9] WARN  Umbraco.Core.Persistence.DbConnectionExtensions - Configured database is reporting as not being available! DataSource: ., InitialCatalog: umbraco. Exception: System.Data.SqlClient.SqlException (0x80131904): Login failed for user 'umbraco_db_user'.
   at System.Data.SqlClient.SqlInternalConnectionTds..ctor(DbConnectionPoolIdentity identity, SqlConnectionString connectionOptions, SqlCredential credential, Object providerInfo, String newPassword, SecureString newSecurePassword, Boolean redirectedUserInstance, SqlConnectionString userConnectionOptions, SessionData reconnectSessionData, DbConnectionPool pool, String accessToken, Boolean applyTransientFaultHandling, SqlAuthenticationProviderManager sqlAuthProviderManager)
   at System.Data.SqlClient.SqlConnectionFactory.CreateConnection(DbConnectionOptions options, DbConnectionPoolKey poolKey, Object poolGroupProviderInfo, DbConnectionPool pool, DbConnection owningConnection, DbConnectionOptions userOptions)
   at System.Data.ProviderBase.DbConnectionFactory.CreatePooledConnection(DbConnectionPool pool, DbConnection owningObject, DbConnectionOptions options, DbConnectionPoolKey poolKey, DbConnectionOptions userOptions)
   at System.Data.ProviderBase.DbConnectionPool.CreateObject(DbConnection owningObject, DbConnectionOptions userOptions, DbConnectionInternal oldConnection)
   at System.Data.ProviderBase.DbConnectionPool.UserCreateRequest(DbConnection owningObject, DbConnectionOptions userOptions, DbConnectionInternal oldConnection)
   at System.Data.ProviderBase.DbConnectionPool.TryGetConnection(DbConnection owningObject, UInt32 waitForMultipleObjectsTimeout, Boolean allowCreate, Boolean onlyOneCheckConnection, DbConnectionOptions userOptions, DbConnectionInternal& connection)
   at System.Data.ProviderBase.DbConnectionPool.TryGetConnection(DbConnection owningObject, TaskCompletionSource`1 retry, DbConnectionOptions userOptions, DbConnectionInternal& connection)
   at System.Data.ProviderBase.DbConnectionFactory.TryGetConnection(DbConnection owningConnection, TaskCompletionSource`1 retry, DbConnectionOptions userOptions, DbConnectionInternal oldConnection, DbConnectionInternal& connection)
   at System.Data.ProviderBase.DbConnectionInternal.TryOpenConnectionInternal(DbConnection outerConnection, DbConnectionFactory connectionFactory, TaskCompletionSource`1 retry, DbConnectionOptions userOptions)
   at System.Data.ProviderBase.DbConnectionClosed.TryOpenConnection(DbConnection outerConnection, DbConnectionFactory connectionFactory, TaskCompletionSource`1 retry, DbConnectionOptions userOptions)
   at System.Data.SqlClient.SqlConnection.TryOpenInner(TaskCompletionSource`1 retry)
   at System.Data.SqlClient.SqlConnection.TryOpen(TaskCompletionSource`1 retry)
   at System.Data.SqlClient.SqlConnection.Open()
   at Umbraco.Core.Persistence.DbConnectionExtensions.IsAvailable(IDbConnection connection)
ClientConnectionId:7918aeb3-fd06-44a2-8acb-463fa92c9132
Error Number:18456,State:1,Class:14
 2018-09-20 22:03:18,215 [P2168/D7/T9] INFO  Umbraco.Core.DatabaseContext - CanConnect = False
 2018-09-20 22:03:18,217 [P2168/D7/T9] ERROR Umbraco.Core.UmbracoApplicationBase - An unhandled exception occurred
Umbraco.Core.Exceptions.UmbracoStartupFailedException: Umbraco cannot start. A connection string is configured but Umbraco cannot connect to the database.
   at Umbraco.Core.CoreBootManager.EnsureDatabaseConnection()
   at Umbraco.Core.CoreBootManager.Complete(Action`1 afterComplete)
   at Umbraco.Web.WebBootManager.Complete(Action`1 afterComplete)
   at Umbraco.Core.UmbracoApplicationBase.StartApplication(Object sender, EventArgs e)
   at Umbraco.Core.UmbracoApplicationBase.Application_Start(Object sender, EventArgs e)
 2018-09-20 22:03:28,229 [P2168/D7/T7] INFO  Umbraco.Core.MainDom - Stopping...
 2018-09-20 22:03:28,230 [P2168/D7/T7] INFO  Umbraco.Web.ExamineStartup - Examine shutting down
 2018-09-20 22:03:28,443 [P2168/D7/T7] INFO  Umbraco.Web.ExamineStartup - Complete (took 213ms)
 2018-09-20 22:03:28,444 [P2168/D7/T7] INFO  Umbraco.Core.MainDom - Released MainDom.
 2018-09-20 22:03:58,579 [P2168/D7/T10] INFO  Umbraco.Core.UmbracoApplicationBase - Application shutdown. Details: InitializationError

_shutDownMessage=Initialization Error
HostingEnvironment initiated shutdown
HostingEnvironment caused shutdown

_shutDownStack=   at System.Environment.GetStackTrace(Exception e, Boolean needFileInfo)
   at System.Environment.get_StackTrace()
   at System.Web.Hosting.HostingEnvironment.InitiateShutdownInternal()
   at System.Web.Hosting.HostingEnvironment.InitiateShutdownWithoutDemand()
   at System.Web.HttpRuntime.ShutdownAppDomain(String stackTrace)
   at System.Web.HttpRuntime.AppDomainShutdownTimerCallback(Object state)
   at System.Threading.TimerQueueTimer.CallCallbackInContext(Object state)
   at System.Threading.ExecutionContext.RunInternal(ExecutionContext executionContext, ContextCallback callback, Object state, Boolean preserveSyncCtx)
   at System.Threading.ExecutionContext.Run(ExecutionContext executionContext, ContextCallback callback, Object state, Boolean preserveSyncCtx)
   at System.Threading.TimerQueueTimer.CallCallback()
   at System.Threading.TimerQueueTimer.Fire()
   at System.Threading.TimerQueue.FireNextTimers()
   at System.Threading.TimerQueue.AppDomainTimerCallback()
 2018-09-20 22:06:10,675 [P2168/D8/T16] INFO  Umbraco.Core.CoreBootManager - Umbraco 7.11.1 application starting on SEMEREMEHAR57F0
 2018-09-20 22:06:10,711 [P2168/D8/T16] INFO  Umbraco.Core.PluginManager - Determining hash of code files on disk
 2018-09-20 22:06:12,300 [P2168/D8/T16] INFO  Umbraco.Core.PluginManager - Hash determined (took 1589ms)
 2018-09-20 22:06:12,321 [P2168/D8/T16] INFO  Umbraco.Core.MainDom - Acquiring MainDom...
 2018-09-20 22:06:12,321 [P2168/D8/T16] INFO  Umbraco.Core.MainDom - Acquired MainDom.
 2018-09-20 22:06:12,323 [P2168/D8/T16] INFO  Umbraco.Core.PluginManager - Resolving umbraco.interfaces.IDiscoverable
 2018-09-20 22:06:12,857 [P2168/D8/T16] INFO  Umbraco.Core.PluginManager - Resolved umbraco.interfaces.IDiscoverable (took 533ms)
 2018-09-20 22:06:12,857 [P2168/D8/T16] INFO  Umbraco.Core.PluginManager - Resolving umbraco.interfaces.IApplicationStartupHandler
 2018-09-20 22:06:12,861 [P2168/D8/T16] INFO  Umbraco.Core.PluginManager - Resolved umbraco.interfaces.IApplicationStartupHandler (took 4ms)
 2018-09-20 22:06:12,921 [P2168/D8/T16] INFO  Umbraco.Core.PluginManager - Resolving umbraco.interfaces.IDiscoverable
 2018-09-20 22:06:12,922 [P2168/D8/T16] INFO  Umbraco.Core.PluginManager - Resolved umbraco.interfaces.IDiscoverable (took 1ms)
 2018-09-20 22:06:12,923 [P2168/D8/T16] INFO  Umbraco.Core.PluginManager - Resolving Umbraco.Core.PropertyEditors.IPropertyEditorValueConverter
 2018-09-20 22:06:12,923 [P2168/D8/T16] INFO  Umbraco.Core.PluginManager - Resolved Umbraco.Core.PropertyEditors.IPropertyEditorValueConverter (took 0ms)
 2018-09-20 22:06:12,924 [P2168/D8/T16] INFO  Umbraco.Core.PluginManager - Resolving umbraco.interfaces.IDiscoverable
 2018-09-20 22:06:12,925 [P2168/D8/T16] INFO  Umbraco.Core.PluginManager - Resolved umbraco.interfaces.IDiscoverable (took 0ms)
 2018-09-20 22:06:12,925 [P2168/D8/T16] INFO  Umbraco.Core.PluginManager - Resolving Umbraco.Core.PropertyEditors.IPropertyValueConverter
 2018-09-20 22:06:12,927 [P2168/D8/T16] INFO  Umbraco.Core.PluginManager - Resolved Umbraco.Core.PropertyEditors.IPropertyValueConverter (took 2ms)
 2018-09-20 22:06:12,938 [P2168/D8/T16] INFO  Umbraco.Core.PluginManager - Resolving umbraco.interfaces.IDiscoverable
 2018-09-20 22:06:12,938 [P2168/D8/T16] INFO  Umbraco.Core.PluginManager - Resolved umbraco.interfaces.IDiscoverable (took 0ms)
 2018-09-20 22:06:12,939 [P2168/D8/T16] INFO  Umbraco.Core.PluginManager - Resolving Umbraco.Web.Mvc.SurfaceController
 2018-09-20 22:06:12,940 [P2168/D8/T16] INFO  Umbraco.Core.PluginManager - Resolved Umbraco.Web.Mvc.SurfaceController (took 1ms)
 2018-09-20 22:06:12,940 [P2168/D8/T16] INFO  Umbraco.Core.PluginManager - Resolving umbraco.interfaces.IDiscoverable
 2018-09-20 22:06:12,941 [P2168/D8/T16] INFO  Umbraco.Core.PluginManager - Resolved umbraco.interfaces.IDiscoverable (took 0ms)
 2018-09-20 22:06:12,941 [P2168/D8/T16] INFO  Umbraco.Core.PluginManager - Resolving Umbraco.Web.WebApi.UmbracoApiController
 2018-09-20 22:06:12,944 [P2168/D8/T16] INFO  Umbraco.Core.PluginManager - Resolved Umbraco.Web.WebApi.UmbracoApiController (took 3ms)
 2018-09-20 22:06:14,687 [P2168/D8/T16] INFO  Umbraco.Core.DatabaseContext - CanConnect = True
 2018-09-20 22:06:15,179 [P2168/D8/T16] INFO  Umbraco.Web.Cache.CacheRefresherEventHandler - Initializing Umbraco internal event handlers for cache refreshing
 2018-09-20 22:06:15,259 [P2168/D8/T16] WARN  Umbraco.Core.Sync.DatabaseServerMessenger - No last synced Id found, this generally means this is a new server/install. The server will build its caches and indexes, and then adjust its last synced Id to the latest found in the database and maintain cache updates based on that Id.
 2018-09-20 22:06:15,385 [P2168/D8/T16] INFO  umbraco.content - Load Xml from file...
 2018-09-20 22:06:15,395 [P2168/D8/T16] INFO  umbraco.content - Loaded Xml from file.
 2018-09-20 22:06:15,409 [P2168/D8/T16] INFO  umbraco.content - Loading content from database...
 2018-09-20 22:06:16,399 [P2168/D8/T16] INFO  UmbracoExamine.DataServices.UmbracoLogService - Rebuilding index, Provider=InternalMemberIndexer, NodeId=-1
 2018-09-20 22:06:16,534 [P2168/D8/T16] INFO  UmbracoExamine.DataServices.UmbracoLogService - PerformIndexAll - Start data queries - member, Provider=InternalMemberIndexer, NodeId=-1
 2018-09-20 22:06:16,660 [P2168/D8/T16] INFO  UmbracoExamine.DataServices.UmbracoLogService - PerformIndexAll - End data queries - member, took 125ms, Provider=InternalMemberIndexer, NodeId=-1
 2018-09-20 22:06:16,662 [P2168/D8/T16] INFO  UmbracoExamine.DataServices.UmbracoLogService - Rebuilding index, Provider=InternalIndexer, NodeId=-1
 2018-09-20 22:06:17,077 [P2168/D8/T16] INFO  UmbracoExamine.DataServices.UmbracoLogService - PerformIndexAll - Start data queries - content, Provider=InternalIndexer, NodeId=-1
 2018-09-20 22:06:17,349 [P2168/D8/T16] INFO  Umbraco.Core.PluginManager - Resolving umbraco.interfaces.IDiscoverable
 2018-09-20 22:06:17,350 [P2168/D8/T16] INFO  Umbraco.Core.PluginManager - Resolved umbraco.interfaces.IDiscoverable (took 0ms)
 2018-09-20 22:06:17,350 [P2168/D8/T16] INFO  Umbraco.Core.PluginManager - Resolving Umbraco.Core.PropertyEditors.IParameterEditor
 2018-09-20 22:06:17,376 [P2168/D8/T16] INFO  Umbraco.Core.PluginManager - Resolved Umbraco.Core.PropertyEditors.IParameterEditor (took 25ms)
 2018-09-20 22:06:17,630 [P2168/D8/T16] INFO  UmbracoExamine.DataServices.UmbracoLogService - PerformIndexAll - End data queries - content, took 552ms, Provider=InternalIndexer, NodeId=-1
 2018-09-20 22:06:17,630 [P2168/D8/T16] INFO  UmbracoExamine.DataServices.UmbracoLogService - PerformIndexAll - Start data queries - media, Provider=InternalIndexer, NodeId=-1
 2018-09-20 22:06:17,799 [P2168/D8/T8] INFO  Umbraco.Core.PluginManager - Resolving umbraco.interfaces.IDiscoverable
 2018-09-20 22:06:17,800 [P2168/D8/T8] INFO  Umbraco.Core.PluginManager - Resolved umbraco.interfaces.IDiscoverable (took 0ms)
 2018-09-20 22:06:17,801 [P2168/D8/T8] INFO  Umbraco.Core.PluginManager - Resolving [Umbraco.Core.Persistence.Mappers.MapperForAttribute]Umbraco.Core.Persistence.Mappers.BaseMapper
 2018-09-20 22:06:17,818 [P2168/D8/T16] INFO  UmbracoExamine.DataServices.UmbracoLogService - PerformIndexAll - End data queries - media, took 186ms, Provider=InternalIndexer, NodeId=-1
 2018-09-20 22:06:17,818 [P2168/D8/T16] INFO  UmbracoExamine.DataServices.UmbracoLogService - Rebuilding index, Provider=ExternalIndexer, NodeId=-1
 2018-09-20 22:06:17,829 [P2168/D8/T8] INFO  Umbraco.Core.PluginManager - Resolved [Umbraco.Core.Persistence.Mappers.MapperForAttribute]Umbraco.Core.Persistence.Mappers.BaseMapper (took 28ms)
 2018-09-20 22:06:18,165 [P2168/D8/T16] INFO  UmbracoExamine.DataServices.UmbracoLogService - PerformIndexAll - Start data queries - content, Provider=ExternalIndexer, NodeId=-1
 2018-09-20 22:06:18,189 [P2168/D8/T16] INFO  UmbracoExamine.DataServices.UmbracoLogService - PerformIndexAll - End data queries - content, took 23ms, Provider=ExternalIndexer, NodeId=-1
 2018-09-20 22:06:18,190 [P2168/D8/T16] INFO  UmbracoExamine.DataServices.UmbracoLogService - PerformIndexAll - Start data queries - media, Provider=ExternalIndexer, NodeId=-1
 2018-09-20 22:06:18,207 [P2168/D8/T16] INFO  UmbracoExamine.DataServices.UmbracoLogService - PerformIndexAll - End data queries - media, took 13ms, Provider=ExternalIndexer, NodeId=-1
 2018-09-20 22:06:18,224 [P2168/D8/T16] INFO  Umbraco.Web.Search.ExamineEvents - Initializing Examine and binding to business logic events
 2018-09-20 22:06:18,226 [P2168/D8/T16] INFO  Umbraco.Web.Search.ExamineEvents - Adding examine event handlers for index providers: 3
 2018-09-20 22:06:18,273 [P2168/D8/T16] INFO  Umbraco.Core.CoreBootManager - Umbraco application startup complete (took 7766ms)
 2018-09-20 22:06:20,154 [P2168/D8/T7] INFO  umbraco.content - Save Xml to file...
 2018-09-20 22:06:20,181 [P2168/D8/T7] INFO  umbraco.content - Saved Xml to file.
 2018-09-20 22:06:21,567 [P2168/D8/T18] INFO  Umbraco.Core.Sync.ApplicationUrlHelper - New ApplicationUrl detected: http://localhost:60450/umbraco
 2018-09-20 22:06:21,569 [P2168/D8/T18] INFO  Umbraco.Core.Sync.ApplicationUrlHelper - ApplicationUrl: http://localhost:60450/umbraco (UmbracoModule request)
 2018-09-20 22:06:26,091 [P2168/D8/T18] WARN  Umbraco.Web.Mvc.RenderRouteHandler - The current Document Type home matches a locally declared controller of type UmbracoBlogSite.Controllers.HomeController. Custom Controllers for Umbraco routing must implement 'Umbraco.Web.Mvc.IRenderController' and inherit from 'System.Web.Mvc.ControllerBase'.
 2018-09-20 22:06:32,966 [P2168/D8/T18] INFO  Umbraco.Core.PluginManager - Resolving umbraco.interfaces.IDiscoverable
 2018-09-20 22:06:32,966 [P2168/D8/T18] INFO  Umbraco.Core.PluginManager - Resolved umbraco.interfaces.IDiscoverable (took 0ms)
 2018-09-20 22:06:32,966 [P2168/D8/T18] INFO  Umbraco.Core.PluginManager - Resolving Umbraco.Core.Deploy.IServiceConnector
 2018-09-20 22:06:32,986 [P2168/D8/T18] INFO  Umbraco.Core.PluginManager - Resolved Umbraco.Core.Deploy.IServiceConnector (took 19ms)
 2018-09-20 22:07:22,597 [P2168/D8/T21] INFO  umbraco.BusinessLogic.Log - Log scrubbed.  Removed all items older than 2018-09-19 22:07:22
 2018-09-20 22:12:46,157 [P2168/D8/T12] WARN  Umbraco.Web.Mvc.RenderRouteHandler - The current Document Type home matches a locally declared controller of type UmbracoBlogSite.Controllers.HomeController. Custom Controllers for Umbraco routing must implement 'Umbraco.Web.Mvc.IRenderController' and inherit from 'System.Web.Mvc.ControllerBase'.
 2018-09-20 22:48:01,497 [P2168/D8/T40] WARN  Umbraco.Web.Mvc.RenderRouteHandler - The current Document Type contact matches a locally declared controller of type UmbracoBlogSite.Controllers.ContactController. Custom Controllers for Umbraco routing must implement 'Umbraco.Web.Mvc.IRenderController' and inherit from 'System.Web.Mvc.ControllerBase'.
 2018-09-20 22:48:31,837 [P2168/D8/T42] WARN  Umbraco.Web.Mvc.RenderRouteHandler - The current Document Type contact matches a locally declared controller of type UmbracoBlogSite.Controllers.ContactController. Custom Controllers for Umbraco routing must implement 'Umbraco.Web.Mvc.IRenderController' and inherit from 'System.Web.Mvc.ControllerBase'.
 2018-09-20 22:48:36,492 [P2168/D8/T42] ERROR Umbraco.Core.UmbracoApplicationBase - An unhandled exception occurred
System.Net.Mail.SmtpException: Failure sending mail. ---> System.Net.WebException: Unable to connect to the remote server ---> System.Net.Sockets.SocketException: No connection could be made because the target machine actively refused it [2001:67c:12b0::7]:25
   at System.Net.Sockets.Socket.DoConnect(EndPoint endPointSnapshot, SocketAddress socketAddress)
   at System.Net.ServicePoint.ConnectSocketInternal(Boolean connectFailure, Socket s4, Socket s6, Socket& socket, IPAddress& address, ConnectSocketState state, IAsyncResult asyncResult, Exception& exception)
   --- End of inner exception stack trace ---
   at System.Net.ServicePoint.GetConnection(PooledStream PooledStream, Object owner, Boolean async, IPAddress& address, Socket& abortSocket, Socket& abortSocket6)
   at System.Net.PooledStream.Activate(Object owningObject, Boolean async, GeneralAsyncDelegate asyncCallback)
   at System.Net.PooledStream.Activate(Object owningObject, GeneralAsyncDelegate asyncCallback)
   at System.Net.ConnectionPool.GetConnection(Object owningObject, GeneralAsyncDelegate asyncCallback, Int32 creationTimeout)
   at System.Net.Mail.SmtpConnection.GetConnection(ServicePoint servicePoint)
   at System.Net.Mail.SmtpTransport.GetConnection(ServicePoint servicePoint)
   at System.Net.Mail.SmtpClient.GetConnection()
   at System.Net.Mail.SmtpClient.Send(MailMessage message)
   --- End of inner exception stack trace ---
   at System.Net.Mail.SmtpClient.Send(MailMessage message)
   at UmbracoBlogSite.Controllers.ContactController.SendEmail(Contact model) in \\Mac\Home\Documents\GitHub\MyUmbracoBlogSite\UmbracoBlogSite\Controllers\ContactController.cs:line 44
   at UmbracoBlogSite.Controllers.ContactController.SubmitForm(Contact model) in \\Mac\Home\Documents\GitHub\MyUmbracoBlogSite\UmbracoBlogSite\Controllers\ContactController.cs:line 27
   at lambda_method(Closure , ControllerBase , Object[] )
   at System.Web.Mvc.ActionMethodDispatcher.Execute(ControllerBase controller, Object[] parameters)
   at System.Web.Mvc.ReflectedActionDescriptor.Execute(ControllerContext controllerContext, IDictionary`2 parameters)
   at System.Web.Mvc.ControllerActionInvoker.InvokeActionMethod(ControllerContext controllerContext, ActionDescriptor actionDescriptor, IDictionary`2 parameters)
   at System.Web.Mvc.Async.AsyncControllerActionInvoker.<BeginInvokeSynchronousActionMethod>b__39(IAsyncResult asyncResult, ActionInvocation innerInvokeState)
   at System.Web.Mvc.Async.AsyncResultWrapper.WrappedAsyncResult`2.CallEndDelegate(IAsyncResult asyncResult)
   at System.Web.Mvc.Async.AsyncResultWrapper.WrappedAsyncResultBase`1.End()
   at System.Web.Mvc.Async.AsyncControllerActionInvoker.EndInvokeActionMethod(IAsyncResult asyncResult)
   at System.Web.Mvc.Async.AsyncControllerActionInvoker.AsyncInvocationWithFilters.<InvokeActionMethodFilterAsynchronouslyRecursive>b__3d()
   at System.Web.Mvc.Async.AsyncControllerActionInvoker.AsyncInvocationWithFilters.<>c__DisplayClass46.<InvokeActionMethodFilterAsynchronouslyRecursive>b__3f()
   at System.Web.Mvc.Async.AsyncControllerActionInvoker.AsyncInvocationWithFilters.<>c__DisplayClass46.<InvokeActionMethodFilterAsynchronouslyRecursive>b__3f()
   at System.Web.Mvc.Async.AsyncControllerActionInvoker.AsyncInvocationWithFilters.<>c__DisplayClass46.<InvokeActionMethodFilterAsynchronouslyRecursive>b__3f()
   at System.Web.Mvc.Async.AsyncControllerActionInvoker.AsyncInvocationWithFilters.<>c__DisplayClass46.<InvokeActionMethodFilterAsynchronouslyRecursive>b__3f()
   at System.Web.Mvc.Async.AsyncControllerActionInvoker.<>c__DisplayClass33.<BeginInvokeActionMethodWithFilters>b__32(IAsyncResult asyncResult)
   at System.Web.Mvc.Async.AsyncResultWrapper.WrappedAsyncResult`1.CallEndDelegate(IAsyncResult asyncResult)
   at System.Web.Mvc.Async.AsyncResultWrapper.WrappedAsyncResultBase`1.End()
   at System.Web.Mvc.Async.AsyncControllerActionInvoker.EndInvokeActionMethodWithFilters(IAsyncResult asyncResult)
   at System.Web.Mvc.Async.AsyncControllerActionInvoker.<>c__DisplayClass21.<>c__DisplayClass2b.<BeginInvokeAction>b__1c()
   at System.Web.Mvc.Async.AsyncControllerActionInvoker.<>c__DisplayClass21.<BeginInvokeAction>b__1e(IAsyncResult asyncResult)
   at System.Web.Mvc.Async.AsyncResultWrapper.WrappedAsyncResult`1.CallEndDelegate(IAsyncResult asyncResult)
   at System.Web.Mvc.Async.AsyncResultWrapper.WrappedAsyncResultBase`1.End()
   at System.Web.Mvc.Async.AsyncControllerActionInvoker.EndInvokeAction(IAsyncResult asyncResult)
   at System.Web.Mvc.Controller.<BeginExecuteCore>b__1d(IAsyncResult asyncResult, ExecuteCoreState innerState)
   at System.Web.Mvc.Async.AsyncResultWrapper.WrappedAsyncVoid`1.CallEndDelegate(IAsyncResult asyncResult)
   at System.Web.Mvc.Async.AsyncResultWrapper.WrappedAsyncResultBase`1.End()
   at System.Web.Mvc.Controller.EndExecuteCore(IAsyncResult asyncResult)
   at System.Web.Mvc.Controller.<BeginExecute>b__15(IAsyncResult asyncResult, Controller controller)
   at System.Web.Mvc.Async.AsyncResultWrapper.WrappedAsyncVoid`1.CallEndDelegate(IAsyncResult asyncResult)
   at System.Web.Mvc.Async.AsyncResultWrapper.WrappedAsyncResultBase`1.End()
   at System.Web.Mvc.Controller.EndExecute(IAsyncResult asyncResult)
   at System.Web.Mvc.Controller.System.Web.Mvc.Async.IAsyncController.EndExecute(IAsyncResult asyncResult)
   at System.Web.Mvc.MvcHandler.<BeginProcessRequest>b__5(IAsyncResult asyncResult, ProcessRequestState innerState)
   at System.Web.Mvc.Async.AsyncResultWrapper.WrappedAsyncVoid`1.CallEndDelegate(IAsyncResult asyncResult)
   at System.Web.Mvc.Async.AsyncResultWrapper.WrappedAsyncResultBase`1.End()
   at System.Web.Mvc.MvcHandler.EndProcessRequest(IAsyncResult asyncResult)
   at System.Web.Mvc.MvcHandler.System.Web.IHttpAsyncHandler.EndProcessRequest(IAsyncResult result)
   at System.Web.HttpApplication.CallHandlerExecutionStep.System.Web.HttpApplication.IExecutionStep.Execute()
   at System.Web.HttpApplication.ExecuteStepImpl(IExecutionStep step)
   at System.Web.HttpApplication.ExecuteStep(IExecutionStep step, Boolean& completedSynchronously)
